Workbook
Name FUNGSI_JABATAN: [1]database!$E$54:$E$56
Name KLASIFIKASI_JABATAN: [1]database!$E$60:$E$65

Sheet CONTROL MP HR
A2: MP SIS & MITRA KERJA 2022 (DATA HR)
A4: NO | B4: ID CONTROL | C4: ID PERUSAHAN | D4: MINE PERMIT ID | E4: NAMA | F4: PERUSAHAN | G4: POSISI | H4: SECTION | I4: KLASIFIKASI JABATAN | J4: FUNGSI JABATAN
A5: 1 | B5: =TEXT(C5,"00000000") -> BAGONG-005 | C5: BAGONG-005 | E5: WALIJO | F5: CV. BAGONG MOTOR | G5: OPERATOR MAN HAUL | H5: HRGA | I5: =IF(J5="A","OPERASIONAL",IF(J5="B","ADMINISTRASI",IF(J5="C","PENGAWAS",IF(J5="D","TEMPORERY")))) -> OPERASIONAL | J5: A | M5: BAGONG-005
A6: =A5+1 -> 2 | B6: =TEXT(C6,"00000000") -> MP/AR | C6: MP/AR | E6: IRHAM MAULANA | F6: PT. ABADI RAYA COMMERCE | G6: GENERAL SERVICE KITCHEN | H6: HRGA | I6: =IF(J6="A","OPERASIONAL",IF(J6="B","ADMINISTRASI",IF(J6="C","PENGAWAS",IF(J6="D","TEMPORERY")))) -> OPERASIONAL | J6: A | M6: MP/AR
A7: =A6+1 -> 3 | B7: =TEXT(C7,"00000000") -> MP/ARCO0141 | C7: MP/ARCO0141 | E7: SAPRI | F7: PT. ABADI RAYA COMMERCE | G7: CHIEF COOK | H7: HRGA | I7: =IF(J7="A","OPERASIONAL",IF(J7="B","ADMINISTRASI",IF(J7="C","PENGAWAS",IF(J7="D","TEMPORERY")))) -> OPERASIONAL | J7: A | M7: MP/ARCO0141
A8: =A7+1 -> 4 | B8: =TEXT(C8,"00000000") -> 3696-0420 | C8: 3696-0420 | E8: RIO MEIDI HERMAWAN | F8: PT. ABADI RAYA COMMERCE | G8: SITE ADMIN | H8: HRGA | I8: =IF(J8="A","OPERASIONAL",IF(J8="B","ADMINISTRASI",IF(J8="C","PENGAWAS",IF(J8="D","TEMPORERY")))) -> ADMINISTRASI | J8: B | M8: 3696-0420
A9: =A8+1 -> 5 | B9: =TEXT(C9,"00000000") -> MP/ARCO0210 | C9: MP/ARCO0210 | E9: YONDI ERPRIANTO | F9: PT. ABADI RAYA COMMERCE | G9: COOK 2 | H9: HRGA | I9: =IF(J9="A","OPERASIONAL",IF(J9="B","ADMINISTRASI",IF(J9="C","PENGAWAS",IF(J9="D","TEMPORERY")))) -> OPERASIONAL | J9: A | M9: MP/ARCO0210
A10: =A9+1 -> 6 | B10: =TEXT(C10,"00000000") -> MP/ARCO0211 | C10: MP/ARCO0211 | E10: ALI MARDANI | F10: PT. ABADI RAYA COMMERCE | G10: DRIVER | H10: HRGA | I10: =IF(J10="A","OPERASIONAL",IF(J10="B","ADMINISTRASI",IF(J10="C","PENGAWAS",IF(J10="D","TEMPORERY")))) -> OPERASIONAL | J10: A | M10: MP/ARCO0211
A11: =A10+1 -> 7 | B11: =TEXT(C11,"00000000") -> MP/ARCO0189 | C11: MP/ARCO0189 | E11: SANDY | F11: PT. ABADI RAYA COMMERCE | G11: GS FACILITIES | H11: HRGA | I11: =IF(J11="A","OPERASIONAL",IF(J11="B","ADMINISTRASI",IF(J11="C","PENGAWAS",IF(J11="D","TEMPORERY")))) -> OPERASIONAL | J11: A | M11: MP/ARCO0189
A12: =A11+1 -> 8 | B12: =TEXT(C12,"00000000") -> ISAC-21120545 | C12: ISAC-21120545 | E12: RUDI AMRI ALFIAN SITORUS | F12: PT. ABADI RAYA COMMERCE | G12: CHIEF COOK | H12: HRGA | I12: =IF(J12="A","OPERASIONAL",IF(J12="B","ADMINISTRASI",IF(J12="C","PENGAWAS",IF(J12="D","TEMPORERY")))) -> OPERASIONAL | J12: A | M12: ISAC-21120545
A13: =A12+1 -> 9 | B13: =TEXT(C13,"00000000") -> ISAC-22082330 | C13: ISAC-22082330 | E13: MUH. ARFAH | F13: PT. ABADI RAYA COMMERCE | G13: SAFETY OFFICER | H13: QHSE | I13: =IF(J13="A","OPERASIONAL",IF(J13="B","ADMINISTRASI",IF(J13="C","PENGAWAS",IF(J13="D","TEMPORERY")))) -> OPERASIONAL | J13: A | M13: ISAC-22082330
A14: =A13+1 -> 10 | B14: =TEXT(C14,"00000000") -> ISAC-21110428 | C14: ISAC-21110428 | E14: SANTI RATNAWATI | F14: PT. ABADI RAYA COMMERCE | G14: SAFETY OFFICER | H14: HRGA | I14: =IF(J14="A","OPERASIONAL",IF(J14="B","ADMINISTRASI",IF(J14="C","PENGAWAS",IF(J14="D","TEMPORERY")))) -> OPERASIONAL | J14: A | M14: ISAC-21110428
A15: =A14+1 -> 11 | B15: =TEXT(C15,"00000000") -> MP/ARCO0129 | C15: MP/ARCO0129 | E15: MUHTADIN | F15: PT. ABADI RAYA COMMERCE | G15: BAKERY | H15: HRGA | I15: =IF(J15="A","OPERASIONAL",IF(J15="B","ADMINISTRASI",IF(J15="C","PENGAWAS",IF(J15="D","TEMPORERY")))) -> OPERASIONAL | J15: A | M15: MP/ARCO0129
A16: =A15+1 -> 12 | B16: =TEXT(C16,"00000000") -> MP/ARCO-0008 | C16: MP/ARCO-0008 | E16: AGUS AMIRUDDIN | F16: PT. ABADI RAYA COMMERCE | G16: BAKERY | H16: HRGA | I16: =IF(J16="A","OPERASIONAL",IF(J16="B","ADMINISTRASI",IF(J16="C","PENGAWAS",IF(J16="D","TEMPORERY")))) -> OPERASIONAL | J16: A | M16: MP/ARCO-0008
A17: =A16+1 -> 13 | B17: =TEXT(C17,"00000000") -> MP/ARCO-0364 | C17: MP/ARCO-0364 | E17: ANDRIANO SONDAKH | F17: PT. ABADI RAYA COMMERCE | G17: GS FACILITIES | H17: HRGA | I17: =IF(J17="A","OPERASIONAL",IF(J17="B","ADMINISTRASI",IF(J17="C","PENGAWAS",IF(J17="D","TEMPORERY")))) -> OPERASIONAL | J17: A | M17: MP/ARCO-0364
... A21: =A20+1 -> 17 | B21: =TEXT(C21,"00000000") -> ISAC-0000078 | C21: ISAC-0000078 | E21: ADELIA | F21: PT. ABADI RAYA COMMERCE | G21: GENERAL SERVICE MESHALL | H21: HRGA | I21: =IF(J21="A","OPERASIONAL",IF(J21="B","ADMINISTRASI",IF(J21="C","PENGAWAS",IF(J21="D","TEMPORERY")))) -> OPERASIONAL | J21: A | M21: ISAC-0000078
A22: =A21+1 -> 18 | B22: =TEXT(C22,"00000000") -> 00000000 | E22: AFDAL WIJAYA | F22: PT. ABADI RAYA COMMERCE | G22: GENERAL SERVICE | H22: HRGA | I22: =IF(J22="A","OPERASIONAL",IF(J22="B","ADMINISTRASI",IF(J22="C","PENGAWAS",IF(J22="D","TEMPORERY")))) -> OPERASIONAL | J22: A | M22: ISAC-22082327
A23: =A22+1 -> 19 | B23: =TEXT(C23,"00000000") -> MP/ARCO329 | C23: MP/ARCO329 | E23: AINI NUDIN | F23: PT. ABADI RAYA COMMERCE | G23: GS FACILITIES | H23: HRGA | I23: =IF(J23="A","OPERASIONAL",IF(J23="B","ADMINISTRASI",IF(J23="C","PENGAWAS",IF(J23="D","TEMPORERY")))) -> OPERASIONAL | J23: A | M23: MP/ARCO329
A24: =A23+1 -> 20 | B24: =TEXT(C24,"00000000") -> ISAC-22011045 | C24: ISAC-22011045 | E24: ARDI TRI FISANTO | F24: PT. ABADI RAYA COMMERCE | G24: GS-HOUSE KEEPING | H24: HRGA | I24: =IF(J24="A","OPERASIONAL",IF(J24="B","ADMINISTRASI",IF(J24="C","PENGAWAS",IF(J24="D","TEMPORERY")))) -> OPERASIONAL | J24: A | M24: ISAC-22011045
A25: =A24+1 -> 21 | B25: =TEXT(C25,"00000000") -> MP/ARCO-137 | C25: MP/ARCO-137 | E25: ARTATY | F25: PT. ABADI RAYA COMMERCE | G25: GENERAL SERVICE MESHALL | H25: HRGA | I25: =IF(J25="A","OPERASIONAL",IF(J25="B","ADMINISTRASI",IF(J25="C","PENGAWAS",IF(J25="D","TEMPORERY")))) -> OPERASIONAL | J25: A | M25: MP/ARCO-137
A26: =A25+1 -> 22 | B26: =TEXT(C26,"00000000") -> MP/ARCO-0375 | C26: MP/ARCO-0375 | E26: CICIT TORO | F26: PT. ABADI RAYA COMMERCE | G26: GS-HKL | H26: HRGA | I26: =IF(J26="A","OPERASIONAL",IF(J26="B","ADMINISTRASI",IF(J26="C","PENGAWAS",IF(J26="D","TEMPORERY")))) -> OPERASIONAL | J26: A | M26: MP/ARCO-0375
A27: =A26+1 -> 23 | B27: =TEXT(C27,"00000000") -> ISAC-000000 | C27: ISAC-000000 | E27: CRIS ADITYA PRATAMA | F27: PT. ABADI RAYA COMMERCE | G27: GS-HKL | H27: HRGA | I27: =IF(J27="A","OPERASIONAL",IF(J27="B","ADMINISTRASI",IF(J27="C","PENGAWAS",IF(J27="D","TEMPORERY")))) -> OPERASIONAL | J27: A | M27: ISAC-000000
A28: =A27+1 -> 24 | B28: =TEXT(C28,"00000000") -> ISAC-22082328 | C28: ISAC-22082328 | E28: DANDI | F28: PT. ABADI RAYA COMMERCE | G28: GENERAL SERVICE | H28: HRGA | I28: =IF(J28="A","OPERASIONAL",IF(J28="B","ADMINISTRASI",IF(J28="C","PENGAWAS",IF(J28="D","TEMPORERY")))) -> OPERASIONAL | J28: A | M28: ISAC-22082328
A29: =A28+1 -> 25 | B29: =TEXT(C29,"00000000") -> ISAC-21100373 | C29: ISAC-21100373 | E29: DICKY WAHYUDI | F29: PT. ABADI RAYA COMMERCE | G29: GS-HKL | H29: HRGA | I29: =IF(J29="A","OPERASIONAL",IF(J29="B","ADMINISTRASI",IF(J29="C","PENGAWAS",IF(J29="D","TEMPORERY")))) -> OPERASIONAL | J29: A | M29: ISAC-21100373
A30: =A29+1 -> 26 | B30: =TEXT(C30,"00000000") -> MP/ARCO-132 | C30: MP/ARCO-132 | E30: EGIUNA SUTERA | F30: PT. ABADI RAYA COMMERCE | G30: GS-HKL | H30: HRGA | I30: =IF(J30="A","OPERASIONAL",IF(J30="B","ADMINISTRASI",IF(J30="C","PENGAWAS",IF(J30="D","TEMPORERY")))) -> OPERASIONAL | J30: A | M30: MP/ARCO-132
A31: =A30+1 -> 27 | B31: =TEXT(C31,"00000000") -> ISAC-22082329 | C31: ISAC-22082329 | E31: ERWIN SUPANDI | F31: PT. ABADI RAYA COMMERCE | G31: GENERAL SERVICE | H31: HRGA | I31: =IF(J31="A","OPERASIONAL",IF(J31="B","ADMINISTRASI",IF(J31="C","PENGAWAS",IF(J31="D","TEMPORERY")))) -> OPERASIONAL | J31: A | M31: ISAC-22082329
A32: =A31+1 -> 28 | B32: =TEXT(C32,"00000000") -> MP/ARCO-19 | C32: MP/ARCO-19 | E32: ESA ITA PURNAMA SARI | F32: PT. ABADI RAYA COMMERCE | G32: GS-HKL | H32: HRGA | I32: =IF(J32="A","OPERASIONAL",IF(J32="B","ADMINISTRASI",IF(J32="C","PENGAWAS",IF(J32="D","TEMPORERY")))) -> OPERASIONAL | J32: A | M32: MP/ARCO-19
A33: =A32+1 -> 29 | B33: =TEXT(C33,"00000000") -> MP/ARCO0335 | C33: MP/ARCO0335 | E33: f | F33: PT. ABADI RAYA COMMERCE | G33: GS-HKL | H33: HRGA | I33: =IF(J33="A","OPERASIONAL",IF(J33="B","ADMINISTRASI",IF(J33="C","PENGAWAS",IF(J33="D","TEMPORERY")))) -> OPERASIONAL | J33: A | M33: MP/ARCO0335
A34: =A33+1 -> 30 | B34: =TEXT(C34,"00000000") -> MP/ARCO-0356 | C34: MP/ARCO-0356 | E34: FERRY DHARMA SAPUTRA | F34: PT. ABADI RAYA COMMERCE | G34: GS-HKL | H34: HRGA | I34: =IF(J34="A","OPERASIONAL",IF(J34="B","ADMINISTRASI",IF(J34="C","PENGAWAS",IF(J34="D","TEMPORERY")))) -> OPERASIONAL | J34: A | M34: MP/ARCO-0356
... A41: =A40+1 -> 37 | B41: =TEXT(C41,"00000000") -> ISAC-000003 | C41: ISAC-000003 | E41: PATIMAH AZAHARA | F41: PT. ABADI RAYA COMMERCE | G41: GENERAL SERVICE MESHALL | H41: HRGA | I41: =IF(J41="A","OPERASIONAL",IF(J41="B","ADMINISTRASI",IF(J41="C","PENGAWAS",IF(J41="D","TEMPORERY")))) -> OPERASIONAL | J41: A | M41: ISAC-000003
A42: =A41+1 -> 38 | B42: =TEXT(C42,"00000000") -> 00000312 | C42: 312 | E42: RAHMANTO | F42: PT. ABADI RAYA COMMERCE | G42: GS-HKL | H42: HRGA | I42: =IF(J42="A","OPERASIONAL",IF(J42="B","ADMINISTRASI",IF(J42="C","PENGAWAS",IF(J42="D","TEMPORERY")))) -> OPERASIONAL | J42: A | M42: 00000312
A43: =A42+1 -> 39 | B43: =TEXT(C43,"00000000") -> MP/ARCO-4002 | C43: MP/ARCO-4002 | E43: RANISA ADE RAHAYU | F43: PT. ABADI RAYA COMMERCE | G43: GENERAL SERVICE MESHALL | H43: HRGA | I43: =IF(J43="A","OPERASIONAL",IF(J43="B","ADMINISTRASI",IF(J43="C","PENGAWAS",IF(J43="D","TEMPORERY")))) -> OPERASIONAL | J43: A | M43: MP/ARCO-4002
A44: =A43+1 -> 40 | B44: =TEXT(C44,"00000000") -> ISAC-21110502 | C44: ISAC-21110502 | E44: RENDANA WANAHARI | F44: PT. ABADI RAYA COMMERCE | G44: GS-HKL | H44: HRGA | I44: =IF(J44="A","OPERASIONAL",IF(J44="B","ADMINISTRASI",IF(J44="C","PENGAWAS",IF(J44="D","TEMPORERY")))) -> OPERASIONAL | J44: A | M44: ISAC-21110502
A45: =A44+1 -> 41 | B45: =TEXT(C45,"00000000") -> MP/ARCO-0354 | C45: MP/ARCO-0354 | E45: RONALDO | F45: PT. ABADI RAYA COMMERCE | G45: DRIVER | H45: HRGA | I45: =IF(J45="A","OPERASIONAL",IF(J45="B","ADMINISTRASI",IF(J45="C","PENGAWAS",IF(J45="D","TEMPORERY")))) -> OPERASIONAL | J45: A | M45: MP/ARCO-0354
A46: =A45+1 -> 42 | B46: =TEXT(C46,"00000000") -> ISAC-000001 | C46: ISAC-000001 | E46: SEPDA SABANO | F46: PT. ABADI RAYA COMMERCE | G46: GS-HKL | H46: HRGA | I46: =IF(J46="A","OPERASIONAL",IF(J46="B","ADMINISTRASI",IF(J46="C","PENGAWAS",IF(J46="D","TEMPORERY")))) -> OPERASIONAL | J46: A | M46: ISAC-000001
A47: =A46+1 -> 43 | B47: =TEXT(C47,"00000000") -> ISAC-21110479 | C47: ISAC-21110479 | E47: SIHANDIKA | F47: PT. ABADI RAYA COMMERCE | G47: GS-HKL | H47: HRGA | I47: =IF(J47="A","OPERASIONAL",IF(J47="B","ADMINISTRASI",IF(J47="C","PENGAWAS",IF(J47="D","TEMPORERY")))) -> OPERASIONAL | J47: A | M47: ISAC-21110479
A48: =A47+1 -> 44 | B48: =TEXT(C48,"00000000") -> ISAC-21110501 | C48: ISAC-21110501 | E48: SRI WULANDARI | F48: PT. ABADI RAYA COMMERCE | G48: GS-HKL | H48: HRGA | I48: =IF(J48="A","OPERASIONAL",IF(J48="B","ADMINISTRASI",IF(J48="C","PENGAWAS",IF(J48="D","TEMPORERY")))) -> OPERASIONAL | J48: A | M48: ISAC-21110501
A49: =A48+1 -> 45 | B49: =TEXT(C49,"00000000") -> ISAC-22021092 | C49: ISAC-22021092 | E49: SYAHRUL SETIAWAN | F49: PT. ABADI RAYA COMMERCE | G49: GS-HKL | H49: HRGA | I49: =IF(J49="A","OPERASIONAL",IF(J49="B","ADMINISTRASI",IF(J49="C","PENGAWAS",IF(J49="D","TEMPORERY")))) -> OPERASIONAL | J49: A | M49: ISAC-22021092
A50: =A49+1 -> 46 | B50: =TEXT(C50,"00000000") -> MP/ARCO0162 | C50: MP/ARCO0162 | E50: TAMJIDILLAH | F50: PT. ABADI RAYA COMMERCE | G50: SUPERVISOR HOUSEKEEPING | H50: HRGA | I50: =IF(J50="A","OPERASIONAL",IF(J50="B","ADMINISTRASI",IF(J50="C","PENGAWAS",IF(J50="D","TEMPORERY")))) -> PENGAWAS | J50: C | M50: MP/ARCO0162
A51: =A50+1 -> 47 | B51: =TEXT(C51,"00000000") -> ISAC-22082356 | C51: ISAC-22082356 | E51: TANTRIADI | F51: PT. ABADI RAYA COMMERCE | G51: GENERAL SERVICE | H51: HRGA | I51: =IF(J51="A","OPERASIONAL",IF(J51="B","ADMINISTRASI",IF(J51="C","PENGAWAS",IF(J51="D","TEMPORERY")))) -> OPERASIONAL | J51: A | M51: ISAC-22082356
...

Sheet VALIDASI
A1: PERUSAHAAN
A2: PT. SAPTAINDRA SEJATI
A3: PT. ABADI RAYA COMMERCE
A4: PT. BANDANG MINING COAL
A5: PT. BORNEO MURA PERKASA
A6: PT. CHIESA MANDIRI UTAMA
A7: PT. CIPTA HYDROPOWER ABADI
A8: PT. DEMITRA KARSA PERDANA A5
A9: PT. EKA DHARMA JAYA SAKTI
A10: PT. EPIROC SOUTHERN ASIA
A11: PT. KINAYA MULTI KONSTRUKSI
A12: PT. LIEBHERR
... A21: PT. VERDANCO ENGINEERING

Sheet INDIVIDUAL RECORD
C6: INDIVIDUAL SHE TRAINING RECORD
C7: NRP | E7: : | F7: 80002071
C8: NAMA | E8: : | F8: =VLOOKUP($F$7,'Data Training 2022'!$B$6:$XFD$1048576,4,FALSE) -> DANCE TANGNGA
C9: PERUSAHAAN | E9: : | F9: =VLOOKUP($F$7,'Data Training 2022'!$B$6:$XFD$1048576,5,FALSE) -> PT. SAPTAINDRA SEJATI
C10: POSISI | E10: : | F10: =VLOOKUP($F$7,'Data Training 2022'!$B$6:$XFD$1048576,6,FALSE) -> GROUP LEADER
C11: SECTION | E11: : | F11: =VLOOKUP($F$7,'Data Training 2022'!$B$6:$XFD$1048576,7,FALSE) -> PRODUKSI
C12: FUNGSI JABATAN | E12: : | F12: =VLOOKUP($F$7,'Data Training 2022'!$B$6:$XFD$1048576,11,FALSE) -> PENGAWAS
C14: NO | D14: JENIS TRAINING | F14: TANGGAL TRAINING | G14: KETERANGAN
C15: 1 | D15: POP | F15: =VLOOKUP($F$7,'Data Training 2022'!$B$6:$XFD$1048576,14,FALSE) -> 44145
C16: 2 | D16: POM | F16: =VLOOKUP($F$7,'Data Training 2022'!$B$6:$XFD$1048576,15,FALSE)
C17: 3 | D17: POU | F17: =VLOOKUP($F$7,'Data Training 2022'!$B$6:$XFD$1048576,16,FALSE)
C18: 4 | D18: PEMBEKALAN POP | F18: =VLOOKUP($F$7,'Data Training 2022'!$B$6:$XFD$1048576,18,FALSE) | G18: =VLOOKUP($F$7,'Data Training 2022'!$B$6:$XFD$1048576,19,FALSE)
C19: 5 | D19: INDUKSI | F19: =VLOOKUP($F$7,'Data Training 2022'!$B$6:$XFD$1048576,21,FALSE) -> #N/A | G19: =VLOOKUP($F$7,'Data Training 2022'!$B$6:$XFD$1048576,22,FALSE) -> LULUS
C20: 6 | D20: REINDUKSI | F20: =VLOOKUP($F$7,'Data Training 2022'!$B$6:$XFD$1048576,24,FALSE) -> 44758 | G20: =VLOOKUP($F$7,'Data Training 2022'!$B$6:$XFD$1048576,25,FALSE) -> LULUS
C21: 7 | D21: BSA | F21: =VLOOKUP($F$7,'Data Training 2022'!$B$6:$XFD$1048576,27,FALSE) -> 0 | G21: =VLOOKUP($F$7,'Data Training 2022'!$B$6:$XFD$1048576,28,FALSE)
D22: BLS | F22: =VLOOKUP($F$7,'Data Training 2022'!$B$6:$XFD$1048576,30,FALSE) -> 0 | G22: =VLOOKUP($F$7,'Data Training 2022'!$B$6:$XFD$1048576,31,FALSE) -> 0
C23: 9 | D23: ISOLASI | F23: =VLOOKUP($F$7,'Data Training 2022'!$B$6:$XFD$1048576,33,FALSE) -> 0 | G23: =VLOOKUP($F$7,'Data Training 2022'!$B$6:$XFD$1048576,34,FALSE)
C24: 10 | D24: DEKAT AIR | F24: =VLOOKUP($F$7,'Data Training 2022'!$B$6:$XFD$1048576,36,FALSE) -> 0 | G24: =VLOOKUP($F$7,'Data Training 2022'!$B$6:$XFD$1048576,37,FALSE)
C25: 11 | D25: KETINGGIAN | F25: =VLOOKUP($F$7,'Data Training 2022'!$B$6:$XFD$1048576,39,FALSE) -> 0 | G25: =VLOOKUP($F$7,'Data Training 2022'!$B$6:$XFD$1048576,40,FALSE)
C26: 12 | D26: RUANG TERBATAS | F26: =VLOOKUP($F$7,'Data Training 2022'!$B$6:$XFD$1048576,42,FALSE) -> 0 | G26: =VLOOKUP($F$7,'Data Training 2022'!$B$6:$XFD$1048576,43,FALSE) -> 0
C27: 13 | D27: TOOLSKEEPER | F27: =VLOOKUP($F$7,'Data Training 2022'!$B$6:$XFD$1048576,45,FALSE) -> 0 | G27: =VLOOKUP($F$7,'Data Training 2022'!$B$6:$XFD$1048576,46,FALSE)

Sheet Dashboard
A1: TRAINING KARYAWAN 2022
A2: PERUSAHAAN | B2: SECTION | C2: PEMBEKALAN POP | F2: INDUKSI | I2: REINDUKSI | L2: BSA | O2: BLS | R2: ISOLASI | U2: DEKAT AIR | X2: KETINGGIAN | AA2: RUANG TERBATAS | AD2: TOOLS KEEPER
C3: PLAN | D3: ACTUAL | E3: ACH | F3: PLAN | G3: ACTUAL | H3: ACH | I3: PLAN | J3: ACTUAL | K3: ACH | L3: PLAN | M3: ACTUAL | N3: ACH | O3: PLAN | P3: ACTUAL | Q3: ACH | R3: PLAN | S3: ACTUAL | T3: ACH | U3: PLAN | V3: ACTUAL | W3: ACH | X3: PLAN | Y3: ACTUAL | Z3: ACH | AA3: PLAN | AB3: ACTUAL | AC3: ACH | AD3: PLAN | AE3: ACTUAL | AF3: ACH
A4: PT. SAPTAINDRA SEJATI | B4: OPERATION | C4: =COUNTIFS('Data Training 2022'!$F$6:$F$1048576,Dashboard!$A$4,'Data Training 2022'!$H$6:$H$1048576,Dashboard!B4,'Data Training 2022'!$R$6:$R$1048576,"TARGET") -> 0 | D4: =COUNTIFS('Data Training 2022'!$F$6:$F$1048576,Dashboard!$A$4,'Data Training 2022'!$H$6:$H$1048576,Dashboard!B4,'Data Training 2022'!$T$6:$T$1048576,"LULUS") -> 0 | E4: =IFERROR(D4/C4,"NA") -> NA | F4: =COUNTIFS('Data Training 2022'!$F$6:$F$1048576,Dashboard!$A$4,'Data Training 2022'!$H$6:$H$1048576,Dashboard!B4,'Data Training 2022'!$U$6:$U$1048576,"TARGET") -> 1 | G4: =COUNTIFS('Data Training 2022'!$F$6:$F$1048576,Dashboard!$A$4,'Data Training 2022'!$H$6:$H$1048576,Dashboard!B4,'Data Training 2022'!$W$6:$W$1048576,"LULUS") -> 1 | H4: =IFERROR(G4/F4,"NA") -> 1 | I4: =COUNTIFS('Data Training 2022'!$F$6:$F$1048576,Dashboard!$A$4,'Data Training 2022'!$H$6:$H$1048576,Dashboard!B4,'Data Training 2022'!$X$6:$X$1048576,"TARGET") -> 1 | J4: =COUNTIFS('Data Training 2022'!$F$6:$F$1048576,Dashboard!$A$4,'Data Training 2022'!$H$6:$H$1048576,Dashboard!B4,'Data Training 2022'!$Z$6:$Z$1048576,"LULUS") -> 0 | K4: =IFERROR(J4/I4,"NA") -> 0 | L4: =COUNTIFS('Data Training 2022'!$F$6:$F$1048576,Dashboard!$A$4,'Data Training 2022'!$H$6:$H$1048576,Dashboard!B4,'Data Training 2022'!$AA$6:$AA$1048576,"TARGET") -> 0 | M4: =COUNTIFS('Data Training 2022'!$F$6:$F$1048576,Dashboard!$A$4,'Data Training 2022'!$H$6:$H$1048576,Dashboard!B4,'Data Training 2022'!$AC$6:$AC$1048576,"LULUS") -> 0 | N4: =IFERROR(M4/L4,"NA") -> NA | O4: =COUNTIFS('Data Training 2022'!$F$6:$F$1048576,Dashboard!$A$4,'Data Training 2022'!$H$6:$H$1048576,Dashboard!B4,'Data Training 2022'!$AD$6:$AD$1048576,"TARGET") -> 1 | P4: =COUNTIFS('Data Training 2022'!$F$6:$F$1048576,Dashboard!$A$4,'Data Training 2022'!$H$6:$H$1048576,Dashboard!B4,'Data Training 2022'!$AF$6:$AF$1048576,"LULUS") -> 0 | Q4: =IFERROR(P4/O4,"NA") -> 0 | R4: =COUNTIFS('Data Training 2022'!$F$6:$F$1048576,Dashboard!$A$4,'Data Training 2022'!$H$6:$H$1048576,Dashboard!B4,'Data Training 2022'!$AG$6:$AG$1048576,"TARGET") -> 0 | S4: =COUNTIFS('Data Training 2022'!$F$6:$F$1048576,Dashboard!$A$4,'Data Training 2022'!$H$6:$H$1048576,Dashboard!B4,'Data Training 2022'!$AI$6:$AI$1048576,"LULUS") -> 0 | T4: =IFERROR(S4/R4,"NA") -> NA | U4: =COUNTIFS('Data Training 2022'!$F$6:$F$1048576,Dashboard!$A$4,'Data Training 2022'!$H$6:$H$1048576,Dashboard!B4,'Data Training 2022'!$AJ$6:$AJ$1048576,"TARGET") -> 0 | V4: =COUNTIFS('Data Training 2022'!$F$6:$F$1048576,Dashboard!$A$4,'Data Training 2022'!$H$6:$H$1048576,Dashboard!B4,'Data Training 2022'!$AL$6:$AL$1048576,"LULUS") -> 0 | W4: =IFERROR(V4/U4,"NA") -> NA | X4: =COUNTIFS('Data Training 2022'!$F$6:$F$1048576,Dashboard!$A$4,'Data Training 2022'!$H$6:$H$1048576,Dashboard!B4,'Data Training 2022'!$AM$6:$AM$1048576,"TARGET") -> 0 | Y4: =COUNTIFS('Data Training 2022'!$F$6:$F$1048576,Dashboard!$A$4,'Data Training 2022'!$H$6:$H$1048576,Dashboard!B4,'Data Training 2022'!$AO$6:$AO$1048576,"LULUS") -> 0 | Z4: =IFERROR(Y4/X4,"NA") -> NA | AA4: =COUNTIFS('Data Training 2022'!$F$6:$F$1048576,Dashboard!$A$4,'Data Training 2022'!$H$6:$H$1048576,Dashboard!B4,'Data Training 2022'!$AP$6:$AP$1048576,"TARGET") -> 0 | AB4: =COUNTIFS('Data Training 2022'!$F$6:$F$1048576,Dashboard!$A$4,'Data Training 2022'!$H$6:$H$1048576,Dashboard!B4,'Data Training 2022'!$AR$6:$AR$1048576,"LULUS") -> 0 | AC4: =IFERROR(AB4/AA4,"NA") -> NA | AD4: =COUNTIFS('Data Training 2022'!$F$6:$F$1048576,Dashboard!$A$4,'Data Training 2022'!$H$6:$H$1048576,Dashboard!B4,'Data Training 2022'!$AS$6:$AS$1048576,"TARGET") -> 0 | AE4: =COUNTIFS('Data Training 2022'!$F$6:$F$1048576,Dashboard!$A$4,'Data Training 2022'!$H$6:$H$1048576,Dashboard!B4,'Data Training 2022'!$AU$6:$AU$1048576,"LULUS") -> 0 | AF4: =IFERROR(AE4/AD4,"NA") -> NA
B5: PRODUKSI | C5: =COUNTIFS('Data Training 2022'!$F$6:$F$1048576,Dashboard!$A$4,'Data Training 2022'!$H$6:$H$1048576,Dashboard!B5,'Data Training 2022'!$R$6:$R$1048576,"TARGET") -> 11 | D5: =COUNTIFS('Data Training 2022'!$F$6:$F$1048576,Dashboard!$A$4,'Data Training 2022'!$H$6:$H$1048576,Dashboard!B5,'Data Training 2022'!$T$6:$T$1048576,"LULUS") -> 18 | E5: =IFERROR(D5/C5,"NA") -> 1.6363636 | F5: =COUNTIFS('Data Training 2022'!$F$6:$F$1048576,Dashboard!$A$4,'Data Training 2022'!$H$6:$H$1048576,Dashboard!B5,'Data Training 2022'!$U$6:$U$1048576,"TARGET") -> 736 | G5: =COUNTIFS('Data Training 2022'!$F$6:$F$1048576,Dashboard!$A$4,'Data Training 2022'!$H$6:$H$1048576,Dashboard!B5,'Data Training 2022'!$W$6:$W$1048576,"LULUS") -> 667 | H5: =IFERROR(G5/F5,"NA") -> 0.90625 | I5: =COUNTIFS('Data Training 2022'!$F$6:$F$1048576,Dashboard!$A$4,'Data Training 2022'!$H$6:$H$1048576,Dashboard!B5,'Data Training 2022'!$X$6:$X$1048576,"TARGET") -> 736 | J5: =COUNTIFS('Data Training 2022'!$F$6:$F$1048576,Dashboard!$A$4,'Data Training 2022'!$H$6:$H$1048576,Dashboard!B5,'Data Training 2022'!$Z$6:$Z$1048576,"LULUS") -> 491 | K5: =IFERROR(J5/I5,"NA") -> 0.66711957 | L5: =COUNTIFS('Data Training 2022'!$F$6:$F$1048576,Dashboard!$A$4,'Data Training 2022'!$H$6:$H$1048576,Dashboard!B5,'Data Training 2022'!$AA$6:$AA$1048576,"TARGET") -> 685 | M5: =COUNTIFS('Data Training 2022'!$F$6:$F$1048576,Dashboard!$A$4,'Data Training 2022'!$H$6:$H$1048576,Dashboard!B5,'Data Training 2022'!$AC$6:$AC$1048576,"LULUS") -> 109 | N5: =IFERROR(M5/L5,"NA") -> 0.15912409 | O5: =COUNTIFS('Data Training 2022'!$F$6:$F$1048576,Dashboard!$A$4,'Data Training 2022'!$H$6:$H$1048576,Dashboard!B5,'Data Training 2022'!$AD$6:$AD$1048576,"TARGET") -> 736 | P5: =COUNTIFS('Data Training 2022'!$F$6:$F$1048576,Dashboard!$A$4,'Data Training 2022'!$H$6:$H$1048576,Dashboard!B5,'Data Training 2022'!$AF$6:$AF$1048576,"LULUS") -> 0 | Q5: =IFERROR(P5/O5,"NA") -> 0 | R5: =COUNTIFS('Data Training 2022'!$F$6:$F$1048576,Dashboard!$A$4,'Data Training 2022'!$H$6:$H$1048576,Dashboard!B5,'Data Training 2022'!$AG$6:$AG$1048576,"TARGET") -> 0 | S5: =COUNTIFS('Data Training 2022'!$F$6:$F$1048576,Dashboard!$A$4,'Data Training 2022'!$H$6:$H$1048576,Dashboard!B5,'Data Training 2022'!$AI$6:$AI$1048576,"LULUS") -> 1 | T5: =IFERROR(S5/R5,"NA") -> NA | U5: =COUNTIFS('Data Training 2022'!$F$6:$F$1048576,Dashboard!$A$4,'Data Training 2022'!$H$6:$H$1048576,Dashboard!B5,'Data Training 2022'!$AJ$6:$AJ$1048576,"TARGET") -> 0 | V5: =COUNTIFS('Data Training 2022'!$F$6:$F$1048576,Dashboard!$A$4,'Data Training 2022'!$H$6:$H$1048576,Dashboard!B5,'Data Training 2022'!$AL$6:$AL$1048576,"LULUS") -> 0 | W5: =IFERROR(V5/U5,"NA") -> NA | X5: =COUNTIFS('Data Training 2022'!$F$6:$F$1048576,Dashboard!$A$4,'Data Training 2022'!$H$6:$H$1048576,Dashboard!B5,'Data Training 2022'!$AM$6:$AM$1048576,"TARGET") -> 0 | Y5: =COUNTIFS('Data Training 2022'!$F$6:$F$1048576,Dashboard!$A$4,'Data Training 2022'!$H$6:$H$1048576,Dashboard!B5,'Data Training 2022'!$AO$6:$AO$1048576,"LULUS") -> 0 | Z5: =IFERROR(Y5/X5,"NA") -> NA | AA5: =COUNTIFS('Data Training 2022'!$F$6:$F$1048576,Dashboard!$A$4,'Data Training 2022'!$H$6:$H$1048576,Dashboard!B5,'Data Training 2022'!$AP$6:$AP$1048576,"TARGET") -> 0 | AB5: =COUNTIFS('Data Training 2022'!$F$6:$F$1048576,Dashboard!$A$4,'Data Training 2022'!$H$6:$H$1048576,Dashboard!B5,'Data Training 2022'!$AR$6:$AR$1048576,"LULUS") -> 0 | AC5: =IFERROR(AB5/AA5,"NA") -> NA | AD5: =COUNTIFS('Data Training 2022'!$F$6:$F$1048576,Dashboard!$A$4,'Data Training 2022'!$H$6:$H$1048576,Dashboard!B5,'Data Training 2022'!$AS$6:$AS$1048576,"TARGET") -> 0 | AE5: =COUNTIFS('Data Training 2022'!$F$6:$F$1048576,Dashboard!$A$4,'Data Training 2022'!$H$6:$H$1048576,Dashboard!B5,'Data Training 2022'!$AU$6:$AU$1048576,"LULUS") -> 0 | AF5: =IFERROR(AE5/AD5,"NA") -> NA
B6: PLANT | C6: =COUNTIFS('Data Training 2022'!$F$6:$F$1048576,Dashboard!$A$4,'Data Training 2022'!$H$6:$H$1048576,Dashboard!B6,'Data Training 2022'!$R$6:$R$1048576,"TARGET") -> 26 | D6: =COUNTIFS('Data Training 2022'!$F$6:$F$1048576,Dashboard!$A$4,'Data Training 2022'!$H$6:$H$1048576,Dashboard!B6,'Data Training 2022'!$T$6:$T$1048576,"LULUS") -> 25 | E6: =IFERROR(D6/C6,"NA") -> 0.96153846 | F6: =COUNTIFS('Data Training 2022'!$F$6:$F$1048576,Dashboard!$A$4,'Data Training 2022'!$H$6:$H$1048576,Dashboard!B6,'Data Training 2022'!$U$6:$U$1048576,"TARGET") -> 304 | G6: =COUNTIFS('Data Training 2022'!$F$6:$F$1048576,Dashboard!$A$4,'Data Training 2022'!$H$6:$H$1048576,Dashboard!B6,'Data Training 2022'!$W$6:$W$1048576,"LULUS") -> 280 | H6: =IFERROR(G6/F6,"NA") -> 0.92105263 | I6: =COUNTIFS('Data Training 2022'!$F$6:$F$1048576,Dashboard!$A$4,'Data Training 2022'!$H$6:$H$1048576,Dashboard!B6,'Data Training 2022'!$X$6:$X$1048576,"TARGET") -> 304 | J6: =COUNTIFS('Data Training 2022'!$F$6:$F$1048576,Dashboard!$A$4,'Data Training 2022'!$H$6:$H$1048576,Dashboard!B6,'Data Training 2022'!$Z$6:$Z$1048576,"LULUS") -> 217 | K6: =IFERROR(J6/I6,"NA") -> 0.71381579 | L6: =COUNTIFS('Data Training 2022'!$F$6:$F$1048576,Dashboard!$A$4,'Data Training 2022'!$H$6:$H$1048576,Dashboard!B6,'Data Training 2022'!$AA$6:$AA$1048576,"TARGET") -> 230 | M6: =COUNTIFS('Data Training 2022'!$F$6:$F$1048576,Dashboard!$A$4,'Data Training 2022'!$H$6:$H$1048576,Dashboard!B6,'Data Training 2022'!$AC$6:$AC$1048576,"LULUS") -> 59 | N6: =IFERROR(M6/L6,"NA") -> 0.25652174 | O6: =COUNTIFS('Data Training 2022'!$F$6:$F$1048576,Dashboard!$A$4,'Data Training 2022'!$H$6:$H$1048576,Dashboard!B6,'Data Training 2022'!$AD$6:$AD$1048576,"TARGET") -> 304 | P6: =COUNTIFS('Data Training 2022'!$F$6:$F$1048576,Dashboard!$A$4,'Data Training 2022'!$H$6:$H$1048576,Dashboard!B6,'Data Training 2022'!$AF$6:$AF$1048576,"LULUS") -> 0 | Q6: =IFERROR(P6/O6,"NA") -> 0 | R6: =COUNTIFS('Data Training 2022'!$F$6:$F$1048576,Dashboard!$A$4,'Data Training 2022'!$H$6:$H$1048576,Dashboard!B6,'Data Training 2022'!$AG$6:$AG$1048576,"TARGET") -> 206 | S6: =COUNTIFS('Data Training 2022'!$F$6:$F$1048576,Dashboard!$A$4,'Data Training 2022'!$H$6:$H$1048576,Dashboard!B6,'Data Training 2022'!$AI$6:$AI$1048576,"LULUS") -> 218 | T6: =IFERROR(S6/R6,"NA") -> 1.0582524 | U6: =COUNTIFS('Data Training 2022'!$F$6:$F$1048576,Dashboard!$A$4,'Data Training 2022'!$H$6:$H$1048576,Dashboard!B6,'Data Training 2022'!$AJ$6:$AJ$1048576,"TARGET") -> 7 | V6: =COUNTIFS('Data Training 2022'!$F$6:$F$1048576,Dashboard!$A$4,'Data Training 2022'!$H$6:$H$1048576,Dashboard!B6,'Data Training 2022'!$AL$6:$AL$1048576,"LULUS") -> 7 | W6: =IFERROR(V6/U6,"NA") -> 1 | X6: =COUNTIFS('Data Training 2022'!$F$6:$F$1048576,Dashboard!$A$4,'Data Training 2022'!$H$6:$H$1048576,Dashboard!B6,'Data Training 2022'!$AM$6:$AM$1048576,"TARGET") -> 29 | Y6: =COUNTIFS('Data Training 2022'!$F$6:$F$1048576,Dashboard!$A$4,'Data Training 2022'!$H$6:$H$1048576,Dashboard!B6,'Data Training 2022'!$AO$6:$AO$1048576,"LULUS") -> 28 | Z6: =IFERROR(Y6/X6,"NA") -> 0.96551724 | AA6: =COUNTIFS('Data Training 2022'!$F$6:$F$1048576,Dashboard!$A$4,'Data Training 2022'!$H$6:$H$1048576,Dashboard!B6,'Data Training 2022'!$AP$6:$AP$1048576,"TARGET") -> 0 | AB6: =COUNTIFS('Data Training 2022'!$F$6:$F$1048576,Dashboard!$A$4,'Data Training 2022'!$H$6:$H$1048576,Dashboard!B6,'Data Training 2022'!$AR$6:$AR$1048576,"LULUS") -> 0 | AC6: =IFERROR(AB6/AA6,"NA") -> NA | AD6: =COUNTIFS('Data Training 2022'!$F$6:$F$1048576,Dashboard!$A$4,'Data Training 2022'!$H$6:$H$1048576,Dashboard!B6,'Data Training 2022'!$AS$6:$AS$1048576,"TARGET") -> 0 | AE6: =COUNTIFS('Data Training 2022'!$F$6:$F$1048576,Dashboard!$A$4,'Data Training 2022'!$H$6:$H$1048576,Dashboard!B6,'Data Training 2022'!$AU$6:$AU$1048576,"LULUS") -> 0 | AF6: =IFERROR(AE6/AD6,"NA") -> NA
B7: ENGINEERING | C7: =COUNTIFS('Data Training 2022'!$F$6:$F$1048576,Dashboard!$A$4,'Data Training 2022'!$H$6:$H$1048576,Dashboard!B7,'Data Training 2022'!$R$6:$R$1048576,"TARGET") -> 4 | D7: =COUNTIFS('Data Training 2022'!$F$6:$F$1048576,Dashboard!$A$4,'Data Training 2022'!$H$6:$H$1048576,Dashboard!B7,'Data Training 2022'!$T$6:$T$1048576,"LULUS") -> 1 | E7: =IFERROR(D7/C7,"NA") -> 0.25 | F7: =COUNTIFS('Data Training 2022'!$F$6:$F$1048576,Dashboard!$A$4,'Data Training 2022'!$H$6:$H$1048576,Dashboard!B7,'Data Training 2022'!$U$6:$U$1048576,"TARGET") -> 16 | G7: =COUNTIFS('Data Training 2022'!$F$6:$F$1048576,Dashboard!$A$4,'Data Training 2022'!$H$6:$H$1048576,Dashboard!B7,'Data Training 2022'!$W$6:$W$1048576,"LULUS") -> 16 | H7: =IFERROR(G7/F7,"NA") -> 1 | I7: =COUNTIFS('Data Training 2022'!$F$6:$F$1048576,Dashboard!$A$4,'Data Training 2022'!$H$6:$H$1048576,Dashboard!B7,'Data Training 2022'!$X$6:$X$1048576,"TARGET") -> 16 | J7: =COUNTIFS('Data Training 2022'!$F$6:$F$1048576,Dashboard!$A$4,'Data Training 2022'!$H$6:$H$1048576,Dashboard!B7,'Data Training 2022'!$Z$6:$Z$1048576,"LULUS") -> 11 | K7: =IFERROR(J7/I7,"NA") -> 0.6875 | L7: =COUNTIFS('Data Training 2022'!$F$6:$F$1048576,Dashboard!$A$4,'Data Training 2022'!$H$6:$H$1048576,Dashboard!B7,'Data Training 2022'!$AA$6:$AA$1048576,"TARGET") -> 0 | M7: =COUNTIFS('Data Training 2022'!$F$6:$F$1048576,Dashboard!$A$4,'Data Training 2022'!$H$6:$H$1048576,Dashboard!B7,'Data Training 2022'!$AC$6:$AC$1048576,"LULUS") -> 0 | N7: =IFERROR(M7/L7,"NA") -> NA | O7: =COUNTIFS('Data Training 2022'!$F$6:$F$1048576,Dashboard!$A$4,'Data Training 2022'!$H$6:$H$1048576,Dashboard!B7,'Data Training 2022'!$AD$6:$AD$1048576,"TARGET") -> 16 | P7: =COUNTIFS('Data Training 2022'!$F$6:$F$1048576,Dashboard!$A$4,'Data Training 2022'!$H$6:$H$1048576,Dashboard!B7,'Data Training 2022'!$AF$6:$AF$1048576,"LULUS") -> 0 | Q7: =IFERROR(P7/O7,"NA") -> 0 | R7: =COUNTIFS('Data Training 2022'!$F$6:$F$1048576,Dashboard!$A$4,'Data Training 2022'!$H$6:$H$1048576,Dashboard!B7,'Data Training 2022'!$AG$6:$AG$1048576,"TARGET") -> 0 | S7: =COUNTIFS('Data Training 2022'!$F$6:$F$1048576,Dashboard!$A$4,'Data Training 2022'!$H$6:$H$1048576,Dashboard!B7,'Data Training 2022'!$AI$6:$AI$1048576,"LULUS") -> 0 | T7: =IFERROR(S7/R7,"NA") -> NA | U7: =COUNTIFS('Data Training 2022'!$F$6:$F$1048576,Dashboard!$A$4,'Data Training 2022'!$H$6:$H$1048576,Dashboard!B7,'Data Training 2022'!$AJ$6:$AJ$1048576,"TARGET") -> 0 | V7: =COUNTIFS('Data Training 2022'!$F$6:$F$1048576,Dashboard!$A$4,'Data Training 2022'!$H$6:$H$1048576,Dashboard!B7,'Data Training 2022'!$AL$6:$AL$1048576,"LULUS") -> 0 | W7: =IFERROR(V7/U7,"NA") -> NA | X7: =COUNTIFS('Data Training 2022'!$F$6:$F$1048576,Dashboard!$A$4,'Data Training 2022'!$H$6:$H$1048576,Dashboard!B7,'Data Training 2022'!$AM$6:$AM$1048576,"TARGET") -> 0 | Y7: =COUNTIFS('Data Training 2022'!$F$6:$F$1048576,Dashboard!$A$4,'Data Training 2022'!$H$6:$H$1048576,Dashboard!B7,'Data Training 2022'!$AO$6:$AO$1048576,"LULUS") -> 0 | Z7: =IFERROR(Y7/X7,"NA") -> NA | AA7: =COUNTIFS('Data Training 2022'!$F$6:$F$1048576,Dashboard!$A$4,'Data Training 2022'!$H$6:$H$1048576,Dashboard!B7,'Data Training 2022'!$AP$6:$AP$1048576,"TARGET") -> 0 | AB7: =COUNTIFS('Data Training 2022'!$F$6:$F$1048576,Dashboard!$A$4,'Data Training 2022'!$H$6:$H$1048576,Dashboard!B7,'Data Training 2022'!$AR$6:$AR$1048576,"LULUS") -> 0 | AC7: =IFERROR(AB7/AA7,"NA") -> NA | AD7: =COUNTIFS('Data Training 2022'!$F$6:$F$1048576,Dashboard!$A$4,'Data Training 2022'!$H$6:$H$1048576,Dashboard!B7,'Data Training 2022'!$AS$6:$AS$1048576,"TARGET") -> 0 | AE7: =COUNTIFS('Data Training 2022'!$F$6:$F$1048576,Dashboard!$A$4,'Data Training 2022'!$H$6:$H$1048576,Dashboard!B7,'Data Training 2022'!$AU$6:$AU$1048576,"LULUS") -> 0 | AF7: =IFERROR(AE7/AD7,"NA") -> NA
B8: LOGISTIC | C8: =COUNTIFS('Data Training 2022'!$F$6:$F$1048576,Dashboard!$A$4,'Data Training 2022'!$H$6:$H$1048576,Dashboard!B8,'Data Training 2022'!$R$6:$R$1048576,"TARGET") -> 11 | D8: =COUNTIFS('Data Training 2022'!$F$6:$F$1048576,Dashboard!$A$4,'Data Training 2022'!$H$6:$H$1048576,Dashboard!B8,'Data Training 2022'!$T$6:$T$1048576,"LULUS") -> 11 | E8: =IFERROR(D8/C8,"NA") -> 1 | F8: =COUNTIFS('Data Training 2022'!$F$6:$F$1048576,Dashboard!$A$4,'Data Training 2022'!$H$6:$H$1048576,Dashboard!B8,'Data Training 2022'!$U$6:$U$1048576,"TARGET") -> 29 | G8: =COUNTIFS('Data Training 2022'!$F$6:$F$1048576,Dashboard!$A$4,'Data Training 2022'!$H$6:$H$1048576,Dashboard!B8,'Data Training 2022'!$W$6:$W$1048576,"LULUS") -> 26 | H8: =IFERROR(G8/F8,"NA") -> 0.89655172 | I8: =COUNTIFS('Data Training 2022'!$F$6:$F$1048576,Dashboard!$A$4,'Data Training 2022'!$H$6:$H$1048576,Dashboard!B8,'Data Training 2022'!$X$6:$X$1048576,"TARGET") -> 29 | J8: =COUNTIFS('Data Training 2022'!$F$6:$F$1048576,Dashboard!$A$4,'Data Training 2022'!$H$6:$H$1048576,Dashboard!B8,'Data Training 2022'!$Z$6:$Z$1048576,"LULUS") -> 18 | K8: =IFERROR(J8/I8,"NA") -> 0.62068966 | L8: =COUNTIFS('Data Training 2022'!$F$6:$F$1048576,Dashboard!$A$4,'Data Training 2022'!$H$6:$H$1048576,Dashboard!B8,'Data Training 2022'!$AA$6:$AA$1048576,"TARGET") -> 6 | M8: =COUNTIFS('Data Training 2022'!$F$6:$F$1048576,Dashboard!$A$4,'Data Training 2022'!$H$6:$H$1048576,Dashboard!B8,'Data Training 2022'!$AC$6:$AC$1048576,"LULUS") -> 1 | N8: =IFERROR(M8/L8,"NA") -> 0.16666667 | O8: =COUNTIFS('Data Training 2022'!$F$6:$F$1048576,Dashboard!$A$4,'Data Training 2022'!$H$6:$H$1048576,Dashboard!B8,'Data Training 2022'!$AD$6:$AD$1048576,"TARGET") -> 29 | P8: =COUNTIFS('Data Training 2022'!$F$6:$F$1048576,Dashboard!$A$4,'Data Training 2022'!$H$6:$H$1048576,Dashboard!B8,'Data Training 2022'!$AF$6:$AF$1048576,"LULUS") -> 0 | Q8: =IFERROR(P8/O8,"NA") -> 0 | R8: =COUNTIFS('Data Training 2022'!$F$6:$F$1048576,Dashboard!$A$4,'Data Training 2022'!$H$6:$H$1048576,Dashboard!B8,'Data Training 2022'!$AG$6:$AG$1048576,"TARGET") -> 0 | S8: =COUNTIFS('Data Training 2022'!$F$6:$F$1048576,Dashboard!$A$4,'Data Training 2022'!$H$6:$H$1048576,Dashboard!B8,'Data Training 2022'!$AI$6:$AI$1048576,"LULUS") -> 0 | T8: =IFERROR(S8/R8,"NA") -> NA | U8: =COUNTIFS('Data Training 2022'!$F$6:$F$1048576,Dashboard!$A$4,'Data Training 2022'!$H$6:$H$1048576,Dashboard!B8,'Data Training 2022'!$AJ$6:$AJ$1048576,"TARGET") -> 0 | V8: =COUNTIFS('Data Training 2022'!$F$6:$F$1048576,Dashboard!$A$4,'Data Training 2022'!$H$6:$H$1048576,Dashboard!B8,'Data Training 2022'!$AL$6:$AL$1048576,"LULUS") -> 0 | W8: =IFERROR(V8/U8,"NA") -> NA | X8: =COUNTIFS('Data Training 2022'!$F$6:$F$1048576,Dashboard!$A$4,'Data Training 2022'!$H$6:$H$1048576,Dashboard!B8,'Data Training 2022'!$AM$6:$AM$1048576,"TARGET") -> 0 | Y8: =COUNTIFS('Data Training 2022'!$F$6:$F$1048576,Dashboard!$A$4,'Data Training 2022'!$H$6:$H$1048576,Dashboard!B8,'Data Training 2022'!$AO$6:$AO$1048576,"LULUS") -> 0 | Z8: =IFERROR(Y8/X8,"NA") -> NA | AA8: =COUNTIFS('Data Training 2022'!$F$6:$F$1048576,Dashboard!$A$4,'Data Training 2022'!$H$6:$H$1048576,Dashboard!B8,'Data Training 2022'!$AP$6:$AP$1048576,"TARGET") -> 0 | AB8: =COUNTIFS('Data Training 2022'!$F$6:$F$1048576,Dashboard!$A$4,'Data Training 2022'!$H$6:$H$1048576,Dashboard!B8,'Data Training 2022'!$AR$6:$AR$1048576,"LULUS") -> 0 | AC8: =IFERROR(AB8/AA8,"NA") -> NA | AD8: =COUNTIFS('Data Training 2022'!$F$6:$F$1048576,Dashboard!$A$4,'Data Training 2022'!$H$6:$H$1048576,Dashboard!B8,'Data Training 2022'!$AS$6:$AS$1048576,"TARGET") -> 0 | AE8: =COUNTIFS('Data Training 2022'!$F$6:$F$1048576,Dashboard!$A$4,'Data Training 2022'!$H$6:$H$1048576,Dashboard!B8,'Data Training 2022'!$AU$6:$AU$1048576,"LULUS") -> 0 | AF8: =IFERROR(AE8/AD8,"NA") -> NA
B9: HRGA & FA | C9: =COUNTIFS('Data Training 2022'!$F$6:$F$1048576,Dashboard!$A$4,'Data Training 2022'!$H$6:$H$1048576,Dashboard!B9,'Data Training 2022'!$R$6:$R$1048576,"TARGET") -> 10 | D9: =COUNTIFS('Data Training 2022'!$F$6:$F$1048576,Dashboard!$A$4,'Data Training 2022'!$H$6:$H$1048576,Dashboard!B9,'Data Training 2022'!$T$6:$T$1048576,"LULUS") -> 7 | E9: =IFERROR(D9/C9,"NA") -> 0.7 | F9: =COUNTIFS('Data Training 2022'!$F$6:$F$1048576,Dashboard!$A$4,'Data Training 2022'!$H$6:$H$1048576,Dashboard!B9,'Data Training 2022'!$U$6:$U$1048576,"TARGET") -> 51 | G9: =COUNTIFS('Data Training 2022'!$F$6:$F$1048576,Dashboard!$A$4,'Data Training 2022'!$H$6:$H$1048576,Dashboard!B9,'Data Training 2022'!$W$6:$W$1048576,"LULUS") -> 49 | H9: =IFERROR(G9/F9,"NA") -> 0.96078431 | I9: =COUNTIFS('Data Training 2022'!$F$6:$F$1048576,Dashboard!$A$4,'Data Training 2022'!$H$6:$H$1048576,Dashboard!B9,'Data Training 2022'!$X$6:$X$1048576,"TARGET") -> 51 | J9: =COUNTIFS('Data Training 2022'!$F$6:$F$1048576,Dashboard!$A$4,'Data Training 2022'!$H$6:$H$1048576,Dashboard!B9,'Data Training 2022'!$Z$6:$Z$1048576,"LULUS") -> 24 | K9: =IFERROR(J9/I9,"NA") -> 0.47058824 | L9: =COUNTIFS('Data Training 2022'!$F$6:$F$1048576,Dashboard!$A$4,'Data Training 2022'!$H$6:$H$1048576,Dashboard!B9,'Data Training 2022'!$AA$6:$AA$1048576,"TARGET") -> 16 | M9: =COUNTIFS('Data Training 2022'!$F$6:$F$1048576,Dashboard!$A$4,'Data Training 2022'!$H$6:$H$1048576,Dashboard!B9,'Data Training 2022'!$AC$6:$AC$1048576,"LULUS") -> 3 | N9: =IFERROR(M9/L9,"NA") -> 0.1875 | O9: =COUNTIFS('Data Training 2022'!$F$6:$F$1048576,Dashboard!$A$4,'Data Training 2022'!$H$6:$H$1048576,Dashboard!B9,'Data Training 2022'!$AD$6:$AD$1048576,"TARGET") -> 51 | P9: =COUNTIFS('Data Training 2022'!$F$6:$F$1048576,Dashboard!$A$4,'Data Training 2022'!$H$6:$H$1048576,Dashboard!B9,'Data Training 2022'!$AF$6:$AF$1048576,"LULUS") -> 0 | Q9: =IFERROR(P9/O9,"NA") -> 0 | R9: =COUNTIFS('Data Training 2022'!$F$6:$F$1048576,Dashboard!$A$4,'Data Training 2022'!$H$6:$H$1048576,Dashboard!B9,'Data Training 2022'!$AG$6:$AG$1048576,"TARGET") -> 0 | S9: =COUNTIFS('Data Training 2022'!$F$6:$F$1048576,Dashboard!$A$4,'Data Training 2022'!$H$6:$H$1048576,Dashboard!B9,'Data Training 2022'!$AI$6:$AI$1048576,"LULUS") -> 1 | T9: =IFERROR(S9/R9,"NA") -> NA | U9: =COUNTIFS('Data Training 2022'!$F$6:$F$1048576,Dashboard!$A$4,'Data Training 2022'!$H$6:$H$1048576,Dashboard!B9,'Data Training 2022'!$AJ$6:$AJ$1048576,"TARGET") -> 0 | V9: =COUNTIFS('Data Training 2022'!$F$6:$F$1048576,Dashboard!$A$4,'Data Training 2022'!$H$6:$H$1048576,Dashboard!B9,'Data Training 2022'!$AL$6:$AL$1048576,"LULUS") -> 0 | W9: =IFERROR(V9/U9,"NA") -> NA | X9: =COUNTIFS('Data Training 2022'!$F$6:$F$1048576,Dashboard!$A$4,'Data Training 2022'!$H$6:$H$1048576,Dashboard!B9,'Data Training 2022'!$AM$6:$AM$1048576,"TARGET") -> 2 | Y9: =COUNTIFS('Data Training 2022'!$F$6:$F$1048576,Dashboard!$A$4,'Data Training 2022'!$H$6:$H$1048576,Dashboard!B9,'Data Training 2022'!$AO$6:$AO$1048576,"LULUS") -> 2 | Z9: =IFERROR(Y9/X9,"NA") -> 1 | AA9: =COUNTIFS('Data Training 2022'!$F$6:$F$1048576,Dashboard!$A$4,'Data Training 2022'!$H$6:$H$1048576,Dashboard!B9,'Data Training 2022'!$AP$6:$AP$1048576,"TARGET") -> 0 | AB9: =COUNTIFS('Data Training 2022'!$F$6:$F$1048576,Dashboard!$A$4,'Data Training 2022'!$H$6:$H$1048576,Dashboard!B9,'Data Training 2022'!$AR$6:$AR$1048576,"LULUS") -> 0 | AC9: =IFERROR(AB9/AA9,"NA") -> NA | AD9: =COUNTIFS('Data Training 2022'!$F$6:$F$1048576,Dashboard!$A$4,'Data Training 2022'!$H$6:$H$1048576,Dashboard!B9,'Data Training 2022'!$AS$6:$AS$1048576,"TARGET") -> 0 | AE9: =COUNTIFS('Data Training 2022'!$F$6:$F$1048576,Dashboard!$A$4,'Data Training 2022'!$H$6:$H$1048576,Dashboard!B9,'Data Training 2022'!$AU$6:$AU$1048576,"LULUS") -> 0 | AF9: =IFERROR(AE9/AD9,"NA") -> NA
B10: SHE | C10: =COUNTIFS('Data Training 2022'!$F$6:$F$1048576,Dashboard!$A$4,'Data Training 2022'!$H$6:$H$1048576,Dashboard!B10,'Data Training 2022'!$R$6:$R$1048576,"TARGET") -> 3 | D10: =COUNTIFS('Data Training 2022'!$F$6:$F$1048576,Dashboard!$A$4,'Data Training 2022'!$H$6:$H$1048576,Dashboard!B10,'Data Training 2022'!$T$6:$T$1048576,"LULUS") -> 4 | E10: =IFERROR(D10/C10,"NA") -> 1.3333333 | F10: =COUNTIFS('Data Training 2022'!$F$6:$F$1048576,Dashboard!$A$4,'Data Training 2022'!$H$6:$H$1048576,Dashboard!B10,'Data Training 2022'!$U$6:$U$1048576,"TARGET") -> 23 | G10: =COUNTIFS('Data Training 2022'!$F$6:$F$1048576,Dashboard!$A$4,'Data Training 2022'!$H$6:$H$1048576,Dashboard!B10,'Data Training 2022'!$W$6:$W$1048576,"LULUS") -> 23 | H10: =IFERROR(G10/F10,"NA") -> 1 | I10: =COUNTIFS('Data Training 2022'!$F$6:$F$1048576,Dashboard!$A$4,'Data Training 2022'!$H$6:$H$1048576,Dashboard!B10,'Data Training 2022'!$X$6:$X$1048576,"TARGET") -> 23 | J10: =COUNTIFS('Data Training 2022'!$F$6:$F$1048576,Dashboard!$A$4,'Data Training 2022'!$H$6:$H$1048576,Dashboard!B10,'Data Training 2022'!$Z$6:$Z$1048576,"LULUS") -> 13 | K10: =IFERROR(J10/I10,"NA") -> 0.56521739 | L10: =COUNTIFS('Data Training 2022'!$F$6:$F$1048576,Dashboard!$A$4,'Data Training 2022'!$H$6:$H$1048576,Dashboard!B10,'Data Training 2022'!$AA$6:$AA$1048576,"TARGET") -> 0 | M10: =COUNTIFS('Data Training 2022'!$F$6:$F$1048576,Dashboard!$A$4,'Data Training 2022'!$H$6:$H$1048576,Dashboard!B10,'Data Training 2022'!$AC$6:$AC$1048576,"LULUS") -> 1 | N10: =IFERROR(M10/L10,"NA") -> NA | O10: =COUNTIFS('Data Training 2022'!$F$6:$F$1048576,Dashboard!$A$4,'Data Training 2022'!$H$6:$H$1048576,Dashboard!B10,'Data Training 2022'!$AD$6:$AD$1048576,"TARGET") -> 23 | P10: =COUNTIFS('Data Training 2022'!$F$6:$F$1048576,Dashboard!$A$4,'Data Training 2022'!$H$6:$H$1048576,Dashboard!B10,'Data Training 2022'!$AF$6:$AF$1048576,"LULUS") -> 0 | Q10: =IFERROR(P10/O10,"NA") -> 0 | R10: =COUNTIFS('Data Training 2022'!$F$6:$F$1048576,Dashboard!$A$4,'Data Training 2022'!$H$6:$H$1048576,Dashboard!B10,'Data Training 2022'!$AG$6:$AG$1048576,"TARGET") -> 0 | S10: =COUNTIFS('Data Training 2022'!$F$6:$F$1048576,Dashboard!$A$4,'Data Training 2022'!$H$6:$H$1048576,Dashboard!B10,'Data Training 2022'!$AI$6:$AI$1048576,"LULUS") -> 3 | T10: =IFERROR(S10/R10,"NA") -> NA | U10: =COUNTIFS('Data Training 2022'!$F$6:$F$1048576,Dashboard!$A$4,'Data Training 2022'!$H$6:$H$1048576,Dashboard!B10,'Data Training 2022'!$AJ$6:$AJ$1048576,"TARGET") -> 1 | V10: =COUNTIFS('Data Training 2022'!$F$6:$F$1048576,Dashboard!$A$4,'Data Training 2022'!$H$6:$H$1048576,Dashboard!B10,'Data Training 2022'!$AL$6:$AL$1048576,"LULUS") -> 1 | W10: =IFERROR(V10/U10,"NA") -> 1 | X10: =COUNTIFS('Data Training 2022'!$F$6:$F$1048576,Dashboard!$A$4,'Data Training 2022'!$H$6:$H$1048576,Dashboard!B10,'Data Training 2022'!$AM$6:$AM$1048576,"TARGET") -> 0 | Y10: =COUNTIFS('Data Training 2022'!$F$6:$F$1048576,Dashboard!$A$4,'Data Training 2022'!$H$6:$H$1048576,Dashboard!B10,'Data Training 2022'!$AO$6:$AO$1048576,"LULUS") -> 1 | Z10: =IFERROR(Y10/X10,"NA") -> NA | AA10: =COUNTIFS('Data Training 2022'!$F$6:$F$1048576,Dashboard!$A$4,'Data Training 2022'!$H$6:$H$1048576,Dashboard!B10,'Data Training 2022'!$AP$6:$AP$1048576,"TARGET") -> 0 | AB10: =COUNTIFS('Data Training 2022'!$F$6:$F$1048576,Dashboard!$A$4,'Data Training 2022'!$H$6:$H$1048576,Dashboard!B10,'Data Training 2022'!$AR$6:$AR$1048576,"LULUS") -> 0 | AC10: =IFERROR(AB10/AA10,"NA") -> NA | AD10: =COUNTIFS('Data Training 2022'!$F$6:$F$1048576,Dashboard!$A$4,'Data Training 2022'!$H$6:$H$1048576,Dashboard!B10,'Data Training 2022'!$AS$6:$AS$1048576,"TARGET") -> 0 | AE10: =COUNTIFS('Data Training 2022'!$F$6:$F$1048576,Dashboard!$A$4,'Data Training 2022'!$H$6:$H$1048576,Dashboard!B10,'Data Training 2022'!$AU$6:$AU$1048576,"LULUS") -> 0 | AF10: =IFERROR(AE10/AD10,"NA") -> NA
B12: =A4 -> PT. SAPTAINDRA SEJATI

Sheet Data Training 2022
A2: DATA TRAINING SIS & MITRA KERJA 2022
A3: 0 | B3: 1 | C3: 2 | D3: 3 | E3: 4 | F3: 5 | G3: 6 | H3: 7 | I3: 8 | J3: 9 | K3: 10 | L3: 11 | M3: 12 | N3: 13 | O3: 14 | P3: 15 | Q3: 16 | R3: 17 | S3: 18 | T3: 19 | U3: 20 | V3: 21 | W3: 22 | X3: 23 | Y3: 24 | Z3: 25 | AA3: 26 | AB3: 27 | AC3: 28 | AD3: 29 | AE3: 30 | AF3: 31 | AG3: 32 | AH3: 33 | AI3: 34 | AJ3: 35 | AK3: 36 | AL3: 37 | AM3: 38 | AN3: 39 | AO3: 40 | AP3: 41 | AQ3: 42 | AR3: 43 | AS3: 44 | AT3: 45 | AU3: 46
A4: NO | B4: ID CONTROL | C4: ID PERUSAHAN | D4: MINE PERMIT ID | E4: NAMA | F4: PERUSAHAN | G4: POSISI | H4: SECTION | I4: LOKASI | J4: AREA PJA | K4: KLASIFIKASIJABATAN | L4: FUNGSI JABATAN | M4: SERTIFIKASI POP/POM/POU | N4: STATUS POP/POM/POU | O4: SERTIFIKASI | R4: TRAINING INTERNAL | U4: TRAINING INTERNAL | X4: TRAINING INTERNAL | AA4: TRAINING INTERNAL | AD4: TRAINING INTERNAL | AG4: TRAINING INTERNAL | AJ4: TRAINING INTERNAL | AM4: TRAINING INTERNAL | AP4: TRAINING INTERNAL | AS4: TRAINING INTERNAL
O5: POP | P5: POM | Q5: POU | R5: Target Pelatihan | S5: Pra POP | T5: Status | U5: Target Pelatihan | V5: Induksi | W5: Status | X5: Target Pelatihan | Y5: Re-Induksi Pasca Cuti | Z5: Status | AA5: Target Pelatihan | AB5: BSA | AC5: Status | AD5: Target Pelatihan | AE5: BLS | AF5: Status | AG5: Target Pelatihan | AH5: Isolasi | AI5: Status | AJ5: Target Pelatihan | AK5: Bekerja Dekat Air | AL5: Status | AM5: Target Pelatihan | AN5: Bekerja di Ketinggian | AO5: Status | AP5: Target Pelatihan | AQ5: Bekerja di Ruang Terbatas | AR5: Status | AS5: Target Pelatihan | AT5: Basic Tools Keeper | AU5: Status
A6: 1 | B6: =TEXT(C6,"00000000") -> 00125489 | C6: 00125489 | E6: EKO ISWANTO | F6: PT. SAPTAINDRA SEJATI | G6: PROJECT MANAGER | H6: OPERATION | I6: MINING-HAULING-PORT | K6: S | L6: PENGAWAS | M6: TARGET | N6: SUDAH | O6: =IFERROR(VLOOKUP(B6,POP!$B$5:$I$1048576,7,0),"") | P6: =IFERROR(VLOOKUP(B6,POM!$B$5:$I$1048576,7,0),"") | Q6: =IFERROR(VLOOKUP(B6,POU!$B$5:$I$1048576,7,0),"") -> 39154 | R6: =IF(AND(L6="PENGAWAS",M6="TARGET",N6=""),"TARGET","") | S6: =IFERROR(VLOOKUP(B6,'PEMBEKALAN POP'!$B$5:$I$1048576,7,0),"") | T6: =IFERROR(VLOOKUP(B6,'PEMBEKALAN POP'!$B$5:$I$1048576,8,0),"") | U6: TARGET | V6: {=MAX(IF(INDUKSI!$B$5:$B$1048576='Data Training 2022'!B6,INDUKSI!$H$5:$H$1048576))} -> #N/A | W6: =IFERROR(VLOOKUP(B6,INDUKSI!$B$5:$I$1048576,8,0),"") -> LULUS | X6: TARGET | Y6: {=MAX(IF(REINDUKSI!$B$5:$B$1048576='Data Training 2022'!B6,REINDUKSI!$H$5:$H$1048576))} -> 0 | Z6: =IFERROR(VLOOKUP(B6,REINDUKSI!$B$5:$I$1048576,8,0),"") | AA6: =IF(L6="OPERATOR","TARGET",IF(L6="MEKANIK","TARGET","")) | AB6: {=MAX(IF(BSA!$B$5:$B$1048576='Data Training 2022'!B6,BSA!$H$5:$H$1048576))} -> 0 | AC6: =IFERROR(VLOOKUP(B6,BSA!$B$5:$I$1048576,8,0),"") | AD6: TARGET | AG6: =IF(L6="MEKANIK","TARGET","") | AH6: {=MAX(IF(ISOLASI!$B$5:$B$1048576='Data Training 2022'!B6,ISOLASI!$H$5:$H$1048576))} -> 0 | AI6: =IFERROR(VLOOKUP(B6,ISOLASI!$B$5:$I$1048576,8,0),"") | AK6: {=MAX(IF('DEKAT AIR'!$B$5:$B$1048576='Data Training 2022'!B6,'DEKAT AIR'!$H$5:$H$1048576))} -> 0 | AL6: =IFERROR(VLOOKUP(B6,'DEKAT AIR'!$B$5:$I$1048576,8,0),"") | AN6: {=MAX(IF(KETINGGIAN!$B$5:$B$1048576='Data Training 2022'!B6,KETINGGIAN!$H$5:$H$1048576))} -> 0 | AO6: =IFERROR(VLOOKUP(B6,KETINGGIAN!$B$5:$I$1048576,8,0),"") | AT6: {=MAX(IF(TOOLSKEEPER!$B$5:$B$1048576='Data Training 2022'!B6,TOOLSKEEPER!$H$5:$H$1048576))} -> 0 | AU6: =IFERROR(VLOOKUP(B6,TOOLSKEEPER!$B$5:$I$1048576,8,0),"")
A7: =A6+1 -> 2 | B7: =TEXT(C7,"00000000") -> 00108258 | C7: 00108258 | E7: BENNY PERMANA | F7: PT. SAPTAINDRA SEJATI | G7: SECTION HEAD | H7: SHE | I7: MINING-HAULING-PORT | K7: S | L7: PENGAWAS | M7: TARGET | N7: SUDAH | O7: =IFERROR(VLOOKUP(B7,POP!$B$5:$I$1048576,7,0),"") | P7: =IFERROR(VLOOKUP(B7,POM!$B$5:$I$1048576,7,0),"") -> 42013 | Q7: =IFERROR(VLOOKUP(B7,POU!$B$5:$I$1048576,7,0),"") | R7: =IF(AND(L7="PENGAWAS",M7="TARGET",N7=""),"TARGET","") | S7: =IFERROR(VLOOKUP(B7,'PEMBEKALAN POP'!$B$5:$I$1048576,7,0),"") | T7: =IFERROR(VLOOKUP(B7,'PEMBEKALAN POP'!$B$5:$I$1048576,8,0),"") | U7: TARGET | V7: {=MAX(IF(INDUKSI!$B$5:$B$1048576='Data Training 2022'!B7,INDUKSI!$H$5:$H$1048576))} -> #N/A | W7: =IFERROR(VLOOKUP(B7,INDUKSI!$B$5:$I$1048576,8,0),"") -> LULUS | X7: TARGET | Y7: {=MAX(IF(REINDUKSI!$B$5:$B$1048576='Data Training 2022'!B7,REINDUKSI!$H$5:$H$1048576))} -> 44693 | Z7: =IFERROR(VLOOKUP(B7,REINDUKSI!$B$5:$I$1048576,8,0),"") -> LULUS | AA7: =IF(L7="OPERATOR","TARGET",IF(L7="MEKANIK","TARGET","")) | AB7: {=MAX(IF(BSA!$B$5:$B$1048576='Data Training 2022'!B7,BSA!$H$5:$H$1048576))} -> 0 | AC7: =IFERROR(VLOOKUP(B7,BSA!$B$5:$I$1048576,8,0),"") | AD7: TARGET | AG7: =IF(L7="MEKANIK","TARGET","") | AH7: {=MAX(IF(ISOLASI!$B$5:$B$1048576='Data Training 2022'!B7,ISOLASI!$H$5:$H$1048576))} -> 0 | AI7: =IFERROR(VLOOKUP(B7,ISOLASI!$B$5:$I$1048576,8,0),"") | AK7: {=MAX(IF('DEKAT AIR'!$B$5:$B$1048576='Data Training 2022'!B7,'DEKAT AIR'!$H$5:$H$1048576))} -> 0 | AL7: =IFERROR(VLOOKUP(B7,'DEKAT AIR'!$B$5:$I$1048576,8,0),"") | AN7: {=MAX(IF(KETINGGIAN!$B$5:$B$1048576='Data Training 2022'!B7,KETINGGIAN!$H$5:$H$1048576))} -> 0 | AO7: =IFERROR(VLOOKUP(B7,KETINGGIAN!$B$5:$I$1048576,8,0),"") | AT7: {=MAX(IF(TOOLSKEEPER!$B$5:$B$1048576='Data Training 2022'!B7,TOOLSKEEPER!$H$5:$H$1048576))} -> 0 | AU7: =IFERROR(VLOOKUP(B7,TOOLSKEEPER!$B$5:$I$1048576,8,0),"")
A8: =A7+1 -> 3 | B8: =TEXT(C8,"00000000") -> 00118157 | C8: 00118157 | E8: SIMSON SONY ROSIDI | F8: PT. SAPTAINDRA SEJATI | G8: UNIT HEAD | H8: SHE | I8: MINING-HAULING-PORT | K8: S | L8: PENGAWAS | M8: TARGET | N8: SUDAH | O8: =IFERROR(VLOOKUP(B8,POP!$B$5:$I$1048576,7,0),"") -> 43444 | P8: =IFERROR(VLOOKUP(B8,POM!$B$5:$I$1048576,7,0),"") | Q8: =IFERROR(VLOOKUP(B8,POU!$B$5:$I$1048576,7,0),"") | R8: =IF(AND(L8="PENGAWAS",M8="TARGET",N8=""),"TARGET","") | S8: =IFERROR(VLOOKUP(B8,'PEMBEKALAN POP'!$B$5:$I$1048576,7,0),"") | T8: =IFERROR(VLOOKUP(B8,'PEMBEKALAN POP'!$B$5:$I$1048576,8,0),"") | U8: TARGET | V8: {=MAX(IF(INDUKSI!$B$5:$B$1048576='Data Training 2022'!B8,INDUKSI!$H$5:$H$1048576))} -> #N/A | W8: =IFERROR(VLOOKUP(B8,INDUKSI!$B$5:$I$1048576,8,0),"") -> LULUS | X8: TARGET | Y8: {=MAX(IF(REINDUKSI!$B$5:$B$1048576='Data Training 2022'!B8,REINDUKSI!$H$5:$H$1048576))} -> 0 | Z8: =IFERROR(VLOOKUP(B8,REINDUKSI!$B$5:$I$1048576,8,0),"") | AA8: =IF(L8="OPERATOR","TARGET",IF(L8="MEKANIK","TARGET","")) | AB8: {=MAX(IF(BSA!$B$5:$B$1048576='Data Training 2022'!B8,BSA!$H$5:$H$1048576))} -> 0 | AC8: =IFERROR(VLOOKUP(B8,BSA!$B$5:$I$1048576,8,0),"") | AD8: TARGET | AG8: =IF(L8="MEKANIK","TARGET","") | AH8: {=MAX(IF(ISOLASI!$B$5:$B$1048576='Data Training 2022'!B8,ISOLASI!$H$5:$H$1048576))} -> 0 | AI8: =IFERROR(VLOOKUP(B8,ISOLASI!$B$5:$I$1048576,8,0),"") | AK8: {=MAX(IF('DEKAT AIR'!$B$5:$B$1048576='Data Training 2022'!B8,'DEKAT AIR'!$H$5:$H$1048576))} -> 0 | AL8: =IFERROR(VLOOKUP(B8,'DEKAT AIR'!$B$5:$I$1048576,8,0),"") | AN8: {=MAX(IF(KETINGGIAN!$B$5:$B$1048576='Data Training 2022'!B8,KETINGGIAN!$H$5:$H$1048576))} -> 0 | AO8: =IFERROR(VLOOKUP(B8,KETINGGIAN!$B$5:$I$1048576,8,0),"") | AT8: {=MAX(IF(TOOLSKEEPER!$B$5:$B$1048576='Data Training 2022'!B8,TOOLSKEEPER!$H$5:$H$1048576))} -> 0 | AU8: =IFERROR(VLOOKUP(B8,TOOLSKEEPER!$B$5:$I$1048576,8,0),"")
A9: =A8+1 -> 4 | B9: =TEXT(C9,"00000000") -> 01111018 | C9: 01111018 | E9: PRASETYA JOKO PRANOTO | F9: PT. SAPTAINDRA SEJATI | G9: UNIT HEAD | H9: SHE | I9: MINING-HAULING-PORT | K9: S | L9: PENGAWAS | M9: TARGET | N9: SUDAH | O9: =IFERROR(VLOOKUP(B9,POP!$B$5:$I$1048576,7,0),"") -> 42475 | P9: =IFERROR(VLOOKUP(B9,POM!$B$5:$I$1048576,7,0),"") | Q9: =IFERROR(VLOOKUP(B9,POU!$B$5:$I$1048576,7,0),"") | R9: =IF(AND(L9="PENGAWAS",M9="TARGET",N9=""),"TARGET","") | S9: =IFERROR(VLOOKUP(B9,'PEMBEKALAN POP'!$B$5:$I$1048576,7,0),"") | T9: =IFERROR(VLOOKUP(B9,'PEMBEKALAN POP'!$B$5:$I$1048576,8,0),"") | U9: TARGET | V9: {=MAX(IF(INDUKSI!$B$5:$B$1048576='Data Training 2022'!B9,INDUKSI!$H$5:$H$1048576))} -> #N/A | W9: =IFERROR(VLOOKUP(B9,INDUKSI!$B$5:$I$1048576,8,0),"") -> LULUS | X9: TARGET | Y9: {=MAX(IF(REINDUKSI!$B$5:$B$1048576='Data Training 2022'!B9,REINDUKSI!$H$5:$H$1048576))} -> 44476 | Z9: =IFERROR(VLOOKUP(B9,REINDUKSI!$B$5:$I$1048576,8,0),"") -> LULUS | AA9: =IF(L9="OPERATOR","TARGET",IF(L9="MEKANIK","TARGET","")) | AB9: {=MAX(IF(BSA!$B$5:$B$1048576='Data Training 2022'!B9,BSA!$H$5:$H$1048576))} -> 0 | AC9: =IFERROR(VLOOKUP(B9,BSA!$B$5:$I$1048576,8,0),"") | AD9: TARGET | AG9: =IF(L9="MEKANIK","TARGET","") | AH9: {=MAX(IF(ISOLASI!$B$5:$B$1048576='Data Training 2022'!B9,ISOLASI!$H$5:$H$1048576))} -> 0 | AI9: =IFERROR(VLOOKUP(B9,ISOLASI!$B$5:$I$1048576,8,0),"") | AK9: {=MAX(IF('DEKAT AIR'!$B$5:$B$1048576='Data Training 2022'!B9,'DEKAT AIR'!$H$5:$H$1048576))} -> 0 | AL9: =IFERROR(VLOOKUP(B9,'DEKAT AIR'!$B$5:$I$1048576,8,0),"") | AN9: {=MAX(IF(KETINGGIAN!$B$5:$B$1048576='Data Training 2022'!B9,KETINGGIAN!$H$5:$H$1048576))} -> 0 | AO9: =IFERROR(VLOOKUP(B9,KETINGGIAN!$B$5:$I$1048576,8,0),"") | AT9: {=MAX(IF(TOOLSKEEPER!$B$5:$B$1048576='Data Training 2022'!B9,TOOLSKEEPER!$H$5:$H$1048576))} -> 0 | AU9: =IFERROR(VLOOKUP(B9,TOOLSKEEPER!$B$5:$I$1048576,8,0),"")
A10: =A9+1 -> 5 | B10: =TEXT(C10,"00000000") -> 00108425 | C10: 00108425 | E10: ROBBY | F10: PT. SAPTAINDRA SEJATI | G10: UNIT HEAD | H10: SHE | I10: MINING-HAULING-PORT | K10: S | L10: PENGAWAS | M10: TARGET | N10: SUDAH | O10: =IFERROR(VLOOKUP(B10,POP!$B$5:$I$1048576,7,0),"") -> 42041 | P10: =IFERROR(VLOOKUP(B10,POM!$B$5:$I$1048576,7,0),"") | Q10: =IFERROR(VLOOKUP(B10,POU!$B$5:$I$1048576,7,0),"") | R10: =IF(AND(L10="PENGAWAS",M10="TARGET",N10=""),"TARGET","") | S10: =IFERROR(VLOOKUP(B10,'PEMBEKALAN POP'!$B$5:$I$1048576,7,0),"") | T10: =IFERROR(VLOOKUP(B10,'PEMBEKALAN POP'!$B$5:$I$1048576,8,0),"") | U10: TARGET | V10: {=MAX(IF(INDUKSI!$B$5:$B$1048576='Data Training 2022'!B10,INDUKSI!$H$5:$H$1048576))} -> #N/A | W10: =IFERROR(VLOOKUP(B10,INDUKSI!$B$5:$I$1048576,8,0),"") -> LULUS | X10: TARGET | Y10: {=MAX(IF(REINDUKSI!$B$5:$B$1048576='Data Training 2022'!B10,REINDUKSI!$H$5:$H$1048576))} -> 0 | Z10: =IFERROR(VLOOKUP(B10,REINDUKSI!$B$5:$I$1048576,8,0),"") | AA10: =IF(L10="OPERATOR","TARGET",IF(L10="MEKANIK","TARGET","")) | AB10: {=MAX(IF(BSA!$B$5:$B$1048576='Data Training 2022'!B10,BSA!$H$5:$H$1048576))} -> 0 | AC10: =IFERROR(VLOOKUP(B10,BSA!$B$5:$I$1048576,8,0),"") | AD10: TARGET | AG10: =IF(L10="MEKANIK","TARGET","") | AH10: {=MAX(IF(ISOLASI!$B$5:$B$1048576='Data Training 2022'!B10,ISOLASI!$H$5:$H$1048576))} -> 0 | AI10: =IFERROR(VLOOKUP(B10,ISOLASI!$B$5:$I$1048576,8,0),"") | AK10: {=MAX(IF('DEKAT AIR'!$B$5:$B$1048576='Data Training 2022'!B10,'DEKAT AIR'!$H$5:$H$1048576))} -> 0 | AL10: =IFERROR(VLOOKUP(B10,'DEKAT AIR'!$B$5:$I$1048576,8,0),"") | AN10: {=MAX(IF(KETINGGIAN!$B$5:$B$1048576='Data Training 2022'!B10,KETINGGIAN!$H$5:$H$1048576))} -> 0 | AO10: =IFERROR(VLOOKUP(B10,KETINGGIAN!$B$5:$I$1048576,8,0),"") | AT10: {=MAX(IF(TOOLSKEEPER!$B$5:$B$1048576='Data Training 2022'!B10,TOOLSKEEPER!$H$5:$H$1048576))} -> 0 | AU10: =IFERROR(VLOOKUP(B10,TOOLSKEEPER!$B$5:$I$1048576,8,0),"")
A11: =A10+1 -> 6 | B11: =TEXT(C11,"00000000") -> 00117238 | C11: 00117238 | E11: WAHYU SETIYO WIBOWO | F11: PT. SAPTAINDRA SEJATI | G11: GROUP LEADER | H11: SHE | I11: MINING-HAULING-PORT | K11: S | L11: PENGAWAS | M11: TARGET | N11: SUDAH | O11: =IFERROR(VLOOKUP(B11,POP!$B$5:$I$1048576,7,0),"") -> 43523 | P11: =IFERROR(VLOOKUP(B11,POM!$B$5:$I$1048576,7,0),"") | Q11: =IFERROR(VLOOKUP(B11,POU!$B$5:$I$1048576,7,0),"") | R11: =IF(AND(L11="PENGAWAS",M11="TARGET",N11=""),"TARGET","") | S11: =IFERROR(VLOOKUP(B11,'PEMBEKALAN POP'!$B$5:$I$1048576,7,0),"") | T11: =IFERROR(VLOOKUP(B11,'PEMBEKALAN POP'!$B$5:$I$1048576,8,0),"") | U11: TARGET | V11: {=MAX(IF(INDUKSI!$B$5:$B$1048576='Data Training 2022'!B11,INDUKSI!$H$5:$H$1048576))} -> #N/A | W11: =IFERROR(VLOOKUP(B11,INDUKSI!$B$5:$I$1048576,8,0),"") -> LULUS | X11: TARGET | Y11: {=MAX(IF(REINDUKSI!$B$5:$B$1048576='Data Training 2022'!B11,REINDUKSI!$H$5:$H$1048576))} -> 44549 | Z11: =IFERROR(VLOOKUP(B11,REINDUKSI!$B$5:$I$1048576,8,0),"") -> LULUS | AA11: =IF(L11="OPERATOR","TARGET",IF(L11="MEKANIK","TARGET","")) | AB11: {=MAX(IF(BSA!$B$5:$B$1048576='Data Training 2022'!B11,BSA!$H$5:$H$1048576))} -> 0 | AC11: =IFERROR(VLOOKUP(B11,BSA!$B$5:$I$1048576,8,0),"") | AD11: TARGET | AG11: =IF(L11="MEKANIK","TARGET","") | AH11: {=MAX(IF(ISOLASI!$B$5:$B$1048576='Data Training 2022'!B11,ISOLASI!$H$5:$H$1048576))} -> 0 | AI11: =IFERROR(VLOOKUP(B11,ISOLASI!$B$5:$I$1048576,8,0),"") | AK11: {=MAX(IF('DEKAT AIR'!$B$5:$B$1048576='Data Training 2022'!B11,'DEKAT AIR'!$H$5:$H$1048576))} -> 0 | AL11: =IFERROR(VLOOKUP(B11,'DEKAT AIR'!$B$5:$I$1048576,8,0),"") | AN11: {=MAX(IF(KETINGGIAN!$B$5:$B$1048576='Data Training 2022'!B11,KETINGGIAN!$H$5:$H$1048576))} -> 0 | AO11: =IFERROR(VLOOKUP(B11,KETINGGIAN!$B$5:$I$1048576,8,0),"") | AT11: {=MAX(IF(TOOLSKEEPER!$B$5:$B$1048576='Data Training 2022'!B11,TOOLSKEEPER!$H$5:$H$1048576))} -> 0 | AU11: =IFERROR(VLOOKUP(B11,TOOLSKEEPER!$B$5:$I$1048576,8,0),"")
A12: =A11+1 -> 7 | B12: =TEXT(C12,"00000000") -> 00117261 | C12: 00117261 | E12: I GUSTI MADE SUTA ADNYANA | F12: PT. SAPTAINDRA SEJATI | G12: GROUP LEADER | H12: SHE | I12: MINING-HAULING-PORT | K12: S | L12: PENGAWAS | M12: TARGET | N12: SUDAH | O12: =IFERROR(VLOOKUP(B12,POP!$B$5:$I$1048576,7,0),"") -> 44438 | P12: =IFERROR(VLOOKUP(B12,POM!$B$5:$I$1048576,7,0),"") | Q12: =IFERROR(VLOOKUP(B12,POU!$B$5:$I$1048576,7,0),"") | R12: =IF(AND(L12="PENGAWAS",M12="TARGET",N12=""),"TARGET","") | S12: =IFERROR(VLOOKUP(B12,'PEMBEKALAN POP'!$B$5:$I$1048576,7,0),"") | T12: =IFERROR(VLOOKUP(B12,'PEMBEKALAN POP'!$B$5:$I$1048576,8,0),"") | U12: TARGET | V12: {=MAX(IF(INDUKSI!$B$5:$B$1048576='Data Training 2022'!B12,INDUKSI!$H$5:$H$1048576))} -> #N/A | W12: =IFERROR(VLOOKUP(B12,INDUKSI!$B$5:$I$1048576,8,0),"") -> LULUS | X12: TARGET | Y12: {=MAX(IF(REINDUKSI!$B$5:$B$1048576='Data Training 2022'!B12,REINDUKSI!$H$5:$H$1048576))} -> 44461 | Z12: =IFERROR(VLOOKUP(B12,REINDUKSI!$B$5:$I$1048576,8,0),"") -> LULUS | AA12: =IF(L12="OPERATOR","TARGET",IF(L12="MEKANIK","TARGET","")) | AB12: {=MAX(IF(BSA!$B$5:$B$1048576='Data Training 2022'!B12,BSA!$H$5:$H$1048576))} -> 0 | AC12: =IFERROR(VLOOKUP(B12,BSA!$B$5:$I$1048576,8,0),"") | AD12: TARGET | AG12: =IF(L12="MEKANIK","TARGET","") | AH12: {=MAX(IF(ISOLASI!$B$5:$B$1048576='Data Training 2022'!B12,ISOLASI!$H$5:$H$1048576))} -> 0 | AI12: =IFERROR(VLOOKUP(B12,ISOLASI!$B$5:$I$1048576,8,0),"") | AK12: {=MAX(IF('DEKAT AIR'!$B$5:$B$1048576='Data Training 2022'!B12,'DEKAT AIR'!$H$5:$H$1048576))} -> 0 | AL12: =IFERROR(VLOOKUP(B12,'DEKAT AIR'!$B$5:$I$1048576,8,0),"") | AN12: {=MAX(IF(KETINGGIAN!$B$5:$B$1048576='Data Training 2022'!B12,KETINGGIAN!$H$5:$H$1048576))} -> 0 | AO12: =IFERROR(VLOOKUP(B12,KETINGGIAN!$B$5:$I$1048576,8,0),"") | AT12: {=MAX(IF(TOOLSKEEPER!$B$5:$B$1048576='Data Training 2022'!B12,TOOLSKEEPER!$H$5:$H$1048576))} -> 0 | AU12: =IFERROR(VLOOKUP(B12,TOOLSKEEPER!$B$5:$I$1048576,8,0),"")
A13: =A12+1 -> 8 | B13: =TEXT(C13,"00000000") -> 00117347 | C13: 00117347 | E13: ROCHMAD SULISTYANTO KUNCORO | F13: PT. SAPTAINDRA SEJATI | G13: GROUP LEADER | H13: SHE | I13: MINING-HAULING-PORT | K13: S | L13: PENGAWAS | M13: TARGET | N13: SUDAH | O13: =IFERROR(VLOOKUP(B13,POP!$B$5:$I$1048576,7,0),"") -> 44237 | P13: =IFERROR(VLOOKUP(B13,POM!$B$5:$I$1048576,7,0),"") | Q13: =IFERROR(VLOOKUP(B13,POU!$B$5:$I$1048576,7,0),"") | R13: =IF(AND(L13="PENGAWAS",M13="TARGET",N13=""),"TARGET","") | S13: =IFERROR(VLOOKUP(B13,'PEMBEKALAN POP'!$B$5:$I$1048576,7,0),"") | T13: =IFERROR(VLOOKUP(B13,'PEMBEKALAN POP'!$B$5:$I$1048576,8,0),"") | U13: TARGET | V13: {=MAX(IF(INDUKSI!$B$5:$B$1048576='Data Training 2022'!B13,INDUKSI!$H$5:$H$1048576))} -> #N/A | W13: =IFERROR(VLOOKUP(B13,INDUKSI!$B$5:$I$1048576,8,0),"") -> LULUS | X13: TARGET | Y13: {=MAX(IF(REINDUKSI!$B$5:$B$1048576='Data Training 2022'!B13,REINDUKSI!$H$5:$H$1048576))} -> 0 | Z13: =IFERROR(VLOOKUP(B13,REINDUKSI!$B$5:$I$1048576,8,0),"") | AA13: =IF(L13="OPERATOR","TARGET",IF(L13="MEKANIK","TARGET","")) | AB13: {=MAX(IF(BSA!$B$5:$B$1048576='Data Training 2022'!B13,BSA!$H$5:$H$1048576))} -> 0 | AC13: =IFERROR(VLOOKUP(B13,BSA!$B$5:$I$1048576,8,0),"") | AD13: TARGET | AG13: =IF(L13="MEKANIK","TARGET","") | AH13: {=MAX(IF(ISOLASI!$B$5:$B$1048576='Data Training 2022'!B13,ISOLASI!$H$5:$H$1048576))} -> 0 | AI13: =IFERROR(VLOOKUP(B13,ISOLASI!$B$5:$I$1048576,8,0),"") | AK13: {=MAX(IF('DEKAT AIR'!$B$5:$B$1048576='Data Training 2022'!B13,'DEKAT AIR'!$H$5:$H$1048576))} -> 0 | AL13: =IFERROR(VLOOKUP(B13,'DEKAT AIR'!$B$5:$I$1048576,8,0),"") | AN13: {=MAX(IF(KETINGGIAN!$B$5:$B$1048576='Data Training 2022'!B13,KETINGGIAN!$H$5:$H$1048576))} -> 0 | AO13: =IFERROR(VLOOKUP(B13,KETINGGIAN!$B$5:$I$1048576,8,0),"") | AT13: {=MAX(IF(TOOLSKEEPER!$B$5:$B$1048576='Data Training 2022'!B13,TOOLSKEEPER!$H$5:$H$1048576))} -> 0 | AU13: =IFERROR(VLOOKUP(B13,TOOLSKEEPER!$B$5:$I$1048576,8,0),"")
