Workbook
Name a: #REF!
Name a: #REF!
Name a: #REF!
Name a: #REF!
Name a: #REF!
Name aa: #REF!
Name aa: #REF!
Name aa: #REF!
Name aa: #REF!
Name aa: #REF!
Name aaaa: #REF!
Name aaaa: #REF!
Name aaaa: #REF!
Name aaaa: #REF!
Name aaaa: #REF!
Name accident: [1]Insiden!$I$21:$I$29
Name Alat: [2]Validasi!$H$8:$H$26
Name Area: [3]Sum!$C$77:$C$79
Name as: #REF!
Name as: #REF!
Name as: #REF!
Name as: #REF!
Name as: #REF!
Name Company: [3]Sum!$J$46:$J$87
Name Departemen: [2]Validasi!$C$8:$C$22
Name Departments: [3]Sum!$G$9:$G$26
Name ENGINEERING: "eng"
Name Excel_BuiltIn__FilterDatabase_6: #REF!
Name Excel_BuiltIn__FilterDatabase_6: #REF!
Name Excel_BuiltIn__FilterDatabase_6: #REF!
Name Excel_BuiltIn__FilterDatabase_6: #REF!
Name Excel_BuiltIn__FilterDatabase_6: #REF!
Name Excel_BuiltIn__FilterDatabase_8: #REF!
Name Excel_BuiltIn__FilterDatabase_8: #REF!
Name Excel_BuiltIn__FilterDatabase_8: #REF!
Name Excel_BuiltIn__FilterDatabase_8: #REF!
Name Excel_BuiltIn__FilterDatabase_8: #REF!
Name Excel_BuiltIn_Print_Area: #REF!
Name Excel_BuiltIn_Print_Area: #REF!
Name Excel_BuiltIn_Print_Area: #REF!
Name Excel_BuiltIn_Print_Area: #REF!
Name Excel_BuiltIn_Print_Area: #REF!
Name F.Pekerjaan: [4]Sum!$C$26:$C$34
Name F.Pribadi: [4]Sum!$C$17:$C$22
Name Faktor_Pekerjaan: [5]Sum!$C$46:$C$53
Name Faktor_Pribadi: [5]Sum!$C$36:$C$43
Name Hari: [2]Validasi!$N$8:$N$14
Name Jabatan: [5]Sum!$G$77:$G$94
Name Jam: [2]Validasi!$Q$9:$Q$32
Name Jenis_Kontak: [5]Sum!$C$59:$C$72
Name Job: [2]Validasi!$M$8:$M$15
Name Kondisi_tidak_aman: [5]Sum!$C$20:$C$33
Name Kontak: [2]Validasi!$I$8:$I$22
Name KTA: [2]Validasi!$K$8:$K$21
Name Lama: [2]Validasi!$P$7:$P$12
Name LOGISTIC_HEAVY_EQUIP: "log"
Name Lokasi: [2]Validasi!$D$8:$D$26
Name MACO: #REF!
Name MACO: #REF!
Name MACO: #REF!

Sheet Dashboard Monthly (2)
B2: 2022
B3: PARAMETER | C3: UNIT | D3: JAN | E3: FEB | F3: MAR | G3: APR | H3: MEI | I3: JUNI | J3: JULI | K3: AUG | L3: SEPT | M3: OCT | N3: NOV | O3: DES | P3: YTD 2022 | R3: PARAMETER | S3: UNIT | T3: Q1 | U3: Q2 | V3: Q3 | W3: Q4 | X3: 2022
B4: SAFETY INSIDENT | R4: Safety Incident
B5: TOTAL INCIDENT | C5: Freq | D5: =SUM(D6:D13) -> 12 | E5: =SUM(E6:E13) -> 5 | F5: =SUM(F6:F13) -> 7 | G5: =SUM(G6:G13) -> 9 | H5: =SUM(H6:H13) -> 10 | I5: =SUM(I6:I13) -> 8 | J5: =SUM(J6:J13) -> 7 | K5: =SUM(K6:K13) -> 9 | ... P5: =SUM(P6:P13) -> 73 | R5: Total Inciden | S5: Freq | T5: =SUM(T6:T13) -> 24 | U5: =SUM(U6:U13) -> 27 | V5: =SUM(V6:V13) -> 19 | W5: =SUM(W6:W13) -> 3 | X5: =SUM(T5:W5) -> 73
B6: FATALITY | C6: Freq | D6: - | E6: - | F6: - | G6: - | H6: - | I6: - | J6: - | K6: - | L6: - | M6: - | N6: - | O6: - | P6: =SUM(D6:O6) -> 0 | R6: Fatality | S6: Freq | T6: =SUM(D6:F6) -> 0 | U6: =SUM(G6:I6) -> 0 | V6: =SUM(J6:L6) -> 0 | W6: =SUM(M6:O6) -> 0 | X6: =SUM(T6:W6) -> 0
B7: LTI | C7: Freq | D7: - | E7: - | F7: - | G7: - | H7: - | I7: - | J7: - | K7: - | L7: - | M7: - | N7: - | O7: - | P7: =SUM(D7:O7) -> 0 | R7: LTI | S7: Freq | T7: =SUM(D7:F7) -> 0 | U7: =SUM(G7:I7) -> 0 | V7: =SUM(J7:L7) -> 0 | W7: =SUM(M7:O7) -> 0 | X7: =SUM(T7:W7) -> 0
B8: MTI | C8: Freq | D8: - | E8: 1 | F8: - | G8: - | H8: - | I8: - | J8: 2 | K8: - | L8: - | M8: - | N8: - | O8: - | P8: =SUM(D8:O8) -> 3 | R8: First Aid | S8: Freq | T8: =SUM(D8:F8) -> 1 | U8: =SUM(G8:I8) -> 0 | V8: =SUM(J8:L8) -> 2 | W8: =SUM(M8:O8) -> 0 | X8: =SUM(T8:W8) -> 3
B9: FAI | C9: Freq | D9: - | E9: - | G9: - | I9: - | K9: - | L9: - | M9: - | N9: - | O9: - | P9: =SUM(D9:O9) -> 0 | R9: MTI | S9: Freq | T9: =SUM(D9:F9) -> 0 | U9: =SUM(G9:I9) -> 0 | V9: =SUM(J9:L9) -> 0 | W9: =SUM(M9:O9) -> 0 | X9: =SUM(T9:W9) -> 0
B10: PROPERTY DAMAGE | C10: Freq | D10: 6 | E10: 2 | F10: 5 | G10: 6 | H10: 4 | I10: 5 | J10: 3 | K10: 3 | L10: 2 | M10: 2 | N10: - | O10: - | P10: =SUM(D10:O10) -> 38 | R10: Properti Damage | S10: Freq | T10: =SUM(D10:F10) -> 13 | U10: =SUM(G10:I10) -> 15 | V10: =SUM(J10:L10) -> 8 | W10: =SUM(M10:O10) -> 2 | X10: =SUM(T10:W10) -> 38
B11: FIRE CASE | C11: Freq | D11: - | E11: - | F11: - | G11: - | H11: - | I11: - | J11: - | K11: - | L11: - | M11: - | N11: - | O11: - | P11: =SUM(D11:O11) -> 0 | R11: Fire Case | S11: Freq | T11: =SUM(D11:F11) -> 0 | U11: =SUM(G11:I11) -> 0 | V11: =SUM(J11:L11) -> 0 | W11: =SUM(M11:O11) -> 0 | X11: =SUM(T11:W11) -> 0
B12: ENVIRONMENT | C12: Freq | D12: 1 | E12: - | F12: - | G12: 1 | H12: 1 | I12: 1 | J12: 1 | K12: 1 | L12: - | M12: 1 | N12: - | O12: - | P12: =SUM(D12:O12) -> 7 | R12: Environment | S12: Freq | T12: =SUM(D12:F12) -> 1 | U12: =SUM(G12:I12) -> 3 | V12: =SUM(J12:L12) -> 2 | W12: =SUM(M12:O12) -> 1 | X12: =SUM(T12:W12) -> 7
B13: NEARMISS | C13: Freq | D13: 5 | E13: 2 | F13: 2 | G13: 2 | H13: 5 | I13: 2 | J13: 1 | K13: 5 | L13: 1 | M13: - | N13: - | O13: - | P13: =SUM(D13:O13) -> 25 | R13: Near Miss | S13: Freq | T13: =SUM(D13:F13) -> 9 | U13: =SUM(G13:I13) -> 9 | V13: =SUM(J13:L13) -> 7 | W13: =SUM(M13:O13) -> 0 | X13: =SUM(T13:W13) -> 25
B16: SHE Legal Compliance | E16: Audit SMKP | I16: SAP YTD 2021
B17: Patuh | C17: 0.97 | E17: Patuh | F17: 0.71 | I17: Observasi | J17: 0.88
B18: Tidak Patuh | C18: 0.03 | E18: Tidak Patuh | F18: 0.29 | I18: Hazard | J18: 0.74 | AE18: =25*40% -> 10
I19: Inspeksi | J19: 0.98
R20: 8406 | S20: 1668
R21: 167 | S21: 62
R22: =SUM(R20:R21) -> 8573 | S22: =SUM(S20:S21) -> 1730
B33: SAFETY INSIDENT | C33: Unit | D33: MTD Vs | E33: Okt-21 | F33: Okt-22 | G33: Long Term | H33: 2019 | I33: 2020 | J33: 2021 | K33: 2022 | N33: Total Incident | O33: HPRI | P33: NON HPRI
B34: Total Incident | C34: Freq | E34: =SUM(E37:E44) -> 41 | F34: =SUM(F37:F44) -> 73 | H34: =SUM(H37:H44) -> 5 | I34: =SUM(I37:I44) -> 28 | J34: =SUM(J37:J44) -> 48 | K34: =SUM(K37:K44) -> 73 | L34: =(54-32)/32 -> 0.6875 | M34: 2019 | N34: 5 | O34: 2 | P34: 3
B35: HPRI | C35: Freq | H35: 2 | I35: 13 | J35: 11 | K35: =O37 -> 34 | M35: 2020 | N35: 28 | O35: 13 | P35: 15
B36: NON HPRI | C36: Freq | H36: 0 | I36: 15 | J36: 37 | K36: =P37 -> 39 | M36: 2021 | N36: 48 | O36: 11 | P36: 37
B37: Fatality | C37: Freq | E37: 1 | F37: 0 | H37: 0 | I37: 0 | J37: 1 | K37: =F37 -> 0 | M37: 2022 | N37: =SUM(O37:P37) -> 73 | O37: 34 | P37: 39
B38: LTI | C38: Freq | E38: 0 | F38: 0 | H38: 0 | I38: 1 | J38: 1 | K38: =F38 -> 0
B39: FA | C39: Freq | E39: 5 | F39: 0 | H39: 1 | I39: 9 | J39: 5 | K39: =F39 -> 0
B40: MTI | C40: Freq | E40: 0 | F40: 3 | H40: 0 | I40: 0 | J40: 0 | K40: =F40 -> 3 | N40: Hauling | O40: Mining | P40: Workshop | Q40: Mess
B41: PD | C41: Freq | E41: 21 | F41: 38 | H41: 4 | I41: 15 | J41: 25 | K41: =F41 -> 38 | M41: Total Incident | N41: =SUM(N42:N43) -> 59 | O41: =SUM(O42:O43) -> 9 | P41: =SUM(P42:P43) -> 4 | Q41: =SUM(Q42:Q43) -> 1
B42: FC | C42: Freq | E42: 0 | F42: 0 | H42: 0 | I42: 0 | J42: 0 | K42: =F42 -> 0 | M42: HPRI | N42: 29 | O42: 4 | P42: 0 | Q42: 1
B43: EI | C43: Freq | E43: 2 | F43: 7 | H43: 0 | I43: 0 | J43: 2 | K43: =F43 -> 7 | M43: NON HPRI | N43: 30 | O43: 5 | P43: 4 | Q43: 0
B44: NM | C44: Freq | E44: 12 | F44: 25 | H44: 0 | I44: 3 | J44: 14 | K44: =F44 -> 25
P48: 9272 | Q48: 1915
P49: 814 | Q49: 159
P50: =SUM(P48:P49) -> 10086 | Q50: =SUM(Q48:Q49) -> 2074 | AI50: =9272+1915 -> 11187
P51: =SUM(P50:Q50) -> 12160
C56: =5/C63 -> 0.71428571
C57: =C62/C63 -> 0.14285714
B59: Penyebab dasar insiden | C59: Basic Cause | D59: % | F59: Kurangnya Keterampilan | G59: Kurangnya Pengawasan | H59: Kurangnya pengetahuan | I59: Pelanggaran Prosedur | J59: Prosedur Kerja Tidak Memadai | Q59: =10/70 -> 0.14285714
B60: Employee Awareness | C60: 6 | D60: =C60/$C$63 -> 0.85714286 | F60: 13 | H60: 2 | I60: 22
B61: SOP Compliance | C61: 0 | D61: =C61/$C$63 -> 0 | J61: 4
...

Sheet Dashboard Monthly
B2: 2022
B3: Parameter | C3: Unit | D3: JAN | E3: FEB | F3: MAR | G3: APR | H3: MEI | I3: JUNI | J3: JULI | K3: AUG | L3: SEPT | M3: OCT | N3: NOV | O3: DES | P3: Ytd 2021 | R3: Parameter | S3: Unit | T3: Q1 | U3: Q2 | V3: Q3 | W3: Q4 | X3: 2021
B4: Safety Incident | R4: Safety Incident
B5: Total Inciden | C5: Freq | D5: =SUM(D6:D13) -> 12 | E5: =SUM(E6:E13) -> 5 | F5: =SUM(F6:F13) -> 7 | G5: =SUM(G6:G13) -> 9 | H5: =SUM(H6:H13) -> 10 | I5: =SUM(I6:I13) -> 8 | J5: =SUM(J6:J13) -> 6 | K5: =SUM(K6:K13) -> 0 | ... P5: =SUM(P6:P13) -> 57 | R5: Total Inciden | S5: Freq | T5: =SUM(T6:T13) -> 24 | U5: =SUM(U6:U13) -> 27 | V5: =SUM(V6:V13) -> 6 | W5: =SUM(W6:W13) -> 0 | X5: =SUM(T5:W5) -> 57
B6: Fatality | C6: Freq | D6: - | E6: - | F6: - | G6: - | H6: - | I6: - | J6: - | K6: - | L6: - | M6: - | N6: - | O6: - | P6: =SUM(D6:O6) -> 0 | R6: Fatality | S6: Freq | T6: =SUM(D6:F6) -> 0 | U6: =SUM(G6:I6) -> 0 | V6: =SUM(J6:L6) -> 0 | W6: =SUM(M6:O6) -> 0 | X6: =SUM(T6:W6) -> 0
B7: LTI | C7: Freq | D7: - | E7: - | F7: - | G7: - | H7: - | I7: - | J7: - | K7: - | L7: - | M7: - | N7: - | O7: - | P7: =SUM(D7:O7) -> 0 | R7: LTI | S7: Freq | T7: =SUM(D7:F7) -> 0 | U7: =SUM(G7:I7) -> 0 | V7: =SUM(J7:L7) -> 0 | W7: =SUM(M7:O7) -> 0 | X7: =SUM(T7:W7) -> 0
B8: First Aid | C8: Freq | D8: - | E8: - | F8: - | G8: - | H8: - | I8: - | J8: - | K8: - | L8: - | M8: - | N8: - | O8: - | P8: =SUM(D8:O8) -> 0 | R8: First Aid | S8: Freq | T8: =SUM(D8:F8) -> 0 | U8: =SUM(G8:I8) -> 0 | V8: =SUM(J8:L8) -> 0 | W8: =SUM(M8:O8) -> 0 | X8: =SUM(T8:W8) -> 0
B9: MTI | C9: Freq | D9: - | E9: 1 | F9: - | G9: - | H9: - | I9: - | J9: 2 | K9: - | L9: - | M9: - | N9: - | O9: - | P9: =SUM(D9:O9) -> 3 | R9: MTI | S9: Freq | T9: =SUM(D9:F9) -> 1 | U9: =SUM(G9:I9) -> 0 | V9: =SUM(J9:L9) -> 2 | W9: =SUM(M9:O9) -> 0 | X9: =SUM(T9:W9) -> 3
B10: Properti Damage | C10: Freq | D10: 4 | E10: 2 | F10: 5 | G10: 6 | H10: 3 | I10: 5 | J10: 3 | K10: - | L10: - | M10: - | N10: - | O10: - | P10: =SUM(D10:O10) -> 28 | R10: Properti Damage | S10: Freq | T10: =SUM(D10:F10) -> 11 | U10: =SUM(G10:I10) -> 14 | V10: =SUM(J10:L10) -> 3 | W10: =SUM(M10:O10) -> 0 | X10: =SUM(T10:W10) -> 28
B11: Fire Case | C11: Freq | D11: - | E11: - | F11: - | G11: - | H11: - | I11: - | J11: - | K11: - | L11: - | M11: - | N11: - | O11: - | P11: =SUM(D11:O11) -> 0 | R11: Fire Case | S11: Freq | T11: =SUM(D11:F11) -> 0 | U11: =SUM(G11:I11) -> 0 | V11: =SUM(J11:L11) -> 0 | W11: =SUM(M11:O11) -> 0 | X11: =SUM(T11:W11) -> 0
B12: Environment | C12: Freq | D12: 1 | E12: - | F12: - | G12: 1 | H12: 1 | I12: 1 | J12: - | K12: - | L12: - | M12: - | N12: - | O12: - | P12: =SUM(D12:O12) -> 4 | R12: Environment | S12: Freq | T12: =SUM(D12:F12) -> 1 | U12: =SUM(G12:I12) -> 3 | V12: =SUM(J12:L12) -> 0 | W12: =SUM(M12:O12) -> 0 | X12: =SUM(T12:W12) -> 4
B13: Near Miss | C13: Freq | D13: 7 | E13: 2 | F13: 2 | G13: 2 | H13: 6 | I13: 2 | J13: 1 | K13: - | L13: - | M13: - | N13: - | O13: - | P13: =SUM(D13:O13) -> 22 | R13: Near Miss | S13: Freq | T13: =SUM(D13:F13) -> 11 | U13: =SUM(G13:I13) -> 10 | V13: =SUM(J13:L13) -> 1 | W13: =SUM(M13:O13) -> 0 | X13: =SUM(T13:W13) -> 22
B16: SHE Legal Compliance | E16: Audit SMKP | I16: SAP YTD 2021
B17: Patuh | C17: 0.97 | E17: Patuh | F17: 0.65 | I17: Observasi | J17: 0.88
B18: Tidak Patuh | C18: 0.05 | E18: Tidak Patuh | F18: 0.35 | I18: Hazard | J18: 0.74
I19: Inspeksi | J19: 0.98
B33: c | C33: Unit | D33: MTD Vs | E33: Jul-21 | F33: Jul-22 | G33: Long Term | H33: 2019 | I33: 2020 | J33: 2021 | K33: 2022
B34: Safety Incident
B35: Total Incident | C35: Freq | E35: =SUM(E36:E43) -> 57 | F35: =SUM(F36:F43) -> 57 | H35: =SUM(H36:H43) -> 5 | I35: =SUM(I36:I43) -> 28 | J35: =SUM(J36:J43) -> 48 | K35: =SUM(K36:K43) -> 57 | M35: =(J35-I35)/J35 -> 0.41666667 | O35: =21/28 -> 0.75
B36: Fatality | C36: Freq | E36: =SUM(D6:J6) -> 0 | F36: 0 | H36: 0 | I36: 0 | J36: 1 | K36: =F36 -> 0 | M36: =28+28 -> 56
B37: LTI | C37: Freq | E37: =SUM(D7:J7) -> 0 | F37: 0 | H37: 0 | I37: 1 | J37: 1 | K37: =F37 -> 0
B38: FA | C38: Freq | E38: =SUM(D8:J8) -> 0 | F38: 0 | H38: 1 | I38: 9 | J38: 5 | K38: =F38 -> 0
B39: MTI | C39: Freq | E39: =SUM(D9:J9) -> 3 | F39: 3 | H39: 0 | I39: 0 | J39: 0 | K39: =F39 -> 3
B40: PD | C40: Freq | E40: =SUM(D10:J10) -> 28 | F40: 28 | H40: 4 | I40: 15 | J40: 25 | K40: =F40 -> 28
B41: FC | C41: Freq | E41: =SUM(D11:J11) -> 0 | F41: 0 | H41: 0 | I41: 0 | J41: 0 | K41: =F41 -> 0 | P41: =4119+197 -> 4316
B42: EI | C42: Freq | E42: =SUM(D12:J12) -> 4 | F42: 4 | H42: 0 | I42: 0 | J42: 2 | K42: =F42 -> 4 | P42: =859+81 -> 940
B43: NM | C43: Freq | E43: =SUM(D13:J13) -> 22 | F43: 22 | H43: 0 | I43: 3 | J43: 14 | K43: =F43 -> 22
D64: 2019 | E64: 2020 | F64: 2021 | G64: 2022 | K64: Total Incident | L64: Fatality | M64: LTI
B65: Total Incident | C65: Freq | D65: 5 | E65: 28 | F65: 49 | G65: 17 | J65: 2019 | K65: 5 | L65: 0 | M65: 0
B66: Fatality | C66: Freq | D66: 0 | E66: 0 | F66: 1 | G66: 0 | J66: 2020 | K66: 28 | L66: 0 | M66: 1
B67: LTI | C67: Freq | D67: 0 | E67: 1 | F67: 1 | G67: 0 | J67: 2021 | K67: 49 | L67: 1 | M67: 1
J68: 2022 | K68: 17 | L68: 0 | M68: 0
B76: 2019 | C76: 5
B77: 2020 | C77: 28
B78: 2021 | C78: 48
B79: 44749 | C79: 57
C81: HPRI | D81: NONHPRI
B82: 2019 | C82: 2 | D82: 3
B83: 2020 | C83: 13 | D83: 15
B84: 2021 | C84: 11 | D84: 37
...

Sheet DASHBOARD
C5: DASHBOARD MONITORING INSIDEN YTD 2022
C11: NO | D11: BULAN | E11: MAN POWER | F11: MAN HOURS | G11: MAN HOURS NLTI | H11: KTA | J11: Jumlah Insiden | S11: LOST DAY | T11: LOST COST | U11: LTIFR/FR | V11: AIFR | W11: PDFR | X11: LTI SR | Y11: IR | Z11: LR
I12: TTA | J12: NM | K12: PD | L12: FAI | M12: MTI | N12: RWI | O12: LTI | P12: FATAL | Q12: EI | R12: TOTAL INSIDEN
C13: 1 | D13: JAN | E13: 1100 | F13: 307708 | G13: =F13/31*31 -> 307708 | H13: 1621 | I13: 365 | J13: =COUNTIFS('BASIC CAUSE INSIDEN'!$N$2:$N$1048576,DASHBOARD!$J$12,'BASIC CAUSE INSIDEN'!$F$2:$F$1048576,DASHBOARD!$D13) -> 5 | K13: =COUNTIFS('BASIC CAUSE INSIDEN'!$N$2:$N$1048576,DASHBOARD!$K$12,'BASIC CAUSE INSIDEN'!$F$2:$F$1048576,DASHBOARD!$D13) -> 6 | L13: =COUNTIFS('BASIC CAUSE INSIDEN'!$N$2:$N$1048576,DASHBOARD!$L$12,'BASIC CAUSE INSIDEN'!$F$2:$F$1048576,DASHBOARD!$D13) -> 0 | M13: =COUNTIFS('BASIC CAUSE INSIDEN'!$N$2:$N$1048576,DASHBOARD!$M$12,'BASIC CAUSE INSIDEN'!$F$2:$F$1048576,DASHBOARD!$D13) -> 0 | N13: =COUNTIFS('BASIC CAUSE INSIDEN'!$N$2:$N$1048576,DASHBOARD!$N$12,'BASIC CAUSE INSIDEN'!$F$2:$F$1048576,DASHBOARD!$D13) -> 0 | O13: =COUNTIFS('BASIC CAUSE INSIDEN'!$N$2:$N$1048576,DASHBOARD!$O$12,'BASIC CAUSE INSIDEN'!$F$2:$F$1048576,DASHBOARD!$D13) -> 0 | P13: =COUNTIFS('BASIC CAUSE INSIDEN'!$N$2:$N$1048576,DASHBOARD!$P$12,'BASIC CAUSE INSIDEN'!$F$2:$F$1048576,DASHBOARD!$D13) -> 0 | Q13: =COUNTIFS('BASIC CAUSE INSIDEN'!$N$2:$N$1048576,DASHBOARD!$Q$12,'BASIC CAUSE INSIDEN'!$F$2:$F$1048576,DASHBOARD!$D13) -> 1 | R13: =SUM(J13:Q13) -> 12 | S13: 31 | T13: 5.6898963e+08 | U13: =(O13*1000000)/F13 -> 0 | V13: {=SUM(K13:P13*1000000)/F13} -> 19.499006 | W13: =(K13*1000000)/F13 -> 19.499006 | X13: =(S13*1000000)/F13 -> 100.74486 | Y13: {=SUM(K13:P13*1000000)/F13} -> 19.499006 | Z13: =T13/F13 -> 1849.122
C14: 2 | D14: FEB | E14: 1117 | F14: 260112 | G14: =F14/28*28 -> 260112 | H14: 1493 | I14: 334 | J14: =COUNTIFS('BASIC CAUSE INSIDEN'!$N$2:$N$1048576,DASHBOARD!$J$12,'BASIC CAUSE INSIDEN'!$F$2:$F$1048576,DASHBOARD!$D14) -> 2 | K14: =COUNTIFS('BASIC CAUSE INSIDEN'!$N$2:$N$1048576,DASHBOARD!$K$12,'BASIC CAUSE INSIDEN'!$F$2:$F$1048576,DASHBOARD!$D14) -> 2 | L14: =COUNTIFS('BASIC CAUSE INSIDEN'!$N$2:$N$1048576,DASHBOARD!$L$12,'BASIC CAUSE INSIDEN'!$F$2:$F$1048576,DASHBOARD!$D14) -> 0 | M14: =COUNTIFS('BASIC CAUSE INSIDEN'!$N$2:$N$1048576,DASHBOARD!$M$12,'BASIC CAUSE INSIDEN'!$F$2:$F$1048576,DASHBOARD!$D14) -> 1 | N14: =COUNTIFS('BASIC CAUSE INSIDEN'!$N$2:$N$1048576,DASHBOARD!$N$12,'BASIC CAUSE INSIDEN'!$F$2:$F$1048576,DASHBOARD!$D14) -> 0 | O14: =COUNTIFS('BASIC CAUSE INSIDEN'!$N$2:$N$1048576,DASHBOARD!$O$12,'BASIC CAUSE INSIDEN'!$F$2:$F$1048576,DASHBOARD!$D14) -> 0 | P14: =COUNTIFS('BASIC CAUSE INSIDEN'!$N$2:$N$1048576,DASHBOARD!$P$12,'BASIC CAUSE INSIDEN'!$F$2:$F$1048576,DASHBOARD!$D14) -> 0 | Q14: =COUNTIFS('BASIC CAUSE INSIDEN'!$N$2:$N$1048576,DASHBOARD!$Q$12,'BASIC CAUSE INSIDEN'!$F$2:$F$1048576,DASHBOARD!$D14) -> 0 | R14: =SUM(J14:Q14) -> 5 | S14: 28 | T14: 9.8178707e+08 | U14: =(O14*1000000)/F14 -> 0 | V14: {=SUM(K14:P14*1000000)/F14} -> 11.533493 | W14: =(K14*1000000)/F14 -> 7.6889955 | X14: =(S14*1000000)/F14 -> 107.64594 | Y14: {=SUM(K14:P14*1000000)/F14} -> 11.533493 | Z14: =T14/F14 -> 3774.4782
C15: 3 | D15: MAR | E15: 1513 | F15: 247068 | G15: =F15/31*31 -> 247068 | H15: 1203 | I15: 256 | J15: =COUNTIFS('BASIC CAUSE INSIDEN'!$N$2:$N$1048576,DASHBOARD!$J$12,'BASIC CAUSE INSIDEN'!$F$2:$F$1048576,DASHBOARD!$D15) -> 2 | K15: =COUNTIFS('BASIC CAUSE INSIDEN'!$N$2:$N$1048576,DASHBOARD!$K$12,'BASIC CAUSE INSIDEN'!$F$2:$F$1048576,DASHBOARD!$D15) -> 5 | L15: =COUNTIFS('BASIC CAUSE INSIDEN'!$N$2:$N$1048576,DASHBOARD!$L$12,'BASIC CAUSE INSIDEN'!$F$2:$F$1048576,DASHBOARD!$D15) -> 0 | M15: =COUNTIFS('BASIC CAUSE INSIDEN'!$N$2:$N$1048576,DASHBOARD!$M$12,'BASIC CAUSE INSIDEN'!$F$2:$F$1048576,DASHBOARD!$D15) -> 0 | N15: =COUNTIFS('BASIC CAUSE INSIDEN'!$N$2:$N$1048576,DASHBOARD!$N$12,'BASIC CAUSE INSIDEN'!$F$2:$F$1048576,DASHBOARD!$D15) -> 0 | O15: =COUNTIFS('BASIC CAUSE INSIDEN'!$N$2:$N$1048576,DASHBOARD!$O$12,'BASIC CAUSE INSIDEN'!$F$2:$F$1048576,DASHBOARD!$D15) -> 0 | P15: =COUNTIFS('BASIC CAUSE INSIDEN'!$N$2:$N$1048576,DASHBOARD!$P$12,'BASIC CAUSE INSIDEN'!$F$2:$F$1048576,DASHBOARD!$D15) -> 0 | Q15: =COUNTIFS('BASIC CAUSE INSIDEN'!$N$2:$N$1048576,DASHBOARD!$Q$12,'BASIC CAUSE INSIDEN'!$F$2:$F$1048576,DASHBOARD!$D15) -> 0 | R15: =SUM(J15:Q15) -> 7 | S15: 31 | T15: 2.3536113e+09 | U15: =(O15*1000000)/F15 -> 0 | V15: {=SUM(K15:P15*1000000)/F15} -> 20.237344 | W15: =(K15*1000000)/F15 -> 20.237344 | X15: =(S15*1000000)/F15 -> 125.47153 | Y15: {=SUM(K15:P15*1000000)/F15} -> 20.237344 | Z15: =T15/F15 -> 9526.1681
C16: 4 | D16: APR | E16: 1270 | F16: 256839 | G16: =F16/30*30 -> 256839 | H16: 761 | I16: 130 | J16: =COUNTIFS('BASIC CAUSE INSIDEN'!$N$2:$N$1048576,DASHBOARD!$J$12,'BASIC CAUSE INSIDEN'!$F$2:$F$1048576,DASHBOARD!$D16) -> 2 | K16: =COUNTIFS('BASIC CAUSE INSIDEN'!$N$2:$N$1048576,DASHBOARD!$K$12,'BASIC CAUSE INSIDEN'!$F$2:$F$1048576,DASHBOARD!$D16) -> 6 | L16: =COUNTIFS('BASIC CAUSE INSIDEN'!$N$2:$N$1048576,DASHBOARD!$L$12,'BASIC CAUSE INSIDEN'!$F$2:$F$1048576,DASHBOARD!$D16) -> 0 | M16: =COUNTIFS('BASIC CAUSE INSIDEN'!$N$2:$N$1048576,DASHBOARD!$M$12,'BASIC CAUSE INSIDEN'!$F$2:$F$1048576,DASHBOARD!$D16) -> 0 | N16: =COUNTIFS('BASIC CAUSE INSIDEN'!$N$2:$N$1048576,DASHBOARD!$N$12,'BASIC CAUSE INSIDEN'!$F$2:$F$1048576,DASHBOARD!$D16) -> 0 | O16: =COUNTIFS('BASIC CAUSE INSIDEN'!$N$2:$N$1048576,DASHBOARD!$O$12,'BASIC CAUSE INSIDEN'!$F$2:$F$1048576,DASHBOARD!$D16) -> 0 | P16: =COUNTIFS('BASIC CAUSE INSIDEN'!$N$2:$N$1048576,DASHBOARD!$P$12,'BASIC CAUSE INSIDEN'!$F$2:$F$1048576,DASHBOARD!$D16) -> 0 | Q16: =COUNTIFS('BASIC CAUSE INSIDEN'!$N$2:$N$1048576,DASHBOARD!$Q$12,'BASIC CAUSE INSIDEN'!$F$2:$F$1048576,DASHBOARD!$D16) -> 1 | R16: =SUM(J16:Q16) -> 9 | S16: 0 | T16: 2.4038619e+09 | U16: =(O16*1000000)/F16 -> 0 | V16: {=SUM(K16:P16*1000000)/F16} -> 23.360938 | W16: =(K16*1000000)/F16 -> 23.360938 | X16: =(S16*1000000)/F16 -> 0 | Y16: {=SUM(K16:P16*1000000)/F16} -> 23.360938 | Z16: =T16/F16 -> 9359.4114
C17: 5 | D17: MEI | E17: 1413 | F17: 327786 | G17: =F17/31*31 -> 327786 | H17: 569 | I17: 37 | J17: =COUNTIFS('BASIC CAUSE INSIDEN'!$N$2:$N$1048576,DASHBOARD!$J$12,'BASIC CAUSE INSIDEN'!$F$2:$F$1048576,DASHBOARD!$D17) -> 5 | K17: =COUNTIFS('BASIC CAUSE INSIDEN'!$N$2:$N$1048576,DASHBOARD!$K$12,'BASIC CAUSE INSIDEN'!$F$2:$F$1048576,DASHBOARD!$D17) -> 4 | L17: =COUNTIFS('BASIC CAUSE INSIDEN'!$N$2:$N$1048576,DASHBOARD!$L$12,'BASIC CAUSE INSIDEN'!$F$2:$F$1048576,DASHBOARD!$D17) -> 0 | M17: =COUNTIFS('BASIC CAUSE INSIDEN'!$N$2:$N$1048576,DASHBOARD!$M$12,'BASIC CAUSE INSIDEN'!$F$2:$F$1048576,DASHBOARD!$D17) -> 0 | N17: =COUNTIFS('BASIC CAUSE INSIDEN'!$N$2:$N$1048576,DASHBOARD!$N$12,'BASIC CAUSE INSIDEN'!$F$2:$F$1048576,DASHBOARD!$D17) -> 0 | O17: =COUNTIFS('BASIC CAUSE INSIDEN'!$N$2:$N$1048576,DASHBOARD!$O$12,'BASIC CAUSE INSIDEN'!$F$2:$F$1048576,DASHBOARD!$D17) -> 0 | P17: =COUNTIFS('BASIC CAUSE INSIDEN'!$N$2:$N$1048576,DASHBOARD!$P$12,'BASIC CAUSE INSIDEN'!$F$2:$F$1048576,DASHBOARD!$D17) -> 0 | Q17: =COUNTIFS('BASIC CAUSE INSIDEN'!$N$2:$N$1048576,DASHBOARD!$Q$12,'BASIC CAUSE INSIDEN'!$F$2:$F$1048576,DASHBOARD!$D17) -> 1 | R17: =SUM(J17:Q17) -> 10 | S17: 0 | T17: 5.5619652e+08 | U17: =(O17*1000000)/F17 -> 0 | V17: {=SUM(K17:P17*1000000)/F17} -> 12.203084 | W17: =(K17*1000000)/F17 -> 12.203084 | X17: =(S17*1000000)/F17 -> 0 | Y17: {=SUM(K17:P17*1000000)/F17} -> 12.203084 | Z17: =T17/F17 -> 1696.8282
C18: 6 | D18: JUN | E18: 1513 | F18: 381712.5 | G18: =F18/30*30 -> 381712.5 | H18: 888 | I18: 158 | J18: =COUNTIFS('BASIC CAUSE INSIDEN'!$N$2:$N$1048576,DASHBOARD!$J$12,'BASIC CAUSE INSIDEN'!$F$2:$F$1048576,DASHBOARD!$D18) -> 2 | K18: =COUNTIFS('BASIC CAUSE INSIDEN'!$N$2:$N$1048576,DASHBOARD!$K$12,'BASIC CAUSE INSIDEN'!$F$2:$F$1048576,DASHBOARD!$D18) -> 5 | L18: =COUNTIFS('BASIC CAUSE INSIDEN'!$N$2:$N$1048576,DASHBOARD!$L$12,'BASIC CAUSE INSIDEN'!$F$2:$F$1048576,DASHBOARD!$D18) -> 0 | M18: =COUNTIFS('BASIC CAUSE INSIDEN'!$N$2:$N$1048576,DASHBOARD!$M$12,'BASIC CAUSE INSIDEN'!$F$2:$F$1048576,DASHBOARD!$D18) -> 0 | N18: =COUNTIFS('BASIC CAUSE INSIDEN'!$N$2:$N$1048576,DASHBOARD!$N$12,'BASIC CAUSE INSIDEN'!$F$2:$F$1048576,DASHBOARD!$D18) -> 0 | O18: =COUNTIFS('BASIC CAUSE INSIDEN'!$N$2:$N$1048576,DASHBOARD!$O$12,'BASIC CAUSE INSIDEN'!$F$2:$F$1048576,DASHBOARD!$D18) -> 0 | P18: =COUNTIFS('BASIC CAUSE INSIDEN'!$N$2:$N$1048576,DASHBOARD!$P$12,'BASIC CAUSE INSIDEN'!$F$2:$F$1048576,DASHBOARD!$D18) -> 0 | Q18: =COUNTIFS('BASIC CAUSE INSIDEN'!$N$2:$N$1048576,DASHBOARD!$Q$12,'BASIC CAUSE INSIDEN'!$F$2:$F$1048576,DASHBOARD!$D18) -> 1 | R18: =SUM(J18:Q18) -> 8 | S18: 0 | T18: 49019660 | U18: =(O18*1000000)/F18 -> 0 | V18: {=SUM(K18:P18*1000000)/F18} -> 13.098864 | W18: =(K18*1000000)/F18 -> 13.098864 | X18: =(S18*1000000)/F18 -> 0 | Y18: {=SUM(K18:P18*1000000)/F18} -> 13.098864 | Z18: =T18/F18 -> 128.42037
C19: 7 | D19: JULI | E19: 1721 | F19: 418169 | G19: =F19/31*31 -> 418169 | H19: 1143 | I19: 193 | J19: =COUNTIFS('BASIC CAUSE INSIDEN'!$N$2:$N$1048576,DASHBOARD!$J$12,'BASIC CAUSE INSIDEN'!$F$2:$F$1048576,DASHBOARD!$D19) -> 1 | K19: =COUNTIFS('BASIC CAUSE INSIDEN'!$N$2:$N$1048576,DASHBOARD!$K$12,'BASIC CAUSE INSIDEN'!$F$2:$F$1048576,DASHBOARD!$D19) -> 3 | L19: =COUNTIFS('BASIC CAUSE INSIDEN'!$N$2:$N$1048576,DASHBOARD!$L$12,'BASIC CAUSE INSIDEN'!$F$2:$F$1048576,DASHBOARD!$D19) -> 0 | M19: =COUNTIFS('BASIC CAUSE INSIDEN'!$N$2:$N$1048576,DASHBOARD!$M$12,'BASIC CAUSE INSIDEN'!$F$2:$F$1048576,DASHBOARD!$D19) -> 2 | N19: =COUNTIFS('BASIC CAUSE INSIDEN'!$N$2:$N$1048576,DASHBOARD!$N$12,'BASIC CAUSE INSIDEN'!$F$2:$F$1048576,DASHBOARD!$D19) -> 0 | O19: =COUNTIFS('BASIC CAUSE INSIDEN'!$N$2:$N$1048576,DASHBOARD!$O$12,'BASIC CAUSE INSIDEN'!$F$2:$F$1048576,DASHBOARD!$D19) -> 0 | P19: =COUNTIFS('BASIC CAUSE INSIDEN'!$N$2:$N$1048576,DASHBOARD!$P$12,'BASIC CAUSE INSIDEN'!$F$2:$F$1048576,DASHBOARD!$D19) -> 0 | Q19: =COUNTIFS('BASIC CAUSE INSIDEN'!$N$2:$N$1048576,DASHBOARD!$Q$12,'BASIC CAUSE INSIDEN'!$F$2:$F$1048576,DASHBOARD!$D19) -> 1 | R19: =SUM(J19:Q19) -> 7 | S19: 0 | T19: 1884392334 | U19: =(O19*1000000)/F19 -> 0 | V19: {=SUM(K19:P19*1000000)/F19} -> 11.956888 | W19: =(K19*1000000)/F19 -> 7.1741329 | X19: =(S19*1000000)/F19 -> 0 | Y19: {=SUM(K19:P19*1000000)/F19} -> 11.956888 | Z19: =T19/F19 -> 4506.2937
C20: 8 | D20: AGST | E20: 1809 | F20: 421621.5 | G20: =F20/31*31 -> 421621.5 | J20: =COUNTIFS('BASIC CAUSE INSIDEN'!$N$2:$N$1048576,DASHBOARD!$J$12,'BASIC CAUSE INSIDEN'!$F$2:$F$1048576,DASHBOARD!$D20) -> 5 | K20: =COUNTIFS('BASIC CAUSE INSIDEN'!$N$2:$N$1048576,DASHBOARD!$K$12,'BASIC CAUSE INSIDEN'!$F$2:$F$1048576,DASHBOARD!$D20) -> 3 | L20: =COUNTIFS('BASIC CAUSE INSIDEN'!$N$2:$N$1048576,DASHBOARD!$L$12,'BASIC CAUSE INSIDEN'!$F$2:$F$1048576,DASHBOARD!$D20) -> 0 | M20: =COUNTIFS('BASIC CAUSE INSIDEN'!$N$2:$N$1048576,DASHBOARD!$M$12,'BASIC CAUSE INSIDEN'!$F$2:$F$1048576,DASHBOARD!$D20) -> 0 | N20: =COUNTIFS('BASIC CAUSE INSIDEN'!$N$2:$N$1048576,DASHBOARD!$N$12,'BASIC CAUSE INSIDEN'!$F$2:$F$1048576,DASHBOARD!$D20) -> 0 | O20: =COUNTIFS('BASIC CAUSE INSIDEN'!$N$2:$N$1048576,DASHBOARD!$O$12,'BASIC CAUSE INSIDEN'!$F$2:$F$1048576,DASHBOARD!$D20) -> 0 | P20: =COUNTIFS('BASIC CAUSE INSIDEN'!$N$2:$N$1048576,DASHBOARD!$P$12,'BASIC CAUSE INSIDEN'!$F$2:$F$1048576,DASHBOARD!$D20) -> 0 | Q20: =COUNTIFS('BASIC CAUSE INSIDEN'!$N$2:$N$1048576,DASHBOARD!$Q$12,'BASIC CAUSE INSIDEN'!$F$2:$F$1048576,DASHBOARD!$D20) -> 1 | R20: =SUM(J20:Q20) -> 9 | S20: 0 | T20: 1193000000 | U20: =(O20*1000000)/F20 -> 0 | V20: {=SUM(K20:P20*1000000)/F20} -> 7.1153867 | W20: =(K20*1000000)/F20 -> 7.1153867 | X20: =(S20*1000000)/F20 -> 0 | Y20: {=SUM(K20:P20*1000000)/F20} -> 7.1153867 | Z20: =T20/F20 -> 2829.5521
C21: 9 | D21: SEPT | E21: 1810 | F21: 426966.5 | G21: =F21/30*30 -> 426966.5 | J21: =COUNTIFS('BASIC CAUSE INSIDEN'!$N$2:$N$1048576,DASHBOARD!$J$12,'BASIC CAUSE INSIDEN'!$F$2:$F$1048576,DASHBOARD!$D21) -> 1 | K21: =COUNTIFS('BASIC CAUSE INSIDEN'!$N$2:$N$1048576,DASHBOARD!$K$12,'BASIC CAUSE INSIDEN'!$F$2:$F$1048576,DASHBOARD!$D21) -> 2 | L21: =COUNTIFS('BASIC CAUSE INSIDEN'!$N$2:$N$1048576,DASHBOARD!$L$12,'BASIC CAUSE INSIDEN'!$F$2:$F$1048576,DASHBOARD!$D21) -> 0 | M21: =COUNTIFS('BASIC CAUSE INSIDEN'!$N$2:$N$1048576,DASHBOARD!$M$12,'BASIC CAUSE INSIDEN'!$F$2:$F$1048576,DASHBOARD!$D21) -> 0 | N21: =COUNTIFS('BASIC CAUSE INSIDEN'!$N$2:$N$1048576,DASHBOARD!$N$12,'BASIC CAUSE INSIDEN'!$F$2:$F$1048576,DASHBOARD!$D21) -> 0 | O21: =COUNTIFS('BASIC CAUSE INSIDEN'!$N$2:$N$1048576,DASHBOARD!$O$12,'BASIC CAUSE INSIDEN'!$F$2:$F$1048576,DASHBOARD!$D21) -> 0 | P21: =COUNTIFS('BASIC CAUSE INSIDEN'!$N$2:$N$1048576,DASHBOARD!$P$12,'BASIC CAUSE INSIDEN'!$F$2:$F$1048576,DASHBOARD!$D21) -> 0 | Q21: =COUNTIFS('BASIC CAUSE INSIDEN'!$N$2:$N$1048576,DASHBOARD!$Q$12,'BASIC CAUSE INSIDEN'!$F$2:$F$1048576,DASHBOARD!$D21) -> 0 | R21: =SUM(J21:Q21) -> 3 | S21: 0 | T21: 26250000 | U21: =(O21*1000000)/F21 -> 0 | V21: {=SUM(K21:P21*1000000)/F21} -> 4.6842082 | W21: =(K21*1000000)/F21 -> 4.6842082 | X21: =(S21*1000000)/F21 -> 0 | Y21: {=SUM(K21:P21*1000000)/F21} -> 4.6842082 | Z21: =T21/F21 -> 61.480233
C22: 10 | D22: OKT | E22: 1810 | F22: 426966.5 | G22: =F22/31*31 -> 426966.5 | J22: =COUNTIFS('BASIC CAUSE INSIDEN'!$N$2:$N$1048576,DASHBOARD!$J$12,'BASIC CAUSE INSIDEN'!$F$2:$F$1048576,DASHBOARD!$D22) -> 1 | K22: =COUNTIFS('BASIC CAUSE INSIDEN'!$N$2:$N$1048576,DASHBOARD!$K$12,'BASIC CAUSE INSIDEN'!$F$2:$F$1048576,DASHBOARD!$D22) -> 2 | L22: =COUNTIFS('BASIC CAUSE INSIDEN'!$N$2:$N$1048576,DASHBOARD!$L$12,'BASIC CAUSE INSIDEN'!$F$2:$F$1048576,DASHBOARD!$D22) -> 0 | M22: =COUNTIFS('BASIC CAUSE INSIDEN'!$N$2:$N$1048576,DASHBOARD!$M$12,'BASIC CAUSE INSIDEN'!$F$2:$F$1048576,DASHBOARD!$D22) -> 0 | N22: =COUNTIFS('BASIC CAUSE INSIDEN'!$N$2:$N$1048576,DASHBOARD!$N$12,'BASIC CAUSE INSIDEN'!$F$2:$F$1048576,DASHBOARD!$D22) -> 0 | O22: =COUNTIFS('BASIC CAUSE INSIDEN'!$N$2:$N$1048576,DASHBOARD!$O$12,'BASIC CAUSE INSIDEN'!$F$2:$F$1048576,DASHBOARD!$D22) -> 0 | P22: =COUNTIFS('BASIC CAUSE INSIDEN'!$N$2:$N$1048576,DASHBOARD!$P$12,'BASIC CAUSE INSIDEN'!$F$2:$F$1048576,DASHBOARD!$D22) -> 0 | Q22: =COUNTIFS('BASIC CAUSE INSIDEN'!$N$2:$N$1048576,DASHBOARD!$Q$12,'BASIC CAUSE INSIDEN'!$F$2:$F$1048576,DASHBOARD!$D22) -> 1 | R22: =SUM(J22:Q22) -> 4 | U22: =(O22*1000000)/F22 -> 0 | V22: {=SUM(K22:P22*1000000)/F22} -> 4.6842082 | W22: =(K22*1000000)/F22 -> 4.6842082 | X22: =(S22*1000000)/F22 -> 0 | Y22: {=SUM(K22:P22*1000000)/F22} -> 4.6842082 | Z22: =T22/F22 -> 0
C23: 11 | D23: NOV | J23: =COUNTIFS('BASIC CAUSE INSIDEN'!$N$2:$N$1048576,DASHBOARD!$J$12,'BASIC CAUSE INSIDEN'!$F$2:$F$1048576,DASHBOARD!$D23) -> 0 | K23: =COUNTIFS('BASIC CAUSE INSIDEN'!$N$2:$N$1048576,DASHBOARD!$K$12,'BASIC CAUSE INSIDEN'!$F$2:$F$1048576,DASHBOARD!$D23) -> 0 | L23: =COUNTIFS('BASIC CAUSE INSIDEN'!$N$2:$N$1048576,DASHBOARD!$L$12,'BASIC CAUSE INSIDEN'!$F$2:$F$1048576,DASHBOARD!$D23) -> 0 | M23: =COUNTIFS('BASIC CAUSE INSIDEN'!$N$2:$N$1048576,DASHBOARD!$M$12,'BASIC CAUSE INSIDEN'!$F$2:$F$1048576,DASHBOARD!$D23) -> 0 | N23: =COUNTIFS('BASIC CAUSE INSIDEN'!$N$2:$N$1048576,DASHBOARD!$N$12,'BASIC CAUSE INSIDEN'!$F$2:$F$1048576,DASHBOARD!$D23) -> 0 | O23: =COUNTIFS('BASIC CAUSE INSIDEN'!$N$2:$N$1048576,DASHBOARD!$O$12,'BASIC CAUSE INSIDEN'!$F$2:$F$1048576,DASHBOARD!$D23) -> 0 | P23: =COUNTIFS('BASIC CAUSE INSIDEN'!$N$2:$N$1048576,DASHBOARD!$P$12,'BASIC CAUSE INSIDEN'!$F$2:$F$1048576,DASHBOARD!$D23) -> 0 | Q23: =COUNTIFS('BASIC CAUSE INSIDEN'!$N$2:$N$1048576,DASHBOARD!$Q$12,'BASIC CAUSE INSIDEN'!$F$2:$F$1048576,DASHBOARD!$D23) -> 0 | R23: =SUM(J23:Q23) -> 0 | U23: =(O23*1000000)/F23 -> #DIV/0! | V23: {=SUM(K23:P23*1000000)/F23} -> #DIV/0! | W23: =(K23*1000000)/F23 -> #DIV/0! | X23: =(S23*1000000)/F23 -> #DIV/0! | Y23: {=SUM(K23:P23*1000000)/F23} -> #DIV/0! | Z23: =T23/F23 -> #DIV/0!
C24: 12 | D24: DES | J24: =COUNTIFS('BASIC CAUSE INSIDEN'!$N$2:$N$1048576,DASHBOARD!$J$12,'BASIC CAUSE INSIDEN'!$F$2:$F$1048576,DASHBOARD!$D24) -> 0 | K24: =COUNTIFS('BASIC CAUSE INSIDEN'!$N$2:$N$1048576,DASHBOARD!$K$12,'BASIC CAUSE INSIDEN'!$F$2:$F$1048576,DASHBOARD!$D24) -> 0 | L24: =COUNTIFS('BASIC CAUSE INSIDEN'!$N$2:$N$1048576,DASHBOARD!$L$12,'BASIC CAUSE INSIDEN'!$F$2:$F$1048576,DASHBOARD!$D24) -> 0 | M24: =COUNTIFS('BASIC CAUSE INSIDEN'!$N$2:$N$1048576,DASHBOARD!$M$12,'BASIC CAUSE INSIDEN'!$F$2:$F$1048576,DASHBOARD!$D24) -> 0 | N24: =COUNTIFS('BASIC CAUSE INSIDEN'!$N$2:$N$1048576,DASHBOARD!$N$12,'BASIC CAUSE INSIDEN'!$F$2:$F$1048576,DASHBOARD!$D24) -> 0 | O24: =COUNTIFS('BASIC CAUSE INSIDEN'!$N$2:$N$1048576,DASHBOARD!$O$12,'BASIC CAUSE INSIDEN'!$F$2:$F$1048576,DASHBOARD!$D24) -> 0 | P24: =COUNTIFS('BASIC CAUSE INSIDEN'!$N$2:$N$1048576,DASHBOARD!$P$12,'BASIC CAUSE INSIDEN'!$F$2:$F$1048576,DASHBOARD!$D24) -> 0 | Q24: =COUNTIFS('BASIC CAUSE INSIDEN'!$N$2:$N$1048576,DASHBOARD!$Q$12,'BASIC CAUSE INSIDEN'!$F$2:$F$1048576,DASHBOARD!$D24) -> 0 | R24: =SUM(J24:Q24) -> 0 | U24: =(O24*1000000)/F24 -> #DIV/0! | V24: {=SUM(K24:P24*1000000)/F24} -> #DIV/0! | W24: =(K24*1000000)/F24 -> #DIV/0! | X24: =(S24*1000000)/F24 -> #DIV/0! | Y24: {=SUM(K24:P24*1000000)/F24} -> #DIV/0! | Z24: =T24/F24 -> #DIV/0!
C25: TOTAL | E25: =SUM(E13:E24) -> 15076 | F25: =SUM(F13:F24) -> 3474949 | G25: =SUM(G13:G24) -> 3474949 | H25: =SUM(H13:H24) -> 4317 | I25: =SUM(I13:I24) -> 955 | J25: =SUM(J13:J24) -> 26 | K25: =SUM(K13:K24) -> 38 | L25: =SUM(L13:L24) -> 0 | ... T25: =SUM(T13:T24) -> 1.0017108e+10 | U25: =(O25*1000000)/F25 -> 0 | V25: {=SUM(K25:P25*1000000)/F25} -> 11.798734 | W25: =(K25*1000000)/F25 -> 10.935412 | X25: =(S25*1000000)/F25 -> 25.899661 | Y25: {=SUM(K25:P25*1000000)/F25} -> 11.798734 | Z25: =T25/F25 -> 2882.6634
C28: REKOMENDASI & LAYERING PENANGGUNG JAWAB AREA (PJA)
C31: NO | E31: Rekomendasi Insiden | H31: Layering Penanggung Jawab Area (PJA) | V31: Klasifikasi
D32: BULAN | E32: REKOMENDASI | F32: ACTUAL | G32: PERSEN % | H32: PRODUKSI HAULING | I32: PRODUKSI MINING | J32: PROCON | K32: MINE PLAN | L32: PITCON & SURVEY | M32: TRAINING | N32: PLANT TUHUP | O32: PLANT HAJU | P32: PLANT CHPP | Q32: HRGA | R32: LOGISTIK | S32: SHE | T32: AMC | U32: HPRI | V32: NON HPRI | W32: TOTAL
C33: 1 | D33: JAN | E33: =COUNTA('RINCIAN KECELAKAAN'!N8:N64) -> 57 | F33: =COUNTIFS('RINCIAN KECELAKAAN'!$S8:$S64,'RINCIAN KECELAKAAN'!$AB$8) -> 57 | G33: =F33/E33 -> 1 | H33: =COUNTIF('RINCIAN KECELAKAAN'!$R8:$R64,DASHBOARD!H32) -> 28 | I33: =COUNTIF('RINCIAN KECELAKAAN'!$R8:$R64,DASHBOARD!I32) -> 2 | J33: =COUNTIF('RINCIAN KECELAKAAN'!$R8:$R64,DASHBOARD!J32) -> 0 | K33: =COUNTIF('RINCIAN KECELAKAAN'!$R8:$R64,DASHBOARD!K32) -> 0 | L33: =COUNTIF('RINCIAN KECELAKAAN'!$R8:$R64,DASHBOARD!L32) -> 0 | M33: =COUNTIF('RINCIAN KECELAKAAN'!$R8:$R64,DASHBOARD!M32) -> 8 | N33: =COUNTIF('RINCIAN KECELAKAAN'!$R8:$R64,DASHBOARD!N32) -> 0 | O33: =COUNTIF('RINCIAN KECELAKAAN'!$R8:$R64,DASHBOARD!O32) -> 9 | ... T33: =COUNTIF('RINCIAN KECELAKAAN'!$R8:$R64,DASHBOARD!T32) -> 2 | U33: =COUNTIF('RINCIAN KECELAKAAN'!$T8:$T64,DASHBOARD!U32) -> 5 | V33: =COUNTIF('RINCIAN KECELAKAAN'!$T8:$T64,DASHBOARD!V32) -> 7 | W33: =SUM(U33:V33) -> 12
C34: 2 | D34: FEB | E34: =COUNTA('RINCIAN KECELAKAAN'!S65:S93) -> 29 | F34: =COUNTIF('RINCIAN KECELAKAAN'!$S$65:$S$93,'RINCIAN KECELAKAAN'!$AB$8) -> 29 | G34: =F34/E34 -> 1 | H34: =COUNTIF('RINCIAN KECELAKAAN'!$R65:$R93,DASHBOARD!H32) -> 15 | I34: =COUNTIF('RINCIAN KECELAKAAN'!$R65:$R93,DASHBOARD!I32) -> 4 | J34: =COUNTIF('RINCIAN KECELAKAAN'!$R65:$R93,DASHBOARD!J32) -> 0 | K34: =COUNTIF('RINCIAN KECELAKAAN'!$R65:$R93,DASHBOARD!K32) -> 0 | L34: =COUNTIF('RINCIAN KECELAKAAN'!$R65:$R93,DASHBOARD!L32) -> 1 | M34: =COUNTIF('RINCIAN KECELAKAAN'!$R65:$R93,DASHBOARD!M32) -> 1 | N34: =COUNTIF('RINCIAN KECELAKAAN'!$R65:$R93,DASHBOARD!N32) -> 0 | O34: =COUNTIF('RINCIAN KECELAKAAN'!$R65:$R93,DASHBOARD!O32) -> 3 | ... T34: =COUNTIF('RINCIAN KECELAKAAN'!$R65:$R93,DASHBOARD!T32) -> 0 | U34: =COUNTIF('RINCIAN KECELAKAAN'!$T65:$T93,DASHBOARD!U32) -> 4 | V34: =COUNTIF('RINCIAN KECELAKAAN'!$T65:$T93,DASHBOARD!V32) -> 1 | W34: =SUM(U34:V34) -> 5
C35: 3 | D35: MAR | E35: =COUNTA('RINCIAN KECELAKAAN'!S94:S133) -> 40 | F35: =COUNTIF('RINCIAN KECELAKAAN'!$S$94:$S$133,'RINCIAN KECELAKAAN'!$AB$8) -> 40 | G35: =F35/E35 -> 1 | H35: =COUNTIF('RINCIAN KECELAKAAN'!$R94:$R133,DASHBOARD!H32) -> 25 | I35: =COUNTIF('RINCIAN KECELAKAAN'!$R94:$R133,DASHBOARD!I32) -> 0 | J35: =COUNTIF('RINCIAN KECELAKAAN'!$R94:$R133,DASHBOARD!J32) -> 0 | K35: =COUNTIF('RINCIAN KECELAKAAN'!$R94:$R133,DASHBOARD!K32) -> 0 | L35: =COUNTIF('RINCIAN KECELAKAAN'!$R94:$R133,DASHBOARD!L32) -> 0 | M35: =COUNTIF('RINCIAN KECELAKAAN'!$R94:$R133,DASHBOARD!M32) -> 2 | N35: =COUNTIF('RINCIAN KECELAKAAN'!$R94:$R133,DASHBOARD!N32) -> 0 | O35: =COUNTIF('RINCIAN KECELAKAAN'!$R94:$R133,DASHBOARD!O32) -> 0 | ... T35: =COUNTIF('RINCIAN KECELAKAAN'!$R94:$R133,DASHBOARD!T32) -> 1 | U35: =COUNTIF('RINCIAN KECELAKAAN'!$T94:$T133,DASHBOARD!U32) -> 3 | V35: =COUNTIF('RINCIAN KECELAKAAN'!$T94:$T133,DASHBOARD!V32) -> 4 | W35: =SUM(U35:V35) -> 7
C36: 4 | D36: APR | E36: =COUNTA('RINCIAN KECELAKAAN'!S134:S192) -> 59 | F36: =COUNTIF('RINCIAN KECELAKAAN'!$S$134:$S$192,'RINCIAN KECELAKAAN'!$AB$8) -> 59 | G36: =F36/E36 -> 1 | H36: =COUNTIF('RINCIAN KECELAKAAN'!$R134:$R192,DASHBOARD!H32) -> 28 | I36: =COUNTIF('RINCIAN KECELAKAAN'!$R134:$R192,DASHBOARD!I32) -> 0 | J36: =COUNTIF('RINCIAN KECELAKAAN'!$R134:$R192,DASHBOARD!J32) -> 0 | K36: =COUNTIF('RINCIAN KECELAKAAN'!$R134:$R192,DASHBOARD!K32) -> 0 | L36: =COUNTIF('RINCIAN KECELAKAAN'!$R134:$R192,DASHBOARD!L32) -> 1 | M36: =COUNTIF('RINCIAN KECELAKAAN'!$R134:$R192,DASHBOARD!M32) -> 7 | N36: =COUNTIF('RINCIAN KECELAKAAN'!$R134:$R192,DASHBOARD!N32) -> 0 | O36: =COUNTIF('RINCIAN KECELAKAAN'!$R134:$R192,DASHBOARD!O32) -> 6 | ... T36: =COUNTIF('RINCIAN KECELAKAAN'!$R134:$R192,DASHBOARD!T32) -> 2 | U36: =COUNTIF('RINCIAN KECELAKAAN'!$T134:$T192,DASHBOARD!U32) -> 4 | V36: =COUNTIF('RINCIAN KECELAKAAN'!$T134:$T192,DASHBOARD!V32) -> 5 | W36: =SUM(U36:V36) -> 9
C37: 5 | D37: MEI | E37: =COUNTA('RINCIAN KECELAKAAN'!S193:S270) -> 78 | F37: =COUNTIF('RINCIAN KECELAKAAN'!$S$193:$S$270,'RINCIAN KECELAKAAN'!$AB$8) -> 78 | G37: =F37/E37 -> 1 | H37: =COUNTIF('RINCIAN KECELAKAAN'!$R193:$R270,DASHBOARD!H32) -> 17 | I37: =COUNTIF('RINCIAN KECELAKAAN'!$R193:$R270,DASHBOARD!I32) -> 22 | J37: =COUNTIF('RINCIAN KECELAKAAN'!$R193:$R270,DASHBOARD!J32) -> 0 | K37: =COUNTIF('RINCIAN KECELAKAAN'!$R193:$R270,DASHBOARD!K32) -> 1 | L37: =COUNTIF('RINCIAN KECELAKAAN'!$R193:$R270,DASHBOARD!L32) -> 0 | M37: =COUNTIF('RINCIAN KECELAKAAN'!$R193:$R270,DASHBOARD!M32) -> 7 | N37: =COUNTIF('RINCIAN KECELAKAAN'!$R193:$R270,DASHBOARD!N32) -> 0 | O37: =COUNTIF('RINCIAN KECELAKAAN'!$R193:$R270,DASHBOARD!O32) -> 23 | ... T37: =COUNTIF('RINCIAN KECELAKAAN'!$R193:$R270,DASHBOARD!T32) -> 0 | U37: =COUNTIF('RINCIAN KECELAKAAN'!$T193:$T270,DASHBOARD!U32) -> 7 | V37: =COUNTIF('RINCIAN KECELAKAAN'!$T193:$T270,DASHBOARD!V32) -> 3 | W37: =SUM(U37:V37) -> 10
C38: 6 | D38: JUN | E38: =COUNTA('RINCIAN KECELAKAAN'!S271:S331) -> 61 | F38: =COUNTIF('RINCIAN KECELAKAAN'!$S$271:$S$331,'RINCIAN KECELAKAAN'!$AB$8) -> 61 | G38: =F38/E38 -> 1 | H38: =COUNTIF('RINCIAN KECELAKAAN'!$R271:$R331,DASHBOARD!H32) -> 23 | I38: =COUNTIF('RINCIAN KECELAKAAN'!$R271:$R331,DASHBOARD!I32) -> 9 | J38: =COUNTIF('RINCIAN KECELAKAAN'!$R271:$R331,DASHBOARD!J32) -> 0 | K38: =COUNTIF('RINCIAN KECELAKAAN'!$R271:$R331,DASHBOARD!K32) -> 0 | L38: =COUNTIF('RINCIAN KECELAKAAN'!$R271:$R331,DASHBOARD!L32) -> 0 | M38: =COUNTIF('RINCIAN KECELAKAAN'!$R271:$R331,DASHBOARD!M32) -> 1 | N38: =COUNTIF('RINCIAN KECELAKAAN'!$R271:$R331,DASHBOARD!N32) -> 0 | O38: =COUNTIF('RINCIAN KECELAKAAN'!$R271:$R331,DASHBOARD!O32) -> 18 | ... T38: =COUNTIF('RINCIAN KECELAKAAN'!$R271:$R331,DASHBOARD!T32) -> 2 | U38: =COUNTIF('RINCIAN KECELAKAAN'!$T271:$T331,DASHBOARD!U32) -> 3 | V38: =COUNTIF('RINCIAN KECELAKAAN'!$T271:$T331,DASHBOARD!V32) -> 5 | W38: =SUM(U38:V38) -> 8
C39: 7 | D39: JULI | E39: =COUNTA('RINCIAN KECELAKAAN'!S332:S394) -> 63 | F39: =COUNTIF('RINCIAN KECELAKAAN'!$S$332:$S$394,'RINCIAN KECELAKAAN'!$AB$8) -> 63 | G39: =F39/E39 -> 1 | H39: =COUNTIF('RINCIAN KECELAKAAN'!$R332:$R394,DASHBOARD!H32) -> 25 | I39: =COUNTIF('RINCIAN KECELAKAAN'!$R332:$R394,DASHBOARD!I32) -> 0 | J39: =COUNTIF('RINCIAN KECELAKAAN'!$R332:$R394,DASHBOARD!J32) -> 0 | K39: =COUNTIF('RINCIAN KECELAKAAN'!$R332:$R394,DASHBOARD!K32) -> 0 | L39: =COUNTIF('RINCIAN KECELAKAAN'!$R332:$R394,DASHBOARD!L32) -> 0 | M39: =COUNTIF('RINCIAN KECELAKAAN'!$R332:$R394,DASHBOARD!M32) -> 0 | N39: =COUNTIF('RINCIAN KECELAKAAN'!$R332:$R394,DASHBOARD!N32) -> 0 | O39: =COUNTIF('RINCIAN KECELAKAAN'!$R332:$R394,DASHBOARD!O32) -> 8 | ... T39: =COUNTIF('RINCIAN KECELAKAAN'!$R332:$R394,DASHBOARD!T32) -> 1 | U39: =COUNTIF('RINCIAN KECELAKAAN'!$T332:$T394,DASHBOARD!U32) -> 4 | V39: =COUNTIF('RINCIAN KECELAKAAN'!$T332:$T394,DASHBOARD!V32) -> 3 | W39: =SUM(U39:V39) -> 7
C40: 8 | D40: AGST | E40: =COUNTA('RINCIAN KECELAKAAN'!S395:S427) -> 31 | F40: =COUNTIF('RINCIAN KECELAKAAN'!$S$395:$S$427,'RINCIAN KECELAKAAN'!$AB$8) -> 30 | G40: =F40/E40 -> 0.96774194 | H40: =COUNTIF('RINCIAN KECELAKAAN'!$R395:$R427,DASHBOARD!H32) -> 15 | I40: =COUNTIF('RINCIAN KECELAKAAN'!$R395:$R427,DASHBOARD!I32) -> 6 | J40: =COUNTIF('RINCIAN KECELAKAAN'!$R395:$R427,DASHBOARD!J32) -> 0 | K40: =COUNTIF('RINCIAN KECELAKAAN'!$R395:$R427,DASHBOARD!K32) -> 0 | L40: =COUNTIF('RINCIAN KECELAKAAN'!$R395:$R427,DASHBOARD!L32) -> 1 | M40: =COUNTIF('RINCIAN KECELAKAAN'!$R395:$R427,DASHBOARD!M32) -> 1 | N40: =COUNTIF('RINCIAN KECELAKAAN'!$R395:$R427,DASHBOARD!N32) -> 0 | O40: =COUNTIF('RINCIAN KECELAKAAN'!$R395:$R427,DASHBOARD!O32) -> 2 | ... T40: =COUNTIF('RINCIAN KECELAKAAN'!$R395:$R427,DASHBOARD!T32) -> 0 | U40: =COUNTIF('RINCIAN KECELAKAAN'!$T395:$T427,DASHBOARD!U32) -> 2 | V40: =COUNTIF('RINCIAN KECELAKAAN'!$T395:$T427,DASHBOARD!V32) -> 7 | W40: =SUM(U40:V40) -> 9
C41: 9 | D41: SEPT | E41: =COUNTA('RINCIAN KECELAKAAN'!S428:S447) -> 19 | F41: =COUNTIF('RINCIAN KECELAKAAN'!$S$428:$S$447,'RINCIAN KECELAKAAN'!$AB$8) -> 11 | G41: =F41/E41 -> 0.57894737 | H41: =COUNTIF('RINCIAN KECELAKAAN'!$R428:$R447,DASHBOARD!H32) -> 7 | I41: =COUNTIF('RINCIAN KECELAKAAN'!$R428:$R447,DASHBOARD!I32) -> 7 | J41: =COUNTIF('RINCIAN KECELAKAAN'!$R428:$R447,DASHBOARD!J32) -> 0 | K41: =COUNTIF('RINCIAN KECELAKAAN'!$R428:$R447,DASHBOARD!K32) -> 0 | L41: =COUNTIF('RINCIAN KECELAKAAN'!$R428:$R447,DASHBOARD!L32) -> 0 | M41: =COUNTIF('RINCIAN KECELAKAAN'!$R428:$R447,DASHBOARD!M32) -> 2 | N41: =COUNTIF('RINCIAN KECELAKAAN'!$R428:$R447,DASHBOARD!N32) -> 0 | O41: =COUNTIF('RINCIAN KECELAKAAN'!$R428:$R447,DASHBOARD!O32) -> 3 | ... T41: =COUNTIF('RINCIAN KECELAKAAN'!$R428:$R447,DASHBOARD!T32) -> 0 | U41: =COUNTIF('RINCIAN KECELAKAAN'!$T428:$T447,DASHBOARD!U32) -> 2 | V41: =COUNTIF('RINCIAN KECELAKAAN'!$T428:$T447,DASHBOARD!V32) -> 1 | W41: =SUM(U41:V41) -> 3
C42: 10 | D42: OKT | E42: =COUNTA('RINCIAN KECELAKAAN'!S448:S456) -> 6 | F42: =COUNTIF('RINCIAN KECELAKAAN'!$S$448:$S$456,'RINCIAN KECELAKAAN'!$AB$8) -> 6 | G42: =F42/E42 -> 1 | H42: =COUNTIF('RINCIAN KECELAKAAN'!$R448:$R456,DASHBOARD!H32) -> 0 | I42: =COUNTIF('RINCIAN KECELAKAAN'!$R448:$R456,DASHBOARD!I32) -> 0 | J42: =COUNTIF('RINCIAN KECELAKAAN'!$R448:$R456,DASHBOARD!J32) -> 0 | K42: =COUNTIF('RINCIAN KECELAKAAN'!$R448:$R456,DASHBOARD!K32) -> 0 | L42: =COUNTIF('RINCIAN KECELAKAAN'!$R448:$R456,DASHBOARD!L32) -> 0 | M42: =COUNTIF('RINCIAN KECELAKAAN'!$R448:$R456,DASHBOARD!M32) -> 0 | N42: =COUNTIF('RINCIAN KECELAKAAN'!$R448:$R456,DASHBOARD!N32) -> 0 | O42: =COUNTIF('RINCIAN KECELAKAAN'!$R448:$R456,DASHBOARD!O32) -> 0 | ... T42: =COUNTIF('RINCIAN KECELAKAAN'!$R448:$R456,DASHBOARD!T32) -> 0 | U42: =COUNTIF('RINCIAN KECELAKAAN'!$T448:$T456,DASHBOARD!U32) -> 0 | V42: =COUNTIF('RINCIAN KECELAKAAN'!$T448:$T456,DASHBOARD!V32) -> 1 | W42: =SUM(U42:V42) -> 1
C43: 11 | D43: NOV
C44: 12 | D44: DES
C45: TOTAL | E45: =SUM(E33:E44) -> 443 | F45: =SUM(F33:F44) -> 434 | G45: =F45/E45 -> 0.97968397 | H45: =SUM(H33:H44) -> 183 | I45: =SUM(I33:I44) -> 50 | J45: =SUM(J33:J44) -> 0 | K45: =SUM(K33:K44) -> 1 | L45: =SUM(L33:L44) -> 3 | M45: =SUM(M33:M44) -> 29 | N45: =SUM(N33:N44) -> 0 | O45: =SUM(O33:O44) -> 72 | ... W45: =SUM(W33:W44) -> 71
E46: =E45-F45 -> 9
C48: LOKASI INSIDEN
C52: NO | E52: LOKASI INSIDEN
D53: BULAN | E53: MINING | F53: LNR | G53: CHR | H53: SHR | I53: ROM CHPP | J53: PORT TUHUP | K53: CSA | L53: PIT STOP | M53: TPS | N53: WORKSHOP | O53: WAREHOUSE | P53: MESS | Q53: KLINIK | R53: MINE ROAD AKSES | S53: TOTAL
C54: 1 | D54: JAN | E54: =COUNTIF('RINCIAN KECELAKAAN'!$H8:$H64,DASHBOARD!E53) -> 0 | F54: =COUNTIF('RINCIAN KECELAKAAN'!$H8:$H64,DASHBOARD!F53) -> 5 | G54: =COUNTIF('RINCIAN KECELAKAAN'!$H8:$H64,DASHBOARD!G53) -> 0 | H54: =COUNTIF('RINCIAN KECELAKAAN'!$H8:$H64,DASHBOARD!H53) -> 4 | I54: =COUNTIF('RINCIAN KECELAKAAN'!$H8:$H64,DASHBOARD!I53) -> 0 | J54: =COUNTIF('RINCIAN KECELAKAAN'!$H8:$H64,DASHBOARD!J53) -> 3 | K54: =COUNTIF('RINCIAN KECELAKAAN'!$H8:$H64,DASHBOARD!K53) -> 0 | L54: =COUNTIF('RINCIAN KECELAKAAN'!$H8:$H64,DASHBOARD!L53) -> 0 | ... R54: =COUNTIF('RINCIAN KECELAKAAN'!$H8:$H64,DASHBOARD!R53) -> 0 | S54: =SUM(E54:R54) -> 12
C55: 2 | D55: FEB | E55: =COUNTIF('RINCIAN KECELAKAAN'!$H65:$H93,DASHBOARD!E53) -> 1 | F55: =COUNTIF('RINCIAN KECELAKAAN'!$H65:$H93,DASHBOARD!F53) -> 0 | G55: =COUNTIF('RINCIAN KECELAKAAN'!$H65:$H93,DASHBOARD!G53) -> 0 | H55: =COUNTIF('RINCIAN KECELAKAAN'!$H65:$H93,DASHBOARD!H53) -> 4 | I55: =COUNTIF('RINCIAN KECELAKAAN'!$H65:$H93,DASHBOARD!I53) -> 0 | J55: =COUNTIF('RINCIAN KECELAKAAN'!$H65:$H93,DASHBOARD!J53) -> 0 | K55: =COUNTIF('RINCIAN KECELAKAAN'!$H65:$H93,DASHBOARD!K53) -> 0 | L55: =COUNTIF('RINCIAN KECELAKAAN'!$H65:$H93,DASHBOARD!L53) -> 0 | ... R55: =COUNTIF('RINCIAN KECELAKAAN'!$H65:$H93,DASHBOARD!R53) -> 0 | S55: =SUM(E55:R55) -> 5
C56: 3 | D56: MAR | E56: =COUNTIF('RINCIAN KECELAKAAN'!$H94:$H133,DASHBOARD!E53) -> 0 | F56: =COUNTIF('RINCIAN KECELAKAAN'!$H94:$H133,DASHBOARD!F53) -> 1 | G56: =COUNTIF('RINCIAN KECELAKAAN'!$H94:$H133,DASHBOARD!G53) -> 1 | H56: =COUNTIF('RINCIAN KECELAKAAN'!$H94:$H133,DASHBOARD!H53) -> 3 | I56: =COUNTIF('RINCIAN KECELAKAAN'!$H94:$H133,DASHBOARD!I53) -> 1 | J56: =COUNTIF('RINCIAN KECELAKAAN'!$H94:$H133,DASHBOARD!J53) -> 1 | K56: =COUNTIF('RINCIAN KECELAKAAN'!$H94:$H133,DASHBOARD!K53) -> 0 | L56: =COUNTIF('RINCIAN KECELAKAAN'!$H94:$H133,DASHBOARD!L53) -> 0 | ... R56: =COUNTIF('RINCIAN KECELAKAAN'!$H94:$H133,DASHBOARD!R53) -> 0 | S56: =SUM(E56:R56) -> 7
C57: 4 | D57: APR | E57: =COUNTIF('RINCIAN KECELAKAAN'!$H134:$H192,DASHBOARD!E53) -> 1 | F57: =COUNTIF('RINCIAN KECELAKAAN'!$H134:$H192,DASHBOARD!F53) -> 3 | G57: =COUNTIF('RINCIAN KECELAKAAN'!$H134:$H192,DASHBOARD!G53) -> 0 | H57: =COUNTIF('RINCIAN KECELAKAAN'!$H134:$H192,DASHBOARD!H53) -> 4 | I57: =COUNTIF('RINCIAN KECELAKAAN'!$H134:$H192,DASHBOARD!I53) -> 0 | J57: =COUNTIF('RINCIAN KECELAKAAN'!$H134:$H192,DASHBOARD!J53) -> 0 | K57: =COUNTIF('RINCIAN KECELAKAAN'!$H134:$H192,DASHBOARD!K53) -> 0 | L57: =COUNTIF('RINCIAN KECELAKAAN'!$H134:$H192,DASHBOARD!L53) -> 0 | ... R57: =COUNTIF('RINCIAN KECELAKAAN'!$H134:$H192,DASHBOARD!R53) -> 0 | S57: =SUM(E57:R57) -> 9
...

Sheet LONG TERM
B1: 2020
B2: MONTH | C2: MAN POWER | D2: MAN HOURS | E2: MAN HOURS NLTI | F2: KTA | G2: TTA | H2: NM | I2: EI | J2: PD | K2: FC | L2: FA | M2: MI | N2: MTI | O2: RWI | P2: LTI | Q2: FATAL | R2: TOTAL | S2: LOST DAY | T2: LOST COST | U2: LTIFR / FR | V2: AIFR | W2: PDFR | X2: LTI SR | Y2: IR | Z2: LR
B4: JANUARI | C4: 355 | D4: 75944.5 | E4: =D4/31*24 -> 58795.742 | F4: 0 | G4: 0 | H4: 0 | J4: 0 | K4: 0 | L4: 0 | M4: 0 | N4: 0 | O4: 0 | P4: 0 | Q4: 0 | R4: =SUM(H4:Q4) -> 0 | T4: 0 | U4: =((P4)*1000000)/D4 -> 0 | V4: =((J4+K4+L4+N4+M4+O4+P4+Q4)*1000000)/D4 -> 0 | W4: =$J4*1000000/$D4 -> 0 | X4: =(SUM(S4)*1000000)/D4 -> 0 | Y4: =(SUM(J4:Q4)*1000000)/D4 -> 0 | Z4: =T4/D4 -> 0
B5: FEBRUARI | C5: 377 | D5: 84564 | E5: =D5/31*24 -> 65468.903 | F5: 0 | G5: 0 | H5: 0 | J5: 0 | K5: 0 | L5: 0 | M5: 0 | N5: 0 | O5: 0 | P5: 1 | Q5: 0 | R5: =SUM(H5:Q5) -> 1 | T5: 3.2146129e+09 | U5: =((P5)*1000000)/D5 -> 11.825363 | V5: =((J5+K5+L5+N5+M5+O5+P5+Q5)*1000000)/D5 -> 11.825363 | W5: =$J5*1000000/$D5 -> 0 | X5: =(SUM(S5)*1000000)/D5 -> 0 | Y5: =(SUM(J5:Q5)*1000000)/D5 -> 11.825363 | Z5: =T5/D5 -> 38013.965
B6: MARET | C6: 485 | D6: 94393 | E6: =D6/31*24 -> 73078.452 | F6: 0 | G6: 0 | H6: 0 | J6: 1 | K6: 0 | L6: 0 | M6: 0 | N6: 0 | O6: 0 | P6: 0 | Q6: 0 | R6: =SUM(H6:Q6) -> 1 | T6: 0 | U6: =((P6)*1000000)/D6 -> 0 | V6: =((J6+K6+L6+N6+M6+O6+P6+Q6)*1000000)/D6 -> 10.594006 | W6: =$J6*1000000/$D6 -> 10.594006 | X6: =(SUM(S6)*1000000)/D6 -> 0 | Y6: =(SUM(J6:Q6)*1000000)/D6 -> 10.594006 | Z6: =T6/D6 -> 0
B7: APRIL | C7: 520 | D7: 117037.3 | E7: =D7/31*24 -> 90609.523 | F7: 0 | G7: 0 | H7: 0 | J7: 0 | K7: 0 | L7: 2 | M7: 0 | N7: 0 | O7: 0 | P7: 0 | Q7: 0 | R7: =SUM(H7:Q7) -> 2 | T7: 822247984 | U7: =((P7)*1000000)/D7 -> 0 | V7: =((J7+K7+L7+N7+M7+O7+P7+Q7)*1000000)/D7 -> 17.088569 | W7: =$J7*1000000/$D7 -> 0 | X7: =(SUM(S7)*1000000)/D7 -> 0 | Y7: =(SUM(J7:Q7)*1000000)/D7 -> 17.088569 | Z7: =T7/D7 -> 7025.5208
B8: MEI | C8: 515 | D8: 120739.8 | E8: =D8/31*24 -> 93475.974 | F8: 0 | G8: 0 | H8: 0 | J8: 3 | K8: 0 | L8: 0 | M8: 0 | N8: 0 | O8: 0 | P8: 0 | Q8: 0 | R8: =SUM(H8:Q8) -> 3 | T8: 2815708108 | U8: =((P8)*1000000)/D8 -> 0 | V8: =((J8+K8+L8+N8+M8+O8+P8+Q8)*1000000)/D8 -> 24.846819 | W8: =$J8*1000000/$D8 -> 24.846819 | X8: =(SUM(S8)*1000000)/D8 -> 0 | Y8: =(SUM(J8:Q8)*1000000)/D8 -> 24.846819 | Z8: =T8/D8 -> 23320.464
B9: JUNE | C9: 508 | D9: 112769 | E9: =D9/31*24 -> 87305.032 | F9: 0 | G9: 0 | H9: 0 | J9: 1 | K9: 0 | L9: 3 | M9: 0 | N9: 0 | O9: 0 | P9: 0 | Q9: 0 | R9: =SUM(H9:Q9) -> 4 | T9: 1006163400 | U9: =((P9)*1000000)/D9 -> 0 | V9: =((J9+K9+L9+N9+M9+O9+P9+Q9)*1000000)/D9 -> 35.470741 | W9: =$J9*1000000/$D9 -> 8.8676853 | X9: =(SUM(S9)*1000000)/D9 -> 0 | Y9: =(SUM(J9:Q9)*1000000)/D9 -> 35.470741 | Z9: =T9/D9 -> 8922.3404
B10: JULI | C10: 532 | D10: 127791.5 | E10: =D10/31*24 -> 98935.355 | F10: 0 | G10: 0 | H10: 0 | J10: 1 | K10: 0 | L10: 0 | M10: 0 | N10: 0 | O10: 0 | P10: 0 | Q10: 0 | R10: =SUM(H10:Q10) -> 1 | T10: 0 | U10: =((P10)*1000000)/D10 -> 0 | V10: =((J10+K10+L10+N10+M10+O10+P10+Q10)*1000000)/D10 -> 7.8252466 | W10: =$J10*1000000/$D10 -> 7.8252466 | X10: =(SUM(S10)*1000000)/D10 -> 0 | Y10: =(SUM(J10:Q10)*1000000)/D10 -> 7.8252466 | Z10: =T10/D10 -> 0
B11: AGUSTUS | C11: 526 | D11: 109451 | E11: =D11/31*24 -> 84736.258 | F11: 0 | G11: 0 | H11: 0 | J11: 3 | K11: 0 | L11: 1 | M11: 0 | N11: 0 | O11: 0 | P11: 0 | Q11: 0 | R11: =SUM(H11:Q11) -> 4 | T11: 1.0366477e+09 | U11: =((P11)*1000000)/D11 -> 0 | V11: =((J11+K11+L11+N11+M11+O11+P11+Q11)*1000000)/D11 -> 36.546034 | W11: =$J11*1000000/$D11 -> 27.409526 | X11: =(SUM(S11)*1000000)/D11 -> 0 | Y11: =(SUM(J11:Q11)*1000000)/D11 -> 36.546034 | Z11: =T11/D11 -> 9471.341
B12: SEPTEMBER | C12: 533 | D12: 103964 | E12: =D12/31*24 -> 80488.258 | F12: 0 | G12: 0 | H12: 1 | J12: 1 | K12: 0 | L12: 2 | M12: 0 | N12: 0 | O12: 0 | P12: 0 | Q12: 0 | R12: =SUM(H12:Q12) -> 4 | T12: 5.1832387e+08 | U12: =((P12)*1000000)/D12 -> 0 | V12: =((J12+K12+L12+N12+M12+O12+P12+Q12)*1000000)/D12 -> 28.856143 | W12: =$J12*1000000/$D12 -> 9.6187142 | X12: =(SUM(S12)*1000000)/D12 -> 0 | Y12: =(SUM(J12:Q12)*1000000)/D12 -> 28.856143 | Z12: =T12/D12 -> 4985.6092
B13: OKTOBER | C13: 573 | D13: 136099 | E13: =D13/31*24 -> 105366.97 | F13: 0 | G13: 0 | H13: 1 | J13: 2 | K13: 0 | L13: 0 | M13: 0 | N13: 0 | O13: 0 | P13: 0 | Q13: 0 | R13: =SUM(H13:Q13) -> 3 | T13: 385000000 | U13: =((P13)*1000000)/D13 -> 0 | V13: =((J13+K13+L13+N13+M13+O13+P13+Q13)*1000000)/D13 -> 14.695185 | W13: =$J13*1000000/$D13 -> 14.695185 | X13: =(SUM(S13)*1000000)/D13 -> 0 | Y13: =(SUM(J13:Q13)*1000000)/D13 -> 14.695185 | Z13: =T13/D13 -> 2828.8231
B14: NOVEMBER | C14: 601 | D14: 136311.5 | E14: =D14/31*24 -> 105531.48 | F14: 0 | G14: 0 | H14: 0 | J14: 2 | K14: 0 | L14: 0 | M14: 0 | N14: 0 | O14: 0 | P14: 0 | Q14: 0 | R14: =SUM(H14:Q14) -> 2 | T14: 1.5097586e+08 | U14: =((P14)*1000000)/D14 -> 0 | V14: =((J14+K14+L14+N14+M14+O14+P14+Q14)*1000000)/D14 -> 14.672276 | W14: =$J14*1000000/$D14 -> 14.672276 | X14: =(SUM(S14)*1000000)/D14 -> 0 | Y14: =(SUM(J14:Q14)*1000000)/D14 -> 14.672276 | Z14: =T14/D14 -> 1107.5798
B15: DESEMBER | C15: 618 | D15: 150349 | E15: =D15/31*24 -> 116399.23 | F15: 0 | G15: 0 | H15: 1 | J15: 1 | K15: 0 | L15: 1 | M15: 0 | N15: 0 | O15: 0 | P15: 0 | Q15: 0 | R15: =SUM(H15:Q15) -> 3 | T15: 5.1832387e+08 | U15: =((P15)*1000000)/D15 -> 0 | V15: =((J15+K15+L15+N15+M15+O15+P15+Q15)*1000000)/D15 -> 13.302383 | W15: =$J15*1000000/$D15 -> 6.6511916 | X15: =(SUM(S15)*1000000)/D15 -> 0 | Y15: =(SUM(J15:Q15)*1000000)/D15 -> 13.302383 | Z15: =T15/D15 -> 3447.4714
B16: TOTAL | C16: =SUM(C4:C15) -> 6143 | D16: =SUM(D4:D15) -> 1369413.6 | E16: =SUM(E4:E15) -> 1060191.2 | F16: =SUM(F4:F15) -> 0 | G16: =SUM(G4:G15) -> 0 | H16: =SUM(H4:H15) -> 3 | J16: =SUM(J4:J15) -> 15 | K16: =SUM(K4:K15) -> 0 | L16: =SUM(L4:L15) -> 9 | M16: =SUM(M4:M15) -> 0 | N16: =SUM(N4:N15) -> 0 | O16: =SUM(O4:O15) -> 0 | P16: =SUM(P4:P15) -> 1 | Q16: =SUM(Q4:Q15) -> 0 | R16: =SUM(R4:R15) -> 28 | S16: =SUM(T4:T15) -> 1.0468004e+10 | T16: =((P16)*1000000)/D16 -> 0.73023957 | U16: =((J16+K16+L16+N16+M16+O16+P16+Q16)*1000000)/D16 -> 18.255989 | V16: =(SUM(R16)*1000000)/D16 -> 20.446708 | W16: =(SUM(J16:Q16)*1000000)/D16 -> 18.255989 | X16: =SUM(X4:X15) -> 0 | Y16: =(SUM(J16:Q16)*1000000)/D16 -> 18.255989 | Z16: =T16/D16 -> 5.3324983e-07
B18: 2021
B19: MONTH | C19: MAN POWER | D19: MAN HOURS | E19: MAN HOURS NLTI | F19: KTA | G19: TTA | H19: NM | I19: EI | J19: PD | K19: FC | L19: FA | M19: MI | N19: MTI | O19: RWI | P19: LTI | Q19: FATAL | R19: TOTAL | S19: LOST DAY | T19: LOST COST | U19: LTIFR / FR | V19: AIFR | W19: PDFR | X19: LTI SR | Y19: IR | Z19: LR
B21: JANUARI | C21: 657 | D21: 155571 | E21: =D21/31*31 -> 155571 | F21: 0 | G21: 0 | H21: 0 | I21: 0 | J21: 1 | K21: 0 | L21: 2 | M21: 0 | N21: 0 | O21: 0 | P21: 0 | Q21: 0 | R21: =SUM(H21:Q21) -> 3 | S21: 0 | T21: 648345729 | U21: =((P21)*1000000)/D21 -> 0 | V21: =((J21+K21+L21+N21+M21+O21+P21+Q21)*1000000)/D21 -> 19.2838 | W21: =$J21*1000000/$D21 -> 6.4279332 | X21: =(SUM(S21)*1000000)/D21 -> 0 | Y21: =(SUM(J21:Q21)*1000000)/D21 -> 19.2838 | Z21: =T21/D21 -> 4167.5231
B22: FEBRUARI | C22: 713 | D22: 156767 | E22: =D22/31*31 -> 156767 | F22: 0 | G22: 0 | H22: 0 | I22: 0 | J22: 1 | K22: 0 | L22: 0 | M22: 0 | N22: 0 | O22: 0 | P22: 0 | Q22: 0 | R22: =SUM(H22:Q22) -> 1 | S22: 0 | T22: 0 | U22: =((P22)*1000000)/D22 -> 0 | V22: =((J22+K22+L22+N22+M22+O22+P22+Q22)*1000000)/D22 -> 6.3788935 | W22: =$J22*1000000/$D22 -> 6.3788935 | X22: =(SUM(S22)*1000000)/D22 -> 0 | Y22: =(SUM(J22:Q22)*1000000)/D22 -> 6.3788935 | Z22: =T22/D22 -> 0
B23: MARET | C23: 789 | D23: 196951.5 | E23: =D23/31*31 -> 196951.5 | F23: 0 | G23: 0 | H23: 1 | I23: 0 | J23: 2 | K23: 0 | L23: 0 | M23: 0 | N23: 0 | O23: 0 | P23: 0 | Q23: 0 | R23: =SUM(H23:Q23) -> 3 | S23: 0 | T23: 384978154 | U23: =((P23)*1000000)/D23 -> 0 | V23: =((J23+K23+L23+N23+M23+O23+P23+Q23)*1000000)/D23 -> 10.154784 | W23: =$J23*1000000/$D23 -> 10.154784 | X23: =(SUM(S23)*1000000)/D23 -> 0 | Y23: =(SUM(J23:Q23)*1000000)/D23 -> 10.154784 | Z23: =T23/D23 -> 1954.6851
B24: APRIL | C24: 849 | D24: 211266 | E24: =D24/31*31 -> 211266 | F24: 0 | G24: 0 | H24: 0 | I24: 0 | J24: 5 | K24: 0 | L24: 3 | M24: 0 | N24: 0 | O24: 0 | P24: 0 | Q24: 0 | R24: =SUM(H24:Q24) -> 8 | S24: 0 | T24: 6.2946727e+09 | U24: =((P24)*1000000)/D24 -> 0 | V24: =((J24+K24+L24+N24+M24+O24+P24+Q24)*1000000)/D24 -> 37.866954 | W24: =$J24*1000000/$D24 -> 23.666847 | X24: =(SUM(S24)*1000000)/D24 -> 0 | Y24: =(SUM(J24:Q24)*1000000)/D24 -> 37.866954 | Z24: =T24/D24 -> 29795.011
B25: MEI | C25: 985 | D25: 208986 | E25: =D25/31*31 -> 208986 | F25: 0 | G25: 0 | H25: 4 | I25: 0 | J25: 3 | K25: 0 | L25: 0 | M25: 0 | N25: 0 | O25: 0 | P25: 0 | Q25: 0 | R25: =SUM(H25:Q25) -> 7 | S25: 0 | T25: 467922400 | U25: =((P25)*1000000)/D25 -> 0 | V25: =((J25+K25+L25+N25+M25+O25+P25+Q25)*1000000)/D25 -> 14.355029 | W25: =$J25*1000000/$D25 -> 14.355029 | X25: =(SUM(S25)*1000000)/D25 -> 0 | Y25: =(SUM(J25:Q25)*1000000)/D25 -> 14.355029 | Z25: =T25/D25 -> 2239.0131
B26: JUNE | C26: 970 | D26: 253971 | E26: 0 | F26: 0 | G26: 0 | H26: 3 | I26: 2 | K26: 0 | L26: 0 | M26: 0 | N26: 0 | O26: 0 | P26: 0 | Q26: 1 | R26: =SUM(H26:Q26) -> 6 | S26: 6000 | T26: 1751009640 | U26: =((P26)*1000000)/D26 -> 0 | V26: =((J26+K26+L26+N26+M26+O26+P26+Q26)*1000000)/D26 -> 3.9374574 | W26: =$J26*1000000/$D26 -> 0 | X26: =(SUM(S26)*1000000)/D26 -> 23624.745 | Y26: =(SUM(J26:Q26)*1000000)/D26 -> 3.9374574 | Z26: =T26/D26 -> 6894.5259
B27: JULI | C27: 970 | D27: 253971 | E27: =D27/31*31 -> 253971 | F27: 0 | G27: 0 | H27: 2 | I27: 0 | J27: 2 | K27: 0 | L27: 0 | M27: 0 | N27: 0 | O27: 0 | P27: 0 | Q27: 0 | R27: =SUM(H27:Q27) -> 4 | S27: 0 | T27: 236732535 | U27: =((P27)*1000000)/D27 -> 0 | V27: =((J27+K27+L27+N27+M27+O27+P27+Q27)*1000000)/D27 -> 7.8749149 | W27: =$J27*1000000/$D27 -> 7.8749149 | X27: =(SUM(S27)*1000000)/D27 -> 0 | Y27: =(SUM(J27:Q27)*1000000)/D27 -> 7.8749149 | Z27: =T27/D27 -> 932.12428
B28: AGUSTUS | C28: 970 | D28: 253971 | E28: =D28/31*31 -> 253971 | F28: 0 | G28: 0 | H28: 0 | I28: 0 | J28: 2 | K28: 0 | L28: 0 | M28: 0 | N28: 0 | O28: 0 | P28: 0 | Q28: 0 | R28: =SUM(H28:Q28) -> 2 | S28: 0 | T28: 173578800 | U28: =((P28)*1000000)/D28 -> 0 | V28: =((J28+K28+L28+N28+M28+O28+P28+Q28)*1000000)/D28 -> 7.8749149 | W28: =$J28*1000000/$D28 -> 7.8749149 | X28: =(SUM(S28)*1000000)/D28 -> 0 | Y28: =(SUM(J28:Q28)*1000000)/D28 -> 7.8749149 | Z28: =T28/D28 -> 683.45914
B29: SEPTEMBER | C29: 970 | D29: 253971 | E29: =D29/31*31 -> 253971 | F29: 0 | G29: 0 | H29: 1 | I29: 0 | J29: 4 | K29: 0 | L29: 0 | M29: 0 | N29: 0 | O29: 0 | P29: 0 | Q29: 0 | R29: =SUM(H29:Q29) -> 5 | S29: 0 | T29: 151384150 | U29: =((P29)*1000000)/D29 -> 0 | V29: =((J29+K29+L29+N29+M29+O29+P29+Q29)*1000000)/D29 -> 15.74983 | W29: =$J29*1000000/$D29 -> 15.74983 | X29: =(SUM(S29)*1000000)/D29 -> 0 | Y29: =(SUM(J29:Q29)*1000000)/D29 -> 15.74983 | Z29: =T29/D29 -> 596.06865
B30: OKTOBER | C30: 931 | D30: 243882 | E30: =D30/31*31 -> 243882 | F30: 0 | G30: 0 | H30: 1 | I30: 0 | J30: 1 | K30: 0 | L30: 0 | M30: 0 | N30: 0 | O30: 0 | P30: 0 | Q30: 0 | R30: =SUM(H30:Q30) -> 2 | S30: 0 | T30: 200000 | U30: =((P30)*1000000)/D30 -> 0 | V30: =((J30+K30+L30+N30+M30+O30+P30+Q30)*1000000)/D30 -> 4.1003436 | W30: =$J30*1000000/$D30 -> 4.1003436 | X30: =(SUM(S30)*1000000)/D30 -> 0 | Y30: =(SUM(J30:Q30)*1000000)/D30 -> 4.1003436 | Z30: =T30/D30 -> 0.82006872
B31: NOVEMBER | C31: 931 | D31: 243882 | E31: =D31/31*31 -> 243882 | F31: 0 | G31: 0 | H31: 1 | I31: 0 | J31: 3 | K31: 0 | L31: 0 | M31: 0 | N31: 0 | O31: 0 | P31: 0 | Q31: 0 | R31: =SUM(H31:Q31) -> 4 | S31: 0 | T31: 758494631 | U31: =((P31)*1000000)/D31 -> 0 | V31: =((J31+K31+L31+N31+M31+O31+P31+Q31)*1000000)/D31 -> 12.301031 | W31: =$J31*1000000/$D31 -> 12.301031 | X31: =(SUM(S31)*1000000)/D31 -> 0 | Y31: =(SUM(J31:Q31)*1000000)/D31 -> 12.301031 | Z31: =T31/D31 -> 3110.0886
B32: DESEMBER | C32: 931 | D32: 243882 | E32: =D32/31*30 -> 236014.84 | F32: 0 | G32: 0 | H32: 1 | I32: 0 | J32: 1 | K32: 0 | L32: 0 | M32: 0 | N32: 0 | O32: 0 | P32: 1 | Q32: 0 | R32: =SUM(H32:Q32) -> 3 | S32: 25 | U32: =((P32)*1000000)/D32 -> 4.1003436 | V32: =((J32+K32+L32+N32+M32+O32+P32+Q32)*1000000)/D32 -> 8.2006872 | W32: =$J32*1000000/$D32 -> 4.1003436 | X32: =(SUM(S32)*1000000)/D32 -> 102.50859 | Y32: =(SUM(J32:Q32)*1000000)/D32 -> 8.2006872 | Z32: =T32/D32 -> 0
B33: TOTAL | C33: =SUM(C21:C32) -> 10666 | D33: =SUM(D21:D32) -> 2677071.5 | E33: =SUM(E21:E32) -> 2415233.3 | F33: =SUM(F21:F32) -> 0 | G33: =SUM(G21:G32) -> 0 | H33: =SUM(H21:H32) -> 14 | I33: =SUM(I21:I32) -> 2 | J33: =SUM(J21:J32) -> 25 | ... T33: =SUM(T21:T32) -> 1.0867319e+10 | U33: =((P33)*1000000)/D33 -> 0.37354251 | V33: =((J33+K33+L33+N33+M33+O33+P33+Q33)*1000000)/D33 -> 11.95336 | W33: =$J33*1000000/$E33 -> 10.350967 | X33: =(SUM(S33)*1000000)/D33 -> 2250.5936 | Y33: =(SUM(J33:Q33)*1000000)/D33 -> 11.95336 | Z33: =T33/D33 -> 4059.4055
B35: 2022
B36: MONTH | C36: MAN POWER | D36: MAN HOURS | E36: MAN HOURS NLTI | F36: KTA | G36: TTA | H36: NM | I36: EI | J36: PD | K36: FC | L36: FA | M36: MI | N36: MTI | O36: RWI | P36: LTI | Q36: FATAL | R36: TOTAL | S36: LOST DAY | T36: LOST COST | U36: LTIFR / FR | V36: AIFR | W36: PDFR | X36: LTI SR | Y36: IR | Z36: LR
B38: JANUARI | C38: 1100 | D38: 300342 | E38: =D38/31*31 -> 300342 | F38: 0 | G38: 0 | H38: 5 | I38: 1 | J38: 6 | K38: 0 | L38: 0 | M38: 0 | N38: 0 | O38: 0 | P38: 0 | Q38: 0 | R38: =-SUM(H38:Q38) -> -12 | S38: 31 | T38: 5.6898963e+08 | U38: =((P38)*1000000)/D38 -> 0 | V38: =((J38+K38+L38+N38+M38+O38+P38+Q38)*1000000)/D38 -> 19.977226 | W38: =$J38*1000000/$D38 -> 19.977226 | X38: =(SUM(S38)*1000000)/D38 -> 103.21567 | Y38: =(SUM(J38:Q38)*1000000)/D38 -> 19.977226 | Z38: =T38/D38 -> 1894.4724
B39: FEBRUARI | C39: 1117 | D39: 260112 | E39: =D39/28*28 -> 260112 | F39: 0 | G39: 0 | H39: 2 | I39: 0 | J39: 2 | K39: 0 | L39: 0 | M39: 0 | N39: 1 | O39: 0 | P39: 0 | Q39: 0 | R39: =-SUM(H39:Q39) -> -5 | S39: 28 | T39: 9.8178707e+08 | U39: =((P39)*1000000)/D39 -> 0 | V39: =((J39+K39+L39+N39+M39+O39+P39+Q39)*1000000)/D39 -> 11.533493 | W39: =$J39*1000000/$D39 -> 7.6889955 | X39: =(SUM(S39)*1000000)/D39 -> 107.64594 | Y39: =(SUM(J39:Q39)*1000000)/D39 -> 11.533493 | Z39: =T39/D39 -> 3774.4782
B40: MARET | C40: 1513 | D40: 247068 | E40: =D40/31*31 -> 247068 | F40: 0 | G40: 0 | H40: 2 | I40: 0 | J40: 5 | K40: 0 | L40: 0 | M40: 0 | N40: 0 | O40: 0 | P40: 0 | Q40: 0 | R40: =-SUM(H40:Q40) -> -7 | S40: 31 | T40: 2.3536113e+09 | U40: =((P40)*1000000)/D40 -> 0 | V40: =((J40+K40+L40+N40+M40+O40+P40+Q40)*1000000)/D40 -> 20.237344 | W40: =$J40*1000000/$D40 -> 20.237344 | X40: =(SUM(S40)*1000000)/D40 -> 125.47153 | Y40: =(SUM(J40:Q40)*1000000)/D40 -> 20.237344 | Z40: =T40/D40 -> 9526.1681
B41: APRIL | C41: 1270 | D41: 256839 | E41: =D41/30*30 -> 256839 | F41: 0 | G41: 0 | H41: 2 | I41: 1 | J41: 6 | K41: 0 | L41: 0 | M41: 0 | N41: 0 | O41: 0 | P41: 0 | Q41: 0 | R41: =-SUM(H41:Q41) -> -9 | S41: 0 | T41: 2.4038619e+09 | U41: =((P41)*1000000)/D41 -> 0 | V41: =((J41+K41+L41+N41+M41+O41+P41+Q41)*1000000)/D41 -> 23.360938 | W41: =$J41*1000000/$D41 -> 23.360938 | X41: =(SUM(S41:S41)*1000000)/D41 -> 0 | Y41: =(SUM(J41:Q41)*1000000)/D41 -> 23.360938 | Z41: =T41/D41 -> 9359.4114
B42: MEI | C42: 1413 | D42: 327786 | E42: =D42/31*31 -> 327786 | F42: 0 | G42: 0 | H42: 5 | I42: 1 | J42: 4 | K42: 0 | L42: 0 | M42: 0 | N42: 0 | O42: 0 | P42: 0 | Q42: 0 | R42: =-SUM(H42:Q42) -> -10 | S42: 0 | T42: 5.5619652e+08 | U42: =((P42)*1000000)/D42 -> 0 | V42: =((J42+K42+L42+N42+M42+O42+P42+Q42)*1000000)/D42 -> 12.203084 | W42: =$J42*1000000/$D42 -> 12.203084 | X42: =(SUM(S42)*1000000)/D42 -> 0 | Y42: =(SUM(J42:Q42)*1000000)/D42 -> 12.203084 | Z42: =T42/D42 -> 1696.8282
